[ERROR] 2021-11-11 19:45:23,903 django.request: Internal Server Error: /login/
Traceback (most recent call last):
  File "/Users/rileymarsden/.local/share/virtualenvs/EasyConnect-40Y_jyS5/lib/python3.9/site-packages/django/core/handlers/exception.py", line 47, in inner
    response = get_response(request)
  File "/Users/rileymarsden/.local/share/virtualenvs/EasyConnect-40Y_jyS5/lib/python3.9/site-packages/django/core/handlers/base.py", line 181, in _get_response
    response = wrapped_callback(request, *callback_args, **callback_kwargs)
  File "/Users/rileymarsden/Desktop/EasyConnect/customuser/views.py", line 88, in login_view
    logger.ERROR('User ' + username + ' failed to log in: in ' + str(round((time.time() - sw) * 1000, 4)) + ' ms')
AttributeError: 'Logger' object has no attribute 'ERROR'
[ERROR] 2021-11-12 21:15:02,727 django.request: Internal Server Error: /home/
Traceback (most recent call last):
  File "/Users/rileymarsden/.local/share/virtualenvs/EasyConnect-40Y_jyS5/lib/python3.9/site-packages/django/core/handlers/exception.py", line 47, in inner
    response = get_response(request)
  File "/Users/rileymarsden/.local/share/virtualenvs/EasyConnect-40Y_jyS5/lib/python3.9/site-packages/django/core/handlers/base.py", line 181, in _get_response
    response = wrapped_callback(request, *callback_args, **callback_kwargs)
TypeError: HomePageView() takes 0 positional arguments but 1 was given
[ERROR] 2021-11-12 21:15:03,169 django.request: Internal Server Error: /home/
Traceback (most recent call last):
  File "/Users/rileymarsden/.local/share/virtualenvs/EasyConnect-40Y_jyS5/lib/python3.9/site-packages/django/core/handlers/exception.py", line 47, in inner
    response = get_response(request)
  File "/Users/rileymarsden/.local/share/virtualenvs/EasyConnect-40Y_jyS5/lib/python3.9/site-packages/django/core/handlers/base.py", line 181, in _get_response
    response = wrapped_callback(request, *callback_args, **callback_kwargs)
TypeError: HomePageView() takes 0 positional arguments but 1 was given
[ERROR] 2021-11-12 21:17:08,849 django.request: Internal Server Error: /home/
Traceback (most recent call last):
  File "/Users/rileymarsden/.local/share/virtualenvs/EasyConnect-40Y_jyS5/lib/python3.9/site-packages/django/core/handlers/exception.py", line 47, in inner
    response = get_response(request)
  File "/Users/rileymarsden/.local/share/virtualenvs/EasyConnect-40Y_jyS5/lib/python3.9/site-packages/django/core/handlers/base.py", line 181, in _get_response
    response = wrapped_callback(request, *callback_args, **callback_kwargs)
  File "/Users/rileymarsden/Desktop/EasyConnect/EasyConnect/views.py", line 6, in HomePageView
    return render(request, 'templates/home.html', context)
  File "/Users/rileymarsden/.local/share/virtualenvs/EasyConnect-40Y_jyS5/lib/python3.9/site-packages/django/shortcuts.py", line 19, in render
    content = loader.render_to_string(template_name, context, request, using=using)
  File "/Users/rileymarsden/.local/share/virtualenvs/EasyConnect-40Y_jyS5/lib/python3.9/site-packages/django/template/loader.py", line 61, in render_to_string
    template = get_template(template_name, using=using)
  File "/Users/rileymarsden/.local/share/virtualenvs/EasyConnect-40Y_jyS5/lib/python3.9/site-packages/django/template/loader.py", line 19, in get_template
    raise TemplateDoesNotExist(template_name, chain=chain)
django.template.exceptions.TemplateDoesNotExist: templates/home.html
[ERROR] 2021-11-12 21:24:25,457 django.request: Internal Server Error: /home/
Traceback (most recent call last):
  File "/Users/rileymarsden/.local/share/virtualenvs/EasyConnect-40Y_jyS5/lib/python3.9/site-packages/django/template/backends/django.py", line 61, in render
    return self.template.render(context)
  File "/Users/rileymarsden/.local/share/virtualenvs/EasyConnect-40Y_jyS5/lib/python3.9/site-packages/django/template/base.py", line 170, in render
    return self._render(context)
  File "/Users/rileymarsden/.local/share/virtualenvs/EasyConnect-40Y_jyS5/lib/python3.9/site-packages/django/template/base.py", line 162, in _render
    return self.nodelist.render(context)
  File "/Users/rileymarsden/.local/share/virtualenvs/EasyConnect-40Y_jyS5/lib/python3.9/site-packages/django/template/base.py", line 938, in render
    bit = node.render_annotated(context)
  File "/Users/rileymarsden/.local/share/virtualenvs/EasyConnect-40Y_jyS5/lib/python3.9/site-packages/django/template/base.py", line 905, in render_annotated
    return self.render(context)
  File "/Users/rileymarsden/.local/share/virtualenvs/EasyConnect-40Y_jyS5/lib/python3.9/site-packages/django/template/loader_tags.py", line 127, in render
    compiled_parent = self.get_parent(context)
  File "/Users/rileymarsden/.local/share/virtualenvs/EasyConnect-40Y_jyS5/lib/python3.9/site-packages/django/template/loader_tags.py", line 124, in get_parent
    return self.find_template(parent, context)
  File "/Users/rileymarsden/.local/share/virtualenvs/EasyConnect-40Y_jyS5/lib/python3.9/site-packages/django/template/loader_tags.py", line 103, in find_template
    template, origin = context.template.engine.find_template(
  File "/Users/rileymarsden/.local/share/virtualenvs/EasyConnect-40Y_jyS5/lib/python3.9/site-packages/django/template/engine.py", line 129, in find_template
    raise TemplateDoesNotExist(name, tried=tried)
django.template.exceptions.TemplateDoesNotExist: templates/base.html

The above exception was the direct cause of the following exception:

Traceback (most recent call last):
  File "/Users/rileymarsden/.local/share/virtualenvs/EasyConnect-40Y_jyS5/lib/python3.9/site-packages/django/core/handlers/exception.py", line 47, in inner
    response = get_response(request)
  File "/Users/rileymarsden/.local/share/virtualenvs/EasyConnect-40Y_jyS5/lib/python3.9/site-packages/django/core/handlers/base.py", line 181, in _get_response
    response = wrapped_callback(request, *callback_args, **callback_kwargs)
  File "/Users/rileymarsden/Desktop/EasyConnect/EasyConnect/views.py", line 6, in HomePageView
    return render(request, 'home.html', context)
  File "/Users/rileymarsden/.local/share/virtualenvs/EasyConnect-40Y_jyS5/lib/python3.9/site-packages/django/shortcuts.py", line 19, in render
    content = loader.render_to_string(template_name, context, request, using=using)
  File "/Users/rileymarsden/.local/share/virtualenvs/EasyConnect-40Y_jyS5/lib/python3.9/site-packages/django/template/loader.py", line 62, in render_to_string
    return template.render(context, request)
  File "/Users/rileymarsden/.local/share/virtualenvs/EasyConnect-40Y_jyS5/lib/python3.9/site-packages/django/template/backends/django.py", line 63, in render
    reraise(exc, self.backend)
  File "/Users/rileymarsden/.local/share/virtualenvs/EasyConnect-40Y_jyS5/lib/python3.9/site-packages/django/template/backends/django.py", line 84, in reraise
    raise new from exc
django.template.exceptions.TemplateDoesNotExist: templates/base.html
[ERROR] 2021-11-12 21:24:43,576 django.request: Internal Server Error: /home/
Traceback (most recent call last):
  File "/Users/rileymarsden/.local/share/virtualenvs/EasyConnect-40Y_jyS5/lib/python3.9/site-packages/django/template/backends/django.py", line 61, in render
    return self.template.render(context)
  File "/Users/rileymarsden/.local/share/virtualenvs/EasyConnect-40Y_jyS5/lib/python3.9/site-packages/django/template/base.py", line 170, in render
    return self._render(context)
  File "/Users/rileymarsden/.local/share/virtualenvs/EasyConnect-40Y_jyS5/lib/python3.9/site-packages/django/template/base.py", line 162, in _render
    return self.nodelist.render(context)
  File "/Users/rileymarsden/.local/share/virtualenvs/EasyConnect-40Y_jyS5/lib/python3.9/site-packages/django/template/base.py", line 938, in render
    bit = node.render_annotated(context)
  File "/Users/rileymarsden/.local/share/virtualenvs/EasyConnect-40Y_jyS5/lib/python3.9/site-packages/django/template/base.py", line 905, in render_annotated
    return self.render(context)
  File "/Users/rileymarsden/.local/share/virtualenvs/EasyConnect-40Y_jyS5/lib/python3.9/site-packages/django/template/loader_tags.py", line 127, in render
    compiled_parent = self.get_parent(context)
  File "/Users/rileymarsden/.local/share/virtualenvs/EasyConnect-40Y_jyS5/lib/python3.9/site-packages/django/template/loader_tags.py", line 124, in get_parent
    return self.find_template(parent, context)
  File "/Users/rileymarsden/.local/share/virtualenvs/EasyConnect-40Y_jyS5/lib/python3.9/site-packages/django/template/loader_tags.py", line 103, in find_template
    template, origin = context.template.engine.find_template(
  File "/Users/rileymarsden/.local/share/virtualenvs/EasyConnect-40Y_jyS5/lib/python3.9/site-packages/django/template/engine.py", line 129, in find_template
    raise TemplateDoesNotExist(name, tried=tried)
django.template.exceptions.TemplateDoesNotExist: templates/base.html

The above exception was the direct cause of the following exception:

Traceback (most recent call last):
  File "/Users/rileymarsden/.local/share/virtualenvs/EasyConnect-40Y_jyS5/lib/python3.9/site-packages/django/core/handlers/exception.py", line 47, in inner
    response = get_response(request)
  File "/Users/rileymarsden/.local/share/virtualenvs/EasyConnect-40Y_jyS5/lib/python3.9/site-packages/django/core/handlers/base.py", line 181, in _get_response
    response = wrapped_callback(request, *callback_args, **callback_kwargs)
  File "/Users/rileymarsden/Desktop/EasyConnect/EasyConnect/views.py", line 6, in HomePageView
    return render(request, 'home.html', context)
  File "/Users/rileymarsden/.local/share/virtualenvs/EasyConnect-40Y_jyS5/lib/python3.9/site-packages/django/shortcuts.py", line 19, in render
    content = loader.render_to_string(template_name, context, request, using=using)
  File "/Users/rileymarsden/.local/share/virtualenvs/EasyConnect-40Y_jyS5/lib/python3.9/site-packages/django/template/loader.py", line 62, in render_to_string
    return template.render(context, request)
  File "/Users/rileymarsden/.local/share/virtualenvs/EasyConnect-40Y_jyS5/lib/python3.9/site-packages/django/template/backends/django.py", line 63, in render
    reraise(exc, self.backend)
  File "/Users/rileymarsden/.local/share/virtualenvs/EasyConnect-40Y_jyS5/lib/python3.9/site-packages/django/template/backends/django.py", line 84, in reraise
    raise new from exc
django.template.exceptions.TemplateDoesNotExist: templates/base.html
[ERROR] 2021-11-12 21:24:45,777 django.request: Internal Server Error: /home/
Traceback (most recent call last):
  File "/Users/rileymarsden/.local/share/virtualenvs/EasyConnect-40Y_jyS5/lib/python3.9/site-packages/django/template/backends/django.py", line 61, in render
    return self.template.render(context)
  File "/Users/rileymarsden/.local/share/virtualenvs/EasyConnect-40Y_jyS5/lib/python3.9/site-packages/django/template/base.py", line 170, in render
    return self._render(context)
  File "/Users/rileymarsden/.local/share/virtualenvs/EasyConnect-40Y_jyS5/lib/python3.9/site-packages/django/template/base.py", line 162, in _render
    return self.nodelist.render(context)
  File "/Users/rileymarsden/.local/share/virtualenvs/EasyConnect-40Y_jyS5/lib/python3.9/site-packages/django/template/base.py", line 938, in render
    bit = node.render_annotated(context)
  File "/Users/rileymarsden/.local/share/virtualenvs/EasyConnect-40Y_jyS5/lib/python3.9/site-packages/django/template/base.py", line 905, in render_annotated
    return self.render(context)
  File "/Users/rileymarsden/.local/share/virtualenvs/EasyConnect-40Y_jyS5/lib/python3.9/site-packages/django/template/loader_tags.py", line 127, in render
    compiled_parent = self.get_parent(context)
  File "/Users/rileymarsden/.local/share/virtualenvs/EasyConnect-40Y_jyS5/lib/python3.9/site-packages/django/template/loader_tags.py", line 124, in get_parent
    return self.find_template(parent, context)
  File "/Users/rileymarsden/.local/share/virtualenvs/EasyConnect-40Y_jyS5/lib/python3.9/site-packages/django/template/loader_tags.py", line 103, in find_template
    template, origin = context.template.engine.find_template(
  File "/Users/rileymarsden/.local/share/virtualenvs/EasyConnect-40Y_jyS5/lib/python3.9/site-packages/django/template/engine.py", line 129, in find_template
    raise TemplateDoesNotExist(name, tried=tried)
django.template.exceptions.TemplateDoesNotExist: templates/base.html

The above exception was the direct cause of the following exception:

Traceback (most recent call last):
  File "/Users/rileymarsden/.local/share/virtualenvs/EasyConnect-40Y_jyS5/lib/python3.9/site-packages/django/core/handlers/exception.py", line 47, in inner
    response = get_response(request)
  File "/Users/rileymarsden/.local/share/virtualenvs/EasyConnect-40Y_jyS5/lib/python3.9/site-packages/django/core/handlers/base.py", line 181, in _get_response
    response = wrapped_callback(request, *callback_args, **callback_kwargs)
  File "/Users/rileymarsden/Desktop/EasyConnect/EasyConnect/views.py", line 6, in HomePageView
    return render(request, 'home.html', context)
  File "/Users/rileymarsden/.local/share/virtualenvs/EasyConnect-40Y_jyS5/lib/python3.9/site-packages/django/shortcuts.py", line 19, in render
    content = loader.render_to_string(template_name, context, request, using=using)
  File "/Users/rileymarsden/.local/share/virtualenvs/EasyConnect-40Y_jyS5/lib/python3.9/site-packages/django/template/loader.py", line 62, in render_to_string
    return template.render(context, request)
  File "/Users/rileymarsden/.local/share/virtualenvs/EasyConnect-40Y_jyS5/lib/python3.9/site-packages/django/template/backends/django.py", line 63, in render
    reraise(exc, self.backend)
  File "/Users/rileymarsden/.local/share/virtualenvs/EasyConnect-40Y_jyS5/lib/python3.9/site-packages/django/template/backends/django.py", line 84, in reraise
    raise new from exc
django.template.exceptions.TemplateDoesNotExist: templates/base.html
[ERROR] 2021-11-12 21:26:09,107 django.request: Internal Server Error: /home_page/
Traceback (most recent call last):
  File "/Users/rileymarsden/.local/share/virtualenvs/EasyConnect-40Y_jyS5/lib/python3.9/site-packages/django/core/handlers/exception.py", line 47, in inner
    response = get_response(request)
  File "/Users/rileymarsden/.local/share/virtualenvs/EasyConnect-40Y_jyS5/lib/python3.9/site-packages/django/core/handlers/base.py", line 181, in _get_response
    response = wrapped_callback(request, *callback_args, **callback_kwargs)
  File "/Users/rileymarsden/Desktop/EasyConnect/EasyConnect/views.py", line 6, in HomePageView
    return render(request, 'home.html', context)
  File "/Users/rileymarsden/.local/share/virtualenvs/EasyConnect-40Y_jyS5/lib/python3.9/site-packages/django/shortcuts.py", line 19, in render
    content = loader.render_to_string(template_name, context, request, using=using)
  File "/Users/rileymarsden/.local/share/virtualenvs/EasyConnect-40Y_jyS5/lib/python3.9/site-packages/django/template/loader.py", line 62, in render_to_string
    return template.render(context, request)
  File "/Users/rileymarsden/.local/share/virtualenvs/EasyConnect-40Y_jyS5/lib/python3.9/site-packages/django/template/backends/django.py", line 61, in render
    return self.template.render(context)
  File "/Users/rileymarsden/.local/share/virtualenvs/EasyConnect-40Y_jyS5/lib/python3.9/site-packages/django/template/base.py", line 170, in render
    return self._render(context)
  File "/Users/rileymarsden/.local/share/virtualenvs/EasyConnect-40Y_jyS5/lib/python3.9/site-packages/django/template/base.py", line 162, in _render
    return self.nodelist.render(context)
  File "/Users/rileymarsden/.local/share/virtualenvs/EasyConnect-40Y_jyS5/lib/python3.9/site-packages/django/template/base.py", line 938, in render
    bit = node.render_annotated(context)
  File "/Users/rileymarsden/.local/share/virtualenvs/EasyConnect-40Y_jyS5/lib/python3.9/site-packages/django/template/base.py", line 905, in render_annotated
    return self.render(context)
  File "/Users/rileymarsden/.local/share/virtualenvs/EasyConnect-40Y_jyS5/lib/python3.9/site-packages/django/template/loader_tags.py", line 150, in render
    return compiled_parent._render(context)
  File "/Users/rileymarsden/.local/share/virtualenvs/EasyConnect-40Y_jyS5/lib/python3.9/site-packages/django/template/base.py", line 162, in _render
    return self.nodelist.render(context)
  File "/Users/rileymarsden/.local/share/virtualenvs/EasyConnect-40Y_jyS5/lib/python3.9/site-packages/django/template/base.py", line 938, in render
    bit = node.render_annotated(context)
  File "/Users/rileymarsden/.local/share/virtualenvs/EasyConnect-40Y_jyS5/lib/python3.9/site-packages/django/template/base.py", line 905, in render_annotated
    return self.render(context)
  File "/Users/rileymarsden/.local/share/virtualenvs/EasyConnect-40Y_jyS5/lib/python3.9/site-packages/django/template/loader_tags.py", line 62, in render
    result = block.nodelist.render(context)
  File "/Users/rileymarsden/.local/share/virtualenvs/EasyConnect-40Y_jyS5/lib/python3.9/site-packages/django/template/base.py", line 938, in render
    bit = node.render_annotated(context)
  File "/Users/rileymarsden/.local/share/virtualenvs/EasyConnect-40Y_jyS5/lib/python3.9/site-packages/django/template/base.py", line 905, in render_annotated
    return self.render(context)
  File "/Users/rileymarsden/.local/share/virtualenvs/EasyConnect-40Y_jyS5/lib/python3.9/site-packages/django/template/defaulttags.py", line 446, in render
    url = reverse(view_name, args=args, kwargs=kwargs, current_app=current_app)
  File "/Users/rileymarsden/.local/share/virtualenvs/EasyConnect-40Y_jyS5/lib/python3.9/site-packages/django/urls/base.py", line 87, in reverse
    return iri_to_uri(resolver._reverse_with_prefix(view, prefix, *args, **kwargs))
  File "/Users/rileymarsden/.local/share/virtualenvs/EasyConnect-40Y_jyS5/lib/python3.9/site-packages/django/urls/resolvers.py", line 685, in _reverse_with_prefix
    raise NoReverseMatch(msg)
django.urls.exceptions.NoReverseMatch: Reverse for 'home' not found. 'home' is not a valid view function or pattern name.
[ERROR] 2021-11-12 21:26:28,438 django.request: Internal Server Error: /home_page/
Traceback (most recent call last):
  File "/Users/rileymarsden/.local/share/virtualenvs/EasyConnect-40Y_jyS5/lib/python3.9/site-packages/django/core/handlers/exception.py", line 47, in inner
    response = get_response(request)
  File "/Users/rileymarsden/.local/share/virtualenvs/EasyConnect-40Y_jyS5/lib/python3.9/site-packages/django/core/handlers/base.py", line 181, in _get_response
    response = wrapped_callback(request, *callback_args, **callback_kwargs)
  File "/Users/rileymarsden/Desktop/EasyConnect/EasyConnect/views.py", line 6, in HomePageView
    return render(request, 'home.html', context)
  File "/Users/rileymarsden/.local/share/virtualenvs/EasyConnect-40Y_jyS5/lib/python3.9/site-packages/django/shortcuts.py", line 19, in render
    content = loader.render_to_string(template_name, context, request, using=using)
  File "/Users/rileymarsden/.local/share/virtualenvs/EasyConnect-40Y_jyS5/lib/python3.9/site-packages/django/template/loader.py", line 62, in render_to_string
    return template.render(context, request)
  File "/Users/rileymarsden/.local/share/virtualenvs/EasyConnect-40Y_jyS5/lib/python3.9/site-packages/django/template/backends/django.py", line 61, in render
    return self.template.render(context)
  File "/Users/rileymarsden/.local/share/virtualenvs/EasyConnect-40Y_jyS5/lib/python3.9/site-packages/django/template/base.py", line 170, in render
    return self._render(context)
  File "/Users/rileymarsden/.local/share/virtualenvs/EasyConnect-40Y_jyS5/lib/python3.9/site-packages/django/template/base.py", line 162, in _render
    return self.nodelist.render(context)
  File "/Users/rileymarsden/.local/share/virtualenvs/EasyConnect-40Y_jyS5/lib/python3.9/site-packages/django/template/base.py", line 938, in render
    bit = node.render_annotated(context)
  File "/Users/rileymarsden/.local/share/virtualenvs/EasyConnect-40Y_jyS5/lib/python3.9/site-packages/django/template/base.py", line 905, in render_annotated
    return self.render(context)
  File "/Users/rileymarsden/.local/share/virtualenvs/EasyConnect-40Y_jyS5/lib/python3.9/site-packages/django/template/loader_tags.py", line 150, in render
    return compiled_parent._render(context)
  File "/Users/rileymarsden/.local/share/virtualenvs/EasyConnect-40Y_jyS5/lib/python3.9/site-packages/django/template/base.py", line 162, in _render
    return self.nodelist.render(context)
  File "/Users/rileymarsden/.local/share/virtualenvs/EasyConnect-40Y_jyS5/lib/python3.9/site-packages/django/template/base.py", line 938, in render
    bit = node.render_annotated(context)
  File "/Users/rileymarsden/.local/share/virtualenvs/EasyConnect-40Y_jyS5/lib/python3.9/site-packages/django/template/base.py", line 905, in render_annotated
    return self.render(context)
  File "/Users/rileymarsden/.local/share/virtualenvs/EasyConnect-40Y_jyS5/lib/python3.9/site-packages/django/template/loader_tags.py", line 62, in render
    result = block.nodelist.render(context)
  File "/Users/rileymarsden/.local/share/virtualenvs/EasyConnect-40Y_jyS5/lib/python3.9/site-packages/django/template/base.py", line 938, in render
    bit = node.render_annotated(context)
  File "/Users/rileymarsden/.local/share/virtualenvs/EasyConnect-40Y_jyS5/lib/python3.9/site-packages/django/template/base.py", line 905, in render_annotated
    return self.render(context)
  File "/Users/rileymarsden/.local/share/virtualenvs/EasyConnect-40Y_jyS5/lib/python3.9/site-packages/django/template/defaulttags.py", line 446, in render
    url = reverse(view_name, args=args, kwargs=kwargs, current_app=current_app)
  File "/Users/rileymarsden/.local/share/virtualenvs/EasyConnect-40Y_jyS5/lib/python3.9/site-packages/django/urls/base.py", line 87, in reverse
    return iri_to_uri(resolver._reverse_with_prefix(view, prefix, *args, **kwargs))
  File "/Users/rileymarsden/.local/share/virtualenvs/EasyConnect-40Y_jyS5/lib/python3.9/site-packages/django/urls/resolvers.py", line 685, in _reverse_with_prefix
    raise NoReverseMatch(msg)
django.urls.exceptions.NoReverseMatch: Reverse for 'home' not found. 'home' is not a valid view function or pattern name.
[ERROR] 2021-11-12 21:26:28,896 django.request: Internal Server Error: /home_page/
Traceback (most recent call last):
  File "/Users/rileymarsden/.local/share/virtualenvs/EasyConnect-40Y_jyS5/lib/python3.9/site-packages/django/core/handlers/exception.py", line 47, in inner
    response = get_response(request)
  File "/Users/rileymarsden/.local/share/virtualenvs/EasyConnect-40Y_jyS5/lib/python3.9/site-packages/django/core/handlers/base.py", line 181, in _get_response
    response = wrapped_callback(request, *callback_args, **callback_kwargs)
  File "/Users/rileymarsden/Desktop/EasyConnect/EasyConnect/views.py", line 6, in HomePageView
    return render(request, 'home.html', context)
  File "/Users/rileymarsden/.local/share/virtualenvs/EasyConnect-40Y_jyS5/lib/python3.9/site-packages/django/shortcuts.py", line 19, in render
    content = loader.render_to_string(template_name, context, request, using=using)
  File "/Users/rileymarsden/.local/share/virtualenvs/EasyConnect-40Y_jyS5/lib/python3.9/site-packages/django/template/loader.py", line 62, in render_to_string
    return template.render(context, request)
  File "/Users/rileymarsden/.local/share/virtualenvs/EasyConnect-40Y_jyS5/lib/python3.9/site-packages/django/template/backends/django.py", line 61, in render
    return self.template.render(context)
  File "/Users/rileymarsden/.local/share/virtualenvs/EasyConnect-40Y_jyS5/lib/python3.9/site-packages/django/template/base.py", line 170, in render
    return self._render(context)
  File "/Users/rileymarsden/.local/share/virtualenvs/EasyConnect-40Y_jyS5/lib/python3.9/site-packages/django/template/base.py", line 162, in _render
    return self.nodelist.render(context)
  File "/Users/rileymarsden/.local/share/virtualenvs/EasyConnect-40Y_jyS5/lib/python3.9/site-packages/django/template/base.py", line 938, in render
    bit = node.render_annotated(context)
  File "/Users/rileymarsden/.local/share/virtualenvs/EasyConnect-40Y_jyS5/lib/python3.9/site-packages/django/template/base.py", line 905, in render_annotated
    return self.render(context)
  File "/Users/rileymarsden/.local/share/virtualenvs/EasyConnect-40Y_jyS5/lib/python3.9/site-packages/django/template/loader_tags.py", line 150, in render
    return compiled_parent._render(context)
  File "/Users/rileymarsden/.local/share/virtualenvs/EasyConnect-40Y_jyS5/lib/python3.9/site-packages/django/template/base.py", line 162, in _render
    return self.nodelist.render(context)
  File "/Users/rileymarsden/.local/share/virtualenvs/EasyConnect-40Y_jyS5/lib/python3.9/site-packages/django/template/base.py", line 938, in render
    bit = node.render_annotated(context)
  File "/Users/rileymarsden/.local/share/virtualenvs/EasyConnect-40Y_jyS5/lib/python3.9/site-packages/django/template/base.py", line 905, in render_annotated
    return self.render(context)
  File "/Users/rileymarsden/.local/share/virtualenvs/EasyConnect-40Y_jyS5/lib/python3.9/site-packages/django/template/loader_tags.py", line 62, in render
    result = block.nodelist.render(context)
  File "/Users/rileymarsden/.local/share/virtualenvs/EasyConnect-40Y_jyS5/lib/python3.9/site-packages/django/template/base.py", line 938, in render
    bit = node.render_annotated(context)
  File "/Users/rileymarsden/.local/share/virtualenvs/EasyConnect-40Y_jyS5/lib/python3.9/site-packages/django/template/base.py", line 905, in render_annotated
    return self.render(context)
  File "/Users/rileymarsden/.local/share/virtualenvs/EasyConnect-40Y_jyS5/lib/python3.9/site-packages/django/template/defaulttags.py", line 446, in render
    url = reverse(view_name, args=args, kwargs=kwargs, current_app=current_app)
  File "/Users/rileymarsden/.local/share/virtualenvs/EasyConnect-40Y_jyS5/lib/python3.9/site-packages/django/urls/base.py", line 87, in reverse
    return iri_to_uri(resolver._reverse_with_prefix(view, prefix, *args, **kwargs))
  File "/Users/rileymarsden/.local/share/virtualenvs/EasyConnect-40Y_jyS5/lib/python3.9/site-packages/django/urls/resolvers.py", line 685, in _reverse_with_prefix
    raise NoReverseMatch(msg)
django.urls.exceptions.NoReverseMatch: Reverse for 'home' not found. 'home' is not a valid view function or pattern name.
[ERROR] 2021-11-13 05:57:25,856 django.request: Internal Server Error: /Home
Traceback (most recent call last):
  File "/Users/rileymarsden/.local/share/virtualenvs/EasyConnect-40Y_jyS5/lib/python3.9/site-packages/django/template/smartif.py", line 175, in translate_token
    op = OPERATORS[token]
KeyError: '!request.user.is_authenticated'

During handling of the above exception, another exception occurred:

Traceback (most recent call last):
  File "/Users/rileymarsden/.local/share/virtualenvs/EasyConnect-40Y_jyS5/lib/python3.9/site-packages/django/core/handlers/exception.py", line 47, in inner
    response = get_response(request)
  File "/Users/rileymarsden/.local/share/virtualenvs/EasyConnect-40Y_jyS5/lib/python3.9/site-packages/django/core/handlers/base.py", line 181, in _get_response
    response = wrapped_callback(request, *callback_args, **callback_kwargs)
  File "/Users/rileymarsden/Desktop/EasyConnect/EasyConnect/views.py", line 6, in HomePageView
    return render(request, 'home.html', context)
  File "/Users/rileymarsden/.local/share/virtualenvs/EasyConnect-40Y_jyS5/lib/python3.9/site-packages/django/shortcuts.py", line 19, in render
    content = loader.render_to_string(template_name, context, request, using=using)
  File "/Users/rileymarsden/.local/share/virtualenvs/EasyConnect-40Y_jyS5/lib/python3.9/site-packages/django/template/loader.py", line 61, in render_to_string
    template = get_template(template_name, using=using)
  File "/Users/rileymarsden/.local/share/virtualenvs/EasyConnect-40Y_jyS5/lib/python3.9/site-packages/django/template/loader.py", line 15, in get_template
    return engine.get_template(template_name)
  File "/Users/rileymarsden/.local/share/virtualenvs/EasyConnect-40Y_jyS5/lib/python3.9/site-packages/django/template/backends/django.py", line 34, in get_template
    return Template(self.engine.get_template(template_name), self)
  File "/Users/rileymarsden/.local/share/virtualenvs/EasyConnect-40Y_jyS5/lib/python3.9/site-packages/django/template/engine.py", line 143, in get_template
    template, origin = self.find_template(template_name)
  File "/Users/rileymarsden/.local/share/virtualenvs/EasyConnect-40Y_jyS5/lib/python3.9/site-packages/django/template/engine.py", line 125, in find_template
    template = loader.get_template(name, skip=skip)
  File "/Users/rileymarsden/.local/share/virtualenvs/EasyConnect-40Y_jyS5/lib/python3.9/site-packages/django/template/loaders/base.py", line 29, in get_template
    return Template(
  File "/Users/rileymarsden/.local/share/virtualenvs/EasyConnect-40Y_jyS5/lib/python3.9/site-packages/django/template/base.py", line 155, in __init__
    self.nodelist = self.compile_nodelist()
  File "/Users/rileymarsden/.local/share/virtualenvs/EasyConnect-40Y_jyS5/lib/python3.9/site-packages/django/template/base.py", line 193, in compile_nodelist
    return parser.parse()
  File "/Users/rileymarsden/.local/share/virtualenvs/EasyConnect-40Y_jyS5/lib/python3.9/site-packages/django/template/base.py", line 478, in parse
    raise self.error(token, e)
  File "/Users/rileymarsden/.local/share/virtualenvs/EasyConnect-40Y_jyS5/lib/python3.9/site-packages/django/template/base.py", line 476, in parse
    compiled_result = compile_func(self, token)
  File "/Users/rileymarsden/.local/share/virtualenvs/EasyConnect-40Y_jyS5/lib/python3.9/site-packages/django/template/loader_tags.py", line 270, in do_extends
    nodelist = parser.parse()
  File "/Users/rileymarsden/.local/share/virtualenvs/EasyConnect-40Y_jyS5/lib/python3.9/site-packages/django/template/base.py", line 478, in parse
    raise self.error(token, e)
  File "/Users/rileymarsden/.local/share/virtualenvs/EasyConnect-40Y_jyS5/lib/python3.9/site-packages/django/template/base.py", line 476, in parse
    compiled_result = compile_func(self, token)
  File "/Users/rileymarsden/.local/share/virtualenvs/EasyConnect-40Y_jyS5/lib/python3.9/site-packages/django/template/loader_tags.py", line 213, in do_block
    nodelist = parser.parse(('endblock',))
  File "/Users/rileymarsden/.local/share/virtualenvs/EasyConnect-40Y_jyS5/lib/python3.9/site-packages/django/template/base.py", line 478, in parse
    raise self.error(token, e)
  File "/Users/rileymarsden/.local/share/virtualenvs/EasyConnect-40Y_jyS5/lib/python3.9/site-packages/django/template/base.py", line 476, in parse
    compiled_result = compile_func(self, token)
  File "/Users/rileymarsden/.local/share/virtualenvs/EasyConnect-40Y_jyS5/lib/python3.9/site-packages/django/template/defaulttags.py", line 964, in do_if
    condition = TemplateIfParser(parser, bits).parse()
  File "/Users/rileymarsden/.local/share/virtualenvs/EasyConnect-40Y_jyS5/lib/python3.9/site-packages/django/template/defaulttags.py", line 897, in __init__
    super().__init__(*args, **kwargs)
  File "/Users/rileymarsden/.local/share/virtualenvs/EasyConnect-40Y_jyS5/lib/python3.9/site-packages/django/template/smartif.py", line 166, in __init__
    mapped_tokens.append(self.translate_token(token))
  File "/Users/rileymarsden/.local/share/virtualenvs/EasyConnect-40Y_jyS5/lib/python3.9/site-packages/django/template/smartif.py", line 177, in translate_token
    return self.create_var(token)
  File "/Users/rileymarsden/.local/share/virtualenvs/EasyConnect-40Y_jyS5/lib/python3.9/site-packages/django/template/defaulttags.py", line 900, in create_var
    return TemplateLiteral(self.template_parser.compile_filter(value), value)
  File "/Users/rileymarsden/.local/share/virtualenvs/EasyConnect-40Y_jyS5/lib/python3.9/site-packages/django/template/base.py", line 563, in compile_filter
    return FilterExpression(token, self)
  File "/Users/rileymarsden/.local/share/virtualenvs/EasyConnect-40Y_jyS5/lib/python3.9/site-packages/django/template/base.py", line 662, in __init__
    raise TemplateSyntaxError("Could not parse the remainder: '%s' "
django.template.exceptions.TemplateSyntaxError: Could not parse the remainder: '!request.user.is_authenticated' from '!request.user.is_authenticated'
[ERROR] 2021-11-13 06:00:33,488 django.request: Internal Server Error: /profile
Traceback (most recent call last):
  File "/Users/rileymarsden/.local/share/virtualenvs/EasyConnect-40Y_jyS5/lib/python3.9/site-packages/django/core/handlers/exception.py", line 47, in inner
    response = get_response(request)
  File "/Users/rileymarsden/.local/share/virtualenvs/EasyConnect-40Y_jyS5/lib/python3.9/site-packages/django/core/handlers/base.py", line 181, in _get_response
    response = wrapped_callback(request, *callback_args, **callback_kwargs)
  File "/Users/rileymarsden/Desktop/EasyConnect/EasyConnect/views.py", line 10, in ProfileView
    return render(request, 'profile.html', context)
  File "/Users/rileymarsden/.local/share/virtualenvs/EasyConnect-40Y_jyS5/lib/python3.9/site-packages/django/shortcuts.py", line 19, in render
    content = loader.render_to_string(template_name, context, request, using=using)
  File "/Users/rileymarsden/.local/share/virtualenvs/EasyConnect-40Y_jyS5/lib/python3.9/site-packages/django/template/loader.py", line 62, in render_to_string
    return template.render(context, request)
  File "/Users/rileymarsden/.local/share/virtualenvs/EasyConnect-40Y_jyS5/lib/python3.9/site-packages/django/template/backends/django.py", line 61, in render
    return self.template.render(context)
  File "/Users/rileymarsden/.local/share/virtualenvs/EasyConnect-40Y_jyS5/lib/python3.9/site-packages/django/template/base.py", line 170, in render
    return self._render(context)
  File "/Users/rileymarsden/.local/share/virtualenvs/EasyConnect-40Y_jyS5/lib/python3.9/site-packages/django/template/base.py", line 162, in _render
    return self.nodelist.render(context)
  File "/Users/rileymarsden/.local/share/virtualenvs/EasyConnect-40Y_jyS5/lib/python3.9/site-packages/django/template/base.py", line 938, in render
    bit = node.render_annotated(context)
  File "/Users/rileymarsden/.local/share/virtualenvs/EasyConnect-40Y_jyS5/lib/python3.9/site-packages/django/template/base.py", line 905, in render_annotated
    return self.render(context)
  File "/Users/rileymarsden/.local/share/virtualenvs/EasyConnect-40Y_jyS5/lib/python3.9/site-packages/django/template/loader_tags.py", line 127, in render
    compiled_parent = self.get_parent(context)
  File "/Users/rileymarsden/.local/share/virtualenvs/EasyConnect-40Y_jyS5/lib/python3.9/site-packages/django/template/loader_tags.py", line 124, in get_parent
    return self.find_template(parent, context)
  File "/Users/rileymarsden/.local/share/virtualenvs/EasyConnect-40Y_jyS5/lib/python3.9/site-packages/django/template/loader_tags.py", line 103, in find_template
    template, origin = context.template.engine.find_template(
  File "/Users/rileymarsden/.local/share/virtualenvs/EasyConnect-40Y_jyS5/lib/python3.9/site-packages/django/template/engine.py", line 125, in find_template
    template = loader.get_template(name, skip=skip)
  File "/Users/rileymarsden/.local/share/virtualenvs/EasyConnect-40Y_jyS5/lib/python3.9/site-packages/django/template/loaders/base.py", line 29, in get_template
    return Template(
  File "/Users/rileymarsden/.local/share/virtualenvs/EasyConnect-40Y_jyS5/lib/python3.9/site-packages/django/template/base.py", line 155, in __init__
    self.nodelist = self.compile_nodelist()
  File "/Users/rileymarsden/.local/share/virtualenvs/EasyConnect-40Y_jyS5/lib/python3.9/site-packages/django/template/base.py", line 193, in compile_nodelist
    return parser.parse()
  File "/Users/rileymarsden/.local/share/virtualenvs/EasyConnect-40Y_jyS5/lib/python3.9/site-packages/django/template/base.py", line 478, in parse
    raise self.error(token, e)
  File "/Users/rileymarsden/.local/share/virtualenvs/EasyConnect-40Y_jyS5/lib/python3.9/site-packages/django/template/base.py", line 476, in parse
    compiled_result = compile_func(self, token)
  File "/Users/rileymarsden/.local/share/virtualenvs/EasyConnect-40Y_jyS5/lib/python3.9/site-packages/django/template/defaulttags.py", line 979, in do_if
    nodelist = parser.parse(('endif',))
  File "/Users/rileymarsden/.local/share/virtualenvs/EasyConnect-40Y_jyS5/lib/python3.9/site-packages/django/template/base.py", line 483, in parse
    self.unclosed_block_tag(parse_until)
  File "/Users/rileymarsden/.local/share/virtualenvs/EasyConnect-40Y_jyS5/lib/python3.9/site-packages/django/template/base.py", line 544, in unclosed_block_tag
    raise self.error(token, msg)
django.template.exceptions.TemplateSyntaxError: Unclosed tag on line 43: 'if'. Looking for one of: endif.
<<<<<<< HEAD
[ERROR] 2021-11-17 21:59:10,735 django.request: Internal Server Error: /adminsignup/
Traceback (most recent call last):
  File "C:\Users\werkc\.virtualenvs\easyconnect-JWSqFyg0\lib\site-packages\django\template\base.py", line 470, in parse
    compile_func = self.tags[command]
KeyError: 'static'
=======
[ERROR] 2021-11-16 00:55:07,395 django.request: Internal Server Error: /adminsignup/
Traceback (most recent call last):
  File "/Users/rileymarsden/.local/share/virtualenvs/EasyConnect-40Y_jyS5/lib/python3.9/site-packages/django/core/handlers/exception.py", line 47, in inner
    response = get_response(request)
  File "/Users/rileymarsden/.local/share/virtualenvs/EasyConnect-40Y_jyS5/lib/python3.9/site-packages/django/core/handlers/base.py", line 181, in _get_response
    response = wrapped_callback(request, *callback_args, **callback_kwargs)
  File "/Users/rileymarsden/Desktop/EasyConnect/customuser/views.py", line 38, in SignUpAdminView
    Group.objects.get(name=org_name).user_set.add(group)
  File "/Users/rileymarsden/.local/share/virtualenvs/EasyConnect-40Y_jyS5/lib/python3.9/site-packages/django/db/models/fields/related_descriptors.py", line 950, in add
    self._add_items(
  File "/Users/rileymarsden/.local/share/virtualenvs/EasyConnect-40Y_jyS5/lib/python3.9/site-packages/django/db/models/fields/related_descriptors.py", line 1126, in _add_items
    target_ids = self._get_target_ids(target_field_name, objs)
  File "/Users/rileymarsden/.local/share/virtualenvs/EasyConnect-40Y_jyS5/lib/python3.9/site-packages/django/db/models/fields/related_descriptors.py", line 1068, in _get_target_ids
    raise TypeError(
TypeError: 'CustomUser' instance expected, got <Group: TestingGroupFunction>
[ERROR] 2021-11-16 01:09:23,474 django.request: Internal Server Error: /adminsignup/
Traceback (most recent call last):
  File "/Users/rileymarsden/.local/share/virtualenvs/EasyConnect-40Y_jyS5/lib/python3.9/site-packages/django/core/handlers/exception.py", line 47, in inner
    response = get_response(request)
  File "/Users/rileymarsden/.local/share/virtualenvs/EasyConnect-40Y_jyS5/lib/python3.9/site-packages/django/core/handlers/base.py", line 181, in _get_response
    response = wrapped_callback(request, *callback_args, **callback_kwargs)
  File "/Users/rileymarsden/Desktop/EasyConnect/customuser/views.py", line 37, in SignUpAdminView
    group.save()
AttributeError: 'tuple' object has no attribute 'save'
[ERROR] 2021-11-16 01:11:22,964 django.request: Internal Server Error: /adminsignup/
Traceback (most recent call last):
  File "/Users/rileymarsden/.local/share/virtualenvs/EasyConnect-40Y_jyS5/lib/python3.9/site-packages/django/core/handlers/exception.py", line 47, in inner
    response = get_response(request)
  File "/Users/rileymarsden/.local/share/virtualenvs/EasyConnect-40Y_jyS5/lib/python3.9/site-packages/django/core/handlers/base.py", line 181, in _get_response
    response = wrapped_callback(request, *callback_args, **callback_kwargs)
  File "/Users/rileymarsden/Desktop/EasyConnect/customuser/views.py", line 37, in SignUpAdminView
    form.groups.add(group)
AttributeError: 'CustomUserCreationAdminForm' object has no attribute 'groups'
[ERROR] 2021-11-16 01:15:58,436 django.request: Internal Server Error: /adminsignup/
Traceback (most recent call last):
  File "/Users/rileymarsden/.local/share/virtualenvs/EasyConnect-40Y_jyS5/lib/python3.9/site-packages/django/core/handlers/exception.py", line 47, in inner
    response = get_response(request)
  File "/Users/rileymarsden/.local/share/virtualenvs/EasyConnect-40Y_jyS5/lib/python3.9/site-packages/django/core/handlers/base.py", line 181, in _get_response
    response = wrapped_callback(request, *callback_args, **callback_kwargs)
  File "/Users/rileymarsden/Desktop/EasyConnect/customuser/views.py", line 38, in SignUpAdminView
    form.user_set.add(group)
AttributeError: 'CustomUserCreationAdminForm' object has no attribute 'user_set'
[ERROR] 2021-11-16 01:21:46,122 django.request: Internal Server Error: /adminsignup/
Traceback (most recent call last):
  File "/Users/rileymarsden/.local/share/virtualenvs/EasyConnect-40Y_jyS5/lib/python3.9/site-packages/django/core/handlers/exception.py", line 47, in inner
    response = get_response(request)
  File "/Users/rileymarsden/.local/share/virtualenvs/EasyConnect-40Y_jyS5/lib/python3.9/site-packages/django/core/handlers/base.py", line 181, in _get_response
    response = wrapped_callback(request, *callback_args, **callback_kwargs)
  File "/Users/rileymarsden/Desktop/EasyConnect/customuser/views.py", line 37, in SignUpAdminView
    user = form.object.get(username=form.cleaned_data.get('username'))
AttributeError: 'CustomUserCreationAdminForm' object has no attribute 'object'
[ERROR] 2021-11-16 01:24:08,844 django.request: Internal Server Error: /adminsignup/
Traceback (most recent call last):
  File "/Users/rileymarsden/.local/share/virtualenvs/EasyConnect-40Y_jyS5/lib/python3.9/site-packages/django/core/handlers/exception.py", line 47, in inner
    response = get_response(request)
  File "/Users/rileymarsden/.local/share/virtualenvs/EasyConnect-40Y_jyS5/lib/python3.9/site-packages/django/core/handlers/base.py", line 181, in _get_response
    response = wrapped_callback(request, *callback_args, **callback_kwargs)
  File "/Users/rileymarsden/Desktop/EasyConnect/customuser/views.py", line 40, in SignUpAdminView
    user.groups.add(group)
AttributeError: 'str' object has no attribute 'groups'
[ERROR] 2021-11-16 01:26:45,819 django.request: Internal Server Error: /adminsignup/
Traceback (most recent call last):
  File "/Users/rileymarsden/.local/share/virtualenvs/EasyConnect-40Y_jyS5/lib/python3.9/site-packages/django/core/handlers/exception.py", line 47, in inner
    response = get_response(request)
  File "/Users/rileymarsden/.local/share/virtualenvs/EasyConnect-40Y_jyS5/lib/python3.9/site-packages/django/core/handlers/base.py", line 181, in _get_response
    response = wrapped_callback(request, *callback_args, **callback_kwargs)
  File "/Users/rileymarsden/Desktop/EasyConnect/customuser/views.py", line 37, in SignUpAdminView
    user= User.objects.get(username=form.cleaned_data.get('username'))
  File "/Users/rileymarsden/.local/share/virtualenvs/EasyConnect-40Y_jyS5/lib/python3.9/site-packages/django/db/models/manager.py", line 187, in __get__
    raise AttributeError(
AttributeError: Manager isn't available; 'auth.User' has been swapped for 'customuser.CustomUser'
[ERROR] 2021-11-16 01:35:22,201 django.request: Internal Server Error: /adminsignup/
Traceback (most recent call last):
  File "/Users/rileymarsden/.local/share/virtualenvs/EasyConnect-40Y_jyS5/lib/python3.9/site-packages/django/core/handlers/exception.py", line 47, in inner
    response = get_response(request)
  File "/Users/rileymarsden/.local/share/virtualenvs/EasyConnect-40Y_jyS5/lib/python3.9/site-packages/django/core/handlers/base.py", line 181, in _get_response
    response = wrapped_callback(request, *callback_args, **callback_kwargs)
  File "/Users/rileymarsden/Desktop/EasyConnect/customuser/views.py", line 40, in SignUpAdminView
    group.user_set.add(form.instance)
AttributeError: 'tuple' object has no attribute 'user_set'
[ERROR] 2021-11-16 01:38:58,237 django.request: Internal Server Error: /adminsignup/
Traceback (most recent call last):
  File "/Users/rileymarsden/.local/share/virtualenvs/EasyConnect-40Y_jyS5/lib/python3.9/site-packages/django/core/handlers/exception.py", line 47, in inner
    response = get_response(request)
  File "/Users/rileymarsden/.local/share/virtualenvs/EasyConnect-40Y_jyS5/lib/python3.9/site-packages/django/core/handlers/base.py", line 181, in _get_response
    response = wrapped_callback(request, *callback_args, **callback_kwargs)
  File "/Users/rileymarsden/Desktop/EasyConnect/customuser/views.py", line 42, in SignUpAdminView
    groups2[0] = group
IndexError: list assignment index out of range
[ERROR] 2021-11-16 01:39:55,911 django.request: Internal Server Error: /adminsignup/
Traceback (most recent call last):
  File "/Users/rileymarsden/.local/share/virtualenvs/EasyConnect-40Y_jyS5/lib/python3.9/site-packages/django/core/handlers/exception.py", line 47, in inner
    response = get_response(request)
  File "/Users/rileymarsden/.local/share/virtualenvs/EasyConnect-40Y_jyS5/lib/python3.9/site-packages/django/core/handlers/base.py", line 181, in _get_response
    response = wrapped_callback(request, *callback_args, **callback_kwargs)
  File "/Users/rileymarsden/Desktop/EasyConnect/customuser/views.py", line 43, in SignUpAdminView
    group[0].user_set.add(form.instance)
  File "/Users/rileymarsden/.local/share/virtualenvs/EasyConnect-40Y_jyS5/lib/python3.9/site-packages/django/db/models/fields/related_descriptors.py", line 950, in add
    self._add_items(
  File "/Users/rileymarsden/.local/share/virtualenvs/EasyConnect-40Y_jyS5/lib/python3.9/site-packages/django/db/models/fields/related_descriptors.py", line 1126, in _add_items
    target_ids = self._get_target_ids(target_field_name, objs)
  File "/Users/rileymarsden/.local/share/virtualenvs/EasyConnect-40Y_jyS5/lib/python3.9/site-packages/django/db/models/fields/related_descriptors.py", line 1055, in _get_target_ids
    raise ValueError(
ValueError: Cannot add "<CustomUser: TestingGroupFunction:  >": instance is on database "default", value is on database "None"
[ERROR] 2021-11-16 01:41:18,756 django.request: Internal Server Error: /adminsignup/
Traceback (most recent call last):
  File "/Users/rileymarsden/.local/share/virtualenvs/EasyConnect-40Y_jyS5/lib/python3.9/site-packages/django/core/handlers/exception.py", line 47, in inner
    response = get_response(request)
  File "/Users/rileymarsden/.local/share/virtualenvs/EasyConnect-40Y_jyS5/lib/python3.9/site-packages/django/core/handlers/base.py", line 181, in _get_response
    response = wrapped_callback(request, *callback_args, **callback_kwargs)
  File "/Users/rileymarsden/Desktop/EasyConnect/customuser/views.py", line 43, in SignUpAdminView
    groups2[count].user_set.add(group)
AttributeError: 'tuple' object has no attribute 'user_set'
[ERROR] 2021-11-16 01:42:57,828 django.request: Internal Server Error: /adminsignup/
Traceback (most recent call last):
  File "/Users/rileymarsden/.local/share/virtualenvs/EasyConnect-40Y_jyS5/lib/python3.9/site-packages/django/core/handlers/exception.py", line 47, in inner
    response = get_response(request)
  File "/Users/rileymarsden/.local/share/virtualenvs/EasyConnect-40Y_jyS5/lib/python3.9/site-packages/django/core/handlers/base.py", line 181, in _get_response
    response = wrapped_callback(request, *callback_args, **callback_kwargs)
  File "/Users/rileymarsden/Desktop/EasyConnect/customuser/views.py", line 43, in SignUpAdminView
    Group.user_set.add(groups2[count])
AttributeError: 'ManyToManyDescriptor' object has no attribute 'add'
[ERROR] 2021-11-16 02:27:14,026 django.request: Internal Server Error: /adminsignup/
Traceback (most recent call last):
  File "/Users/rileymarsden/.local/share/virtualenvs/EasyConnect-40Y_jyS5/lib/python3.9/site-packages/django/core/handlers/exception.py", line 47, in inner
    response = get_response(request)
  File "/Users/rileymarsden/.local/share/virtualenvs/EasyConnect-40Y_jyS5/lib/python3.9/site-packages/django/core/handlers/base.py", line 181, in _get_response
    response = wrapped_callback(request, *callback_args, **callback_kwargs)
  File "/Users/rileymarsden/Desktop/EasyConnect/customuser/views.py", line 40, in SignUpAdminView
    group = g.objects.get_or_create(name=org_name)
  File "/Users/rileymarsden/.local/share/virtualenvs/EasyConnect-40Y_jyS5/lib/python3.9/site-packages/django/db/models/manager.py", line 179, in __get__
    raise AttributeError("Manager isn't accessible via %s instances" % cls.__name__)
AttributeError: Manager isn't accessible via Group instances
[ERROR] 2021-11-16 02:30:18,868 django.request: Internal Server Error: /adminsignup/
Traceback (most recent call last):
  File "/Users/rileymarsden/.local/share/virtualenvs/EasyConnect-40Y_jyS5/lib/python3.9/site-packages/django/core/handlers/exception.py", line 47, in inner
    response = get_response(request)
  File "/Users/rileymarsden/.local/share/virtualenvs/EasyConnect-40Y_jyS5/lib/python3.9/site-packages/django/core/handlers/base.py", line 181, in _get_response
    response = wrapped_callback(request, *callback_args, **callback_kwargs)
  File "/Users/rileymarsden/Desktop/EasyConnect/customuser/views.py", line 41, in SignUpAdminView
    request.user.groups.add(group)
AttributeError: 'EmptyManager' object has no attribute 'add'
[ERROR] 2021-11-16 03:02:40,137 django.request: Internal Server Error: /adminsignup/
Traceback (most recent call last):
  File "/Users/rileymarsden/.local/share/virtualenvs/EasyConnect-40Y_jyS5/lib/python3.9/site-packages/django/core/handlers/exception.py", line 47, in inner
    response = get_response(request)
  File "/Users/rileymarsden/.local/share/virtualenvs/EasyConnect-40Y_jyS5/lib/python3.9/site-packages/django/core/handlers/base.py", line 181, in _get_response
    response = wrapped_callback(request, *callback_args, **callback_kwargs)
  File "/Users/rileymarsden/Desktop/EasyConnect/customuser/views.py", line 42, in SignUpAdminView
    current_user.groups.add(group)
AttributeError: 'EmptyManager' object has no attribute 'add'
[ERROR] 2021-11-16 03:05:10,847 django.request: Internal Server Error: /adminsignup/
Traceback (most recent call last):
  File "/Users/rileymarsden/.local/share/virtualenvs/EasyConnect-40Y_jyS5/lib/python3.9/site-packages/django/core/handlers/exception.py", line 47, in inner
    response = get_response(request)
  File "/Users/rileymarsden/.local/share/virtualenvs/EasyConnect-40Y_jyS5/lib/python3.9/site-packages/django/core/handlers/base.py", line 181, in _get_response
    response = wrapped_callback(request, *callback_args, **callback_kwargs)
  File "/Users/rileymarsden/Desktop/EasyConnect/customuser/views.py", line 31, in SignUpAdminView
    form = CustomUserCreationAdminForm(request.POST, user=request.user)
  File "/Users/rileymarsden/.local/share/virtualenvs/EasyConnect-40Y_jyS5/lib/python3.9/site-packages/django/contrib/auth/forms.py", line 109, in __init__
    super().__init__(*args, **kwargs)
TypeError: __init__() got an unexpected keyword argument 'user'
[ERROR] 2021-11-16 03:14:04,503 django.request: Internal Server Error: /adminsignup/
Traceback (most recent call last):
  File "/Users/rileymarsden/.local/share/virtualenvs/EasyConnect-40Y_jyS5/lib/python3.9/site-packages/django/core/handlers/exception.py", line 47, in inner
    response = get_response(request)
  File "/Users/rileymarsden/.local/share/virtualenvs/EasyConnect-40Y_jyS5/lib/python3.9/site-packages/django/core/handlers/base.py", line 181, in _get_response
    response = wrapped_callback(request, *callback_args, **callback_kwargs)
  File "/Users/rileymarsden/Desktop/EasyConnect/customuser/views.py", line 31, in SignUpAdminView
    form = CustomUserCreationAdminForm(request.POST, user=request.user)
  File "/Users/rileymarsden/.local/share/virtualenvs/EasyConnect-40Y_jyS5/lib/python3.9/site-packages/django/contrib/auth/forms.py", line 109, in __init__
    super().__init__(*args, **kwargs)
TypeError: __init__() got an unexpected keyword argument 'user'
[ERROR] 2021-11-16 03:14:40,425 django.request: Internal Server Error: /adminsignup/
Traceback (most recent call last):
  File "/Users/rileymarsden/.local/share/virtualenvs/EasyConnect-40Y_jyS5/lib/python3.9/site-packages/django/db/models/fields/__init__.py", line 1774, in get_prep_value
    return int(value)
TypeError: int() argument must be a string, a bytes-like object or a number, not 'tuple'

The above exception was the direct cause of the following exception:

Traceback (most recent call last):
  File "/Users/rileymarsden/.local/share/virtualenvs/EasyConnect-40Y_jyS5/lib/python3.9/site-packages/django/core/handlers/exception.py", line 47, in inner
    response = get_response(request)
  File "/Users/rileymarsden/.local/share/virtualenvs/EasyConnect-40Y_jyS5/lib/python3.9/site-packages/django/core/handlers/base.py", line 181, in _get_response
    response = wrapped_callback(request, *callback_args, **callback_kwargs)
  File "/Users/rileymarsden/Desktop/EasyConnect/customuser/views.py", line 42, in SignUpAdminView
    user.groups.add(group)
  File "/Users/rileymarsden/.local/share/virtualenvs/EasyConnect-40Y_jyS5/lib/python3.9/site-packages/django/db/models/fields/related_descriptors.py", line 950, in add
    self._add_items(
  File "/Users/rileymarsden/.local/share/virtualenvs/EasyConnect-40Y_jyS5/lib/python3.9/site-packages/django/db/models/fields/related_descriptors.py", line 1126, in _add_items
    target_ids = self._get_target_ids(target_field_name, objs)
  File "/Users/rileymarsden/.local/share/virtualenvs/EasyConnect-40Y_jyS5/lib/python3.9/site-packages/django/db/models/fields/related_descriptors.py", line 1073, in _get_target_ids
    target_ids.add(target_field.get_prep_value(obj))
  File "/Users/rileymarsden/.local/share/virtualenvs/EasyConnect-40Y_jyS5/lib/python3.9/site-packages/django/db/models/fields/related.py", line 977, in get_prep_value
    return self.target_field.get_prep_value(value)
  File "/Users/rileymarsden/.local/share/virtualenvs/EasyConnect-40Y_jyS5/lib/python3.9/site-packages/django/db/models/fields/__init__.py", line 1776, in get_prep_value
    raise e.__class__(
TypeError: Field 'id' expected a number but got (<Group: SwitchUP>, True).
[ERROR] 2021-11-16 03:17:31,243 django.request: Internal Server Error: /adminsignup/
Traceback (most recent call last):
  File "/Users/rileymarsden/.local/share/virtualenvs/EasyConnect-40Y_jyS5/lib/python3.9/site-packages/django/db/models/fields/__init__.py", line 1774, in get_prep_value
    return int(value)
TypeError: int() argument must be a string, a bytes-like object or a number, not 'tuple'

The above exception was the direct cause of the following exception:

Traceback (most recent call last):
  File "/Users/rileymarsden/.local/share/virtualenvs/EasyConnect-40Y_jyS5/lib/python3.9/site-packages/django/core/handlers/exception.py", line 47, in inner
    response = get_response(request)
  File "/Users/rileymarsden/.local/share/virtualenvs/EasyConnect-40Y_jyS5/lib/python3.9/site-packages/django/core/handlers/base.py", line 181, in _get_response
    response = wrapped_callback(request, *callback_args, **callback_kwargs)
  File "/Users/rileymarsden/Desktop/EasyConnect/customuser/views.py", line 42, in SignUpAdminView
    user.groups.add(group)
  File "/Users/rileymarsden/.local/share/virtualenvs/EasyConnect-40Y_jyS5/lib/python3.9/site-packages/django/db/models/fields/related_descriptors.py", line 950, in add
    self._add_items(
  File "/Users/rileymarsden/.local/share/virtualenvs/EasyConnect-40Y_jyS5/lib/python3.9/site-packages/django/db/models/fields/related_descriptors.py", line 1126, in _add_items
    target_ids = self._get_target_ids(target_field_name, objs)
  File "/Users/rileymarsden/.local/share/virtualenvs/EasyConnect-40Y_jyS5/lib/python3.9/site-packages/django/db/models/fields/related_descriptors.py", line 1073, in _get_target_ids
    target_ids.add(target_field.get_prep_value(obj))
  File "/Users/rileymarsden/.local/share/virtualenvs/EasyConnect-40Y_jyS5/lib/python3.9/site-packages/django/db/models/fields/related.py", line 977, in get_prep_value
    return self.target_field.get_prep_value(value)
  File "/Users/rileymarsden/.local/share/virtualenvs/EasyConnect-40Y_jyS5/lib/python3.9/site-packages/django/db/models/fields/__init__.py", line 1776, in get_prep_value
    raise e.__class__(
TypeError: Field 'id' expected a number but got (<Group: SwitchUP2>, True).
[ERROR] 2021-11-16 03:26:50,175 django.request: Internal Server Error: /adminsignup/
Traceback (most recent call last):
  File "/Users/rileymarsden/.local/share/virtualenvs/EasyConnect-40Y_jyS5/lib/python3.9/site-packages/django/core/handlers/exception.py", line 47, in inner
    response = get_response(request)
  File "/Users/rileymarsden/.local/share/virtualenvs/EasyConnect-40Y_jyS5/lib/python3.9/site-packages/django/core/handlers/base.py", line 181, in _get_response
    response = wrapped_callback(request, *callback_args, **callback_kwargs)
  File "/Users/rileymarsden/Desktop/EasyConnect/customuser/views.py", line 45, in SignUpAdminView
    group = Group.objects.get_or_create(name=org_name2 + count)
TypeError: can only concatenate str (not "int") to str
[ERROR] 2021-11-16 03:29:16,524 django.request: Internal Server Error: /adminsignup/
Traceback (most recent call last):
  File "/Users/rileymarsden/.local/share/virtualenvs/EasyConnect-40Y_jyS5/lib/python3.9/site-packages/django/db/models/fields/__init__.py", line 1774, in get_prep_value
    return int(value)
TypeError: int() argument must be a string, a bytes-like object or a number, not 'tuple'

The above exception was the direct cause of the following exception:

Traceback (most recent call last):
  File "/Users/rileymarsden/.local/share/virtualenvs/EasyConnect-40Y_jyS5/lib/python3.9/site-packages/django/core/handlers/exception.py", line 47, in inner
    response = get_response(request)
  File "/Users/rileymarsden/.local/share/virtualenvs/EasyConnect-40Y_jyS5/lib/python3.9/site-packages/django/core/handlers/base.py", line 181, in _get_response
    response = wrapped_callback(request, *callback_args, **callback_kwargs)
  File "/Users/rileymarsden/Desktop/EasyConnect/customuser/views.py", line 46, in SignUpAdminView
    user.groups.add(group)
  File "/Users/rileymarsden/.local/share/virtualenvs/EasyConnect-40Y_jyS5/lib/python3.9/site-packages/django/db/models/fields/related_descriptors.py", line 950, in add
    self._add_items(
  File "/Users/rileymarsden/.local/share/virtualenvs/EasyConnect-40Y_jyS5/lib/python3.9/site-packages/django/db/models/fields/related_descriptors.py", line 1126, in _add_items
    target_ids = self._get_target_ids(target_field_name, objs)
  File "/Users/rileymarsden/.local/share/virtualenvs/EasyConnect-40Y_jyS5/lib/python3.9/site-packages/django/db/models/fields/related_descriptors.py", line 1073, in _get_target_ids
    target_ids.add(target_field.get_prep_value(obj))
  File "/Users/rileymarsden/.local/share/virtualenvs/EasyConnect-40Y_jyS5/lib/python3.9/site-packages/django/db/models/fields/related.py", line 977, in get_prep_value
    return self.target_field.get_prep_value(value)
  File "/Users/rileymarsden/.local/share/virtualenvs/EasyConnect-40Y_jyS5/lib/python3.9/site-packages/django/db/models/fields/__init__.py", line 1776, in get_prep_value
    raise e.__class__(
TypeError: Field 'id' expected a number but got (<Group: testorg60>, True).
[ERROR] 2021-11-16 05:51:50,630 django.request: Internal Server Error: /adminsignup/
Traceback (most recent call last):
  File "/Users/rileymarsden/Desktop/EasyConnect/customuser/views.py", line 41, in SignUpAdminView
    group = Group.objects.get(name=org_name2 + '_' + i)
  File "/Users/rileymarsden/.local/share/virtualenvs/EasyConnect-40Y_jyS5/lib/python3.9/site-packages/django/db/models/manager.py", line 85, in manager_method
    return getattr(self.get_queryset(), name)(*args, **kwargs)
  File "/Users/rileymarsden/.local/share/virtualenvs/EasyConnect-40Y_jyS5/lib/python3.9/site-packages/django/db/models/query.py", line 429, in get
    raise self.model.DoesNotExist(
django.contrib.auth.models.Group.DoesNotExist: Group matching query does not exist.

During handling of the above exception, another exception occurred:

Traceback (most recent call last):
  File "/Users/rileymarsden/Desktop/EasyConnect/customuser/views.py", line 58, in SignUpAdminView
    messages.error(request, e + ' No Groups were created for this oganization. ')
TypeError: unsupported operand type(s) for +: 'DoesNotExist' and 'str'

During handling of the above exception, another exception occurred:

Traceback (most recent call last):
  File "/Users/rileymarsden/.local/share/virtualenvs/EasyConnect-40Y_jyS5/lib/python3.9/site-packages/django/core/handlers/exception.py", line 47, in inner
    response = get_response(request)
  File "/Users/rileymarsden/.local/share/virtualenvs/EasyConnect-40Y_jyS5/lib/python3.9/site-packages/django/core/handlers/base.py", line 181, in _get_response
    response = wrapped_callback(request, *callback_args, **callback_kwargs)
  File "/Users/rileymarsden/Desktop/EasyConnect/customuser/views.py", line 64, in SignUpAdminView
    messages.success(request, 'Token generated for ' + org_name + ': ' + tk.generate_token(org_name))
TypeError: can only concatenate str (not "NoneType") to str
[ERROR] 2021-11-16 06:02:14,704 django.request: Internal Server Error: /adminsignup/
Traceback (most recent call last):
  File "/Users/rileymarsden/Desktop/EasyConnect/customuser/views.py", line 41, in SignUpAdminView
    group = Group.objects.get(name=org_name2 + '_' + i)
  File "/Users/rileymarsden/.local/share/virtualenvs/EasyConnect-40Y_jyS5/lib/python3.9/site-packages/django/db/models/manager.py", line 85, in manager_method
    return getattr(self.get_queryset(), name)(*args, **kwargs)
  File "/Users/rileymarsden/.local/share/virtualenvs/EasyConnect-40Y_jyS5/lib/python3.9/site-packages/django/db/models/query.py", line 429, in get
    raise self.model.DoesNotExist(
django.contrib.auth.models.Group.DoesNotExist: Group matching query does not exist.

During handling of the above exception, another exception occurred:

Traceback (most recent call last):
  File "/Users/rileymarsden/Desktop/EasyConnect/customuser/views.py", line 58, in SignUpAdminView
    messages.error(request, e + ' No Groups were created for this oganization. ')
TypeError: unsupported operand type(s) for +: 'DoesNotExist' and 'str'

During handling of the above exception, another exception occurred:

Traceback (most recent call last):
  File "/Users/rileymarsden/.local/share/virtualenvs/EasyConnect-40Y_jyS5/lib/python3.9/site-packages/django/core/handlers/exception.py", line 47, in inner
    response = get_response(request)
  File "/Users/rileymarsden/.local/share/virtualenvs/EasyConnect-40Y_jyS5/lib/python3.9/site-packages/django/core/handlers/base.py", line 181, in _get_response
    response = wrapped_callback(request, *callback_args, **callback_kwargs)
  File "/Users/rileymarsden/Desktop/EasyConnect/customuser/views.py", line 64, in SignUpAdminView
    messages.success(request, 'Token generated for ' + org_name + ': ' + tk.generate_token(org_name))
TypeError: can only concatenate str (not "NoneType") to str
[ERROR] 2021-11-16 06:42:21,878 django.request: Internal Server Error: /adminsignup/
Traceback (most recent call last):
  File "/Users/rileymarsden/.local/share/virtualenvs/EasyConnect-40Y_jyS5/lib/python3.9/site-packages/django/core/handlers/exception.py", line 47, in inner
    response = get_response(request)
  File "/Users/rileymarsden/.local/share/virtualenvs/EasyConnect-40Y_jyS5/lib/python3.9/site-packages/django/core/handlers/base.py", line 181, in _get_response
    response = wrapped_callback(request, *callback_args, **callback_kwargs)
  File "/Users/rileymarsden/Desktop/EasyConnect/customuser/views.py", line 45, in SignUpAdminView
    FormSaveandAccountCreation(form, user, org_name, sw, request, tk)
  File "/Users/rileymarsden/Desktop/EasyConnect/customuser/views.py", line 105, in FormSaveandAccountCreation
    messages.success(request, 'Account was created for ' + user)
TypeError: can only concatenate str (not "CustomUser") to str
[ERROR] 2021-11-16 06:46:05,179 django.request: Internal Server Error: /adminsignup/
Traceback (most recent call last):
  File "/Users/rileymarsden/.local/share/virtualenvs/EasyConnect-40Y_jyS5/lib/python3.9/site-packages/django/core/handlers/exception.py", line 47, in inner
    response = get_response(request)
  File "/Users/rileymarsden/.local/share/virtualenvs/EasyConnect-40Y_jyS5/lib/python3.9/site-packages/django/core/handlers/base.py", line 181, in _get_response
    response = wrapped_callback(request, *callback_args, **callback_kwargs)
  File "/Users/rileymarsden/Desktop/EasyConnect/customuser/views.py", line 31, in SignUpAdminView
    user = form.save(commit=False)
  File "/Users/rileymarsden/.local/share/virtualenvs/EasyConnect-40Y_jyS5/lib/python3.9/site-packages/django/contrib/auth/forms.py", line 135, in save
    user = super().save(commit=False)
  File "/Users/rileymarsden/.local/share/virtualenvs/EasyConnect-40Y_jyS5/lib/python3.9/site-packages/django/forms/models.py", line 452, in save
    raise ValueError(
ValueError: The CustomUser could not be created because the data didn't validate.
[ERROR] 2021-11-16 06:49:03,659 django.request: Internal Server Error: /adminsignup/
Traceback (most recent call last):
  File "/Users/rileymarsden/.local/share/virtualenvs/EasyConnect-40Y_jyS5/lib/python3.9/site-packages/django/core/handlers/exception.py", line 47, in inner
    response = get_response(request)
  File "/Users/rileymarsden/.local/share/virtualenvs/EasyConnect-40Y_jyS5/lib/python3.9/site-packages/django/core/handlers/base.py", line 181, in _get_response
    response = wrapped_callback(request, *callback_args, **callback_kwargs)
  File "/Users/rileymarsden/Desktop/EasyConnect/customuser/views.py", line 41, in SignUpAdminView
    AddUserToGroup(groups, form, org_name2)
TypeError: AddUserToGroup() missing 1 required positional argument: 'form'
[ERROR] 2021-11-16 06:50:01,032 django.request: Internal Server Error: /adminsignup/
Traceback (most recent call last):
  File "/Users/rileymarsden/.local/share/virtualenvs/EasyConnect-40Y_jyS5/lib/python3.9/site-packages/django/core/handlers/exception.py", line 47, in inner
    response = get_response(request)
  File "/Users/rileymarsden/.local/share/virtualenvs/EasyConnect-40Y_jyS5/lib/python3.9/site-packages/django/core/handlers/base.py", line 181, in _get_response
    response = wrapped_callback(request, *callback_args, **callback_kwargs)
  File "/Users/rileymarsden/Desktop/EasyConnect/customuser/views.py", line 41, in SignUpAdminView
    AddUserToGroup(groups, form, org_name2)
  File "/Users/rileymarsden/Desktop/EasyConnect/customuser/views.py", line 114, in AddUserToGroup
    user = form.save(commit=False)
AttributeError: 'str' object has no attribute 'save'
[ERROR] 2021-11-16 19:32:55,313 django.request: Internal Server Error: /logout/
Traceback (most recent call last):
  File "/Users/rileymarsden/.local/share/virtualenvs/EasyConnect-40Y_jyS5/lib/python3.9/site-packages/django/core/handlers/exception.py", line 47, in inner
    response = get_response(request)
  File "/Users/rileymarsden/.local/share/virtualenvs/EasyConnect-40Y_jyS5/lib/python3.9/site-packages/django/core/handlers/base.py", line 181, in _get_response
    response = wrapped_callback(request, *callback_args, **callback_kwargs)
  File "/Users/rileymarsden/Desktop/EasyConnect/customuser/views.py", line 97, in logout_view
    loggingReports.LogoutGeneral(request, sw)
TypeError: LogoutGeneral() missing 1 required positional argument: 'sw'
[ERROR] 2021-11-16 19:34:59,891 django.request: Internal Server Error: /logout/
Traceback (most recent call last):
  File "/Users/rileymarsden/.local/share/virtualenvs/EasyConnect-40Y_jyS5/lib/python3.9/site-packages/django/core/handlers/exception.py", line 47, in inner
    response = get_response(request)
  File "/Users/rileymarsden/.local/share/virtualenvs/EasyConnect-40Y_jyS5/lib/python3.9/site-packages/django/core/handlers/base.py", line 181, in _get_response
    response = wrapped_callback(request, *callback_args, **callback_kwargs)
  File "/Users/rileymarsden/Desktop/EasyConnect/customuser/views.py", line 97, in logout_view
    loggingReports.LogoutGeneral(request, sw)
TypeError: LogoutGeneral() missing 1 required positional argument: 'stopwatch'
[ERROR] 2021-11-16 19:37:49,887 django.request: Internal Server Error: /logout/
Traceback (most recent call last):
  File "/Users/rileymarsden/.local/share/virtualenvs/EasyConnect-40Y_jyS5/lib/python3.9/site-packages/django/core/handlers/exception.py", line 47, in inner
    response = get_response(request)
  File "/Users/rileymarsden/.local/share/virtualenvs/EasyConnect-40Y_jyS5/lib/python3.9/site-packages/django/core/handlers/base.py", line 181, in _get_response
    response = wrapped_callback(request, *callback_args, **callback_kwargs)
  File "/Users/rileymarsden/Desktop/EasyConnect/customuser/views.py", line 98, in logout_view
    loggingReports.LogoutGeneral(request, sw)
TypeError: LogoutGeneral() missing 1 required positional argument: 'stopwatch'
[ERROR] 2021-11-16 19:39:34,584 django.request: Internal Server Error: /logout/
Traceback (most recent call last):
  File "/Users/rileymarsden/.local/share/virtualenvs/EasyConnect-40Y_jyS5/lib/python3.9/site-packages/django/core/handlers/exception.py", line 47, in inner
    response = get_response(request)
  File "/Users/rileymarsden/.local/share/virtualenvs/EasyConnect-40Y_jyS5/lib/python3.9/site-packages/django/core/handlers/base.py", line 181, in _get_response
    response = wrapped_callback(request, *callback_args, **callback_kwargs)
  File "/Users/rileymarsden/Desktop/EasyConnect/customuser/views.py", line 98, in logout_view
    loggingReports.LogoutGeneral(request, time.process_time() - sw)
TypeError: LogoutGeneral() missing 1 required positional argument: 'stopwatch'
[ERROR] 2021-11-17 20:17:58,212 django.request: Internal Server Error: /adminsignup/
Traceback (most recent call last):
  File "/Users/rileymarsden/Desktop/EasyConnect/customuser/views.py", line 40, in SignUpAdminView
    AddUserToGroup(groups, Org_name_CleanUP(form.cleaned_data.get('Organization_name')), form, True)
TypeError: AddUserToGroup() missing 1 required positional argument: 'org_user_type'

During handling of the above exception, another exception occurred:

Traceback (most recent call last):
  File "/Users/rileymarsden/.local/share/virtualenvs/EasyConnect-40Y_jyS5/lib/python3.9/site-packages/django/db/backends/utils.py", line 84, in _execute
    return self.cursor.execute(sql, params)
  File "/Users/rileymarsden/.local/share/virtualenvs/EasyConnect-40Y_jyS5/lib/python3.9/site-packages/django/db/backends/sqlite3/base.py", line 413, in execute
    return Database.Cursor.execute(self, query, params)
sqlite3.IntegrityError: NOT NULL constraint failed: customuser_customuser.Organizatoin_user_type

The above exception was the direct cause of the following exception:

Traceback (most recent call last):
  File "/Users/rileymarsden/.local/share/virtualenvs/EasyConnect-40Y_jyS5/lib/python3.9/site-packages/django/core/handlers/exception.py", line 47, in inner
    response = get_response(request)
  File "/Users/rileymarsden/.local/share/virtualenvs/EasyConnect-40Y_jyS5/lib/python3.9/site-packages/django/core/handlers/base.py", line 181, in _get_response
    response = wrapped_callback(request, *callback_args, **callback_kwargs)
  File "/Users/rileymarsden/Desktop/EasyConnect/customuser/views.py", line 43, in SignUpAdminView
    FormSaveandAccountCreation(form, Org_name_CleanUP(form.cleaned_data.get('Organization_name')), sw, request, tk, True)
  File "/Users/rileymarsden/Desktop/EasyConnect/customuser/views.py", line 112, in FormSaveandAccountCreation
    formsdata.save()
  File "/Users/rileymarsden/.local/share/virtualenvs/EasyConnect-40Y_jyS5/lib/python3.9/site-packages/django/contrib/auth/forms.py", line 138, in save
    user.save()
  File "/Users/rileymarsden/.local/share/virtualenvs/EasyConnect-40Y_jyS5/lib/python3.9/site-packages/django/contrib/auth/base_user.py", line 67, in save
    super().save(*args, **kwargs)
  File "/Users/rileymarsden/.local/share/virtualenvs/EasyConnect-40Y_jyS5/lib/python3.9/site-packages/django/db/models/base.py", line 753, in save
    self.save_base(using=using, force_insert=force_insert,
  File "/Users/rileymarsden/.local/share/virtualenvs/EasyConnect-40Y_jyS5/lib/python3.9/site-packages/django/db/models/base.py", line 790, in save_base
    updated = self._save_table(
  File "/Users/rileymarsden/.local/share/virtualenvs/EasyConnect-40Y_jyS5/lib/python3.9/site-packages/django/db/models/base.py", line 895, in _save_table
    results = self._do_insert(cls._base_manager, using, fields, returning_fields, raw)
  File "/Users/rileymarsden/.local/share/virtualenvs/EasyConnect-40Y_jyS5/lib/python3.9/site-packages/django/db/models/base.py", line 933, in _do_insert
    return manager._insert(
  File "/Users/rileymarsden/.local/share/virtualenvs/EasyConnect-40Y_jyS5/lib/python3.9/site-packages/django/db/models/manager.py", line 85, in manager_method
    return getattr(self.get_queryset(), name)(*args, **kwargs)
  File "/Users/rileymarsden/.local/share/virtualenvs/EasyConnect-40Y_jyS5/lib/python3.9/site-packages/django/db/models/query.py", line 1254, in _insert
    return query.get_compiler(using=using).execute_sql(returning_fields)
  File "/Users/rileymarsden/.local/share/virtualenvs/EasyConnect-40Y_jyS5/lib/python3.9/site-packages/django/db/models/sql/compiler.py", line 1397, in execute_sql
    cursor.execute(sql, params)
  File "/Users/rileymarsden/.local/share/virtualenvs/EasyConnect-40Y_jyS5/lib/python3.9/site-packages/django/db/backends/utils.py", line 98, in execute
    return super().execute(sql, params)
  File "/Users/rileymarsden/.local/share/virtualenvs/EasyConnect-40Y_jyS5/lib/python3.9/site-packages/django/db/backends/utils.py", line 66, in execute
    return self._execute_with_wrappers(sql, params, many=False, executor=self._execute)
  File "/Users/rileymarsden/.local/share/virtualenvs/EasyConnect-40Y_jyS5/lib/python3.9/site-packages/django/db/backends/utils.py", line 75, in _execute_with_wrappers
    return executor(sql, params, many, context)
  File "/Users/rileymarsden/.local/share/virtualenvs/EasyConnect-40Y_jyS5/lib/python3.9/site-packages/django/db/backends/utils.py", line 84, in _execute
    return self.cursor.execute(sql, params)
  File "/Users/rileymarsden/.local/share/virtualenvs/EasyConnect-40Y_jyS5/lib/python3.9/site-packages/django/db/utils.py", line 90, in __exit__
    raise dj_exc_value.with_traceback(traceback) from exc_value
  File "/Users/rileymarsden/.local/share/virtualenvs/EasyConnect-40Y_jyS5/lib/python3.9/site-packages/django/db/backends/utils.py", line 84, in _execute
    return self.cursor.execute(sql, params)
  File "/Users/rileymarsden/.local/share/virtualenvs/EasyConnect-40Y_jyS5/lib/python3.9/site-packages/django/db/backends/sqlite3/base.py", line 413, in execute
    return Database.Cursor.execute(self, query, params)
django.db.utils.IntegrityError: NOT NULL constraint failed: customuser_customuser.Organizatoin_user_type
[ERROR] 2021-11-17 20:21:55,623 django.request: Internal Server Error: /adminsignup/
Traceback (most recent call last):
  File "/Users/rileymarsden/.local/share/virtualenvs/EasyConnect-40Y_jyS5/lib/python3.9/site-packages/django/core/handlers/exception.py", line 47, in inner
    response = get_response(request)
  File "/Users/rileymarsden/.local/share/virtualenvs/EasyConnect-40Y_jyS5/lib/python3.9/site-packages/django/core/handlers/base.py", line 181, in _get_response
    response = wrapped_callback(request, *callback_args, **callback_kwargs)
  File "/Users/rileymarsden/Desktop/EasyConnect/customuser/views.py", line 33, in SignUpAdminView
    org_pin = str(form.cleaned_data.get('Organizational_pin'))
AttributeError: 'CustomUserCreationAdminForm' object has no attribute 'cleaned_data'
[ERROR] 2021-11-17 20:25:36,292 django.request: Internal Server Error: /adminsignup/
Traceback (most recent call last):
  File "/Users/rileymarsden/.local/share/virtualenvs/EasyConnect-40Y_jyS5/lib/python3.9/site-packages/django/db/backends/utils.py", line 84, in _execute
    return self.cursor.execute(sql, params)
  File "/Users/rileymarsden/.local/share/virtualenvs/EasyConnect-40Y_jyS5/lib/python3.9/site-packages/django/db/backends/sqlite3/base.py", line 413, in execute
    return Database.Cursor.execute(self, query, params)
sqlite3.IntegrityError: NOT NULL constraint failed: customuser_customuser.Organizatoin_user_type

The above exception was the direct cause of the following exception:

Traceback (most recent call last):
  File "/Users/rileymarsden/Desktop/EasyConnect/customuser/views.py", line 40, in SignUpAdminView
    AddUserToGroup(groups, Org_name_CleanUP(form.cleaned_data.get('Organization_name')), form, True)
  File "/Users/rileymarsden/Desktop/EasyConnect/customuser/views.py", line 118, in AddUserToGroup
    user.save()
  File "/Users/rileymarsden/.local/share/virtualenvs/EasyConnect-40Y_jyS5/lib/python3.9/site-packages/django/contrib/auth/base_user.py", line 67, in save
    super().save(*args, **kwargs)
  File "/Users/rileymarsden/.local/share/virtualenvs/EasyConnect-40Y_jyS5/lib/python3.9/site-packages/django/db/models/base.py", line 753, in save
    self.save_base(using=using, force_insert=force_insert,
  File "/Users/rileymarsden/.local/share/virtualenvs/EasyConnect-40Y_jyS5/lib/python3.9/site-packages/django/db/models/base.py", line 790, in save_base
    updated = self._save_table(
  File "/Users/rileymarsden/.local/share/virtualenvs/EasyConnect-40Y_jyS5/lib/python3.9/site-packages/django/db/models/base.py", line 895, in _save_table
    results = self._do_insert(cls._base_manager, using, fields, returning_fields, raw)
  File "/Users/rileymarsden/.local/share/virtualenvs/EasyConnect-40Y_jyS5/lib/python3.9/site-packages/django/db/models/base.py", line 933, in _do_insert
    return manager._insert(
  File "/Users/rileymarsden/.local/share/virtualenvs/EasyConnect-40Y_jyS5/lib/python3.9/site-packages/django/db/models/manager.py", line 85, in manager_method
    return getattr(self.get_queryset(), name)(*args, **kwargs)
  File "/Users/rileymarsden/.local/share/virtualenvs/EasyConnect-40Y_jyS5/lib/python3.9/site-packages/django/db/models/query.py", line 1254, in _insert
    return query.get_compiler(using=using).execute_sql(returning_fields)
  File "/Users/rileymarsden/.local/share/virtualenvs/EasyConnect-40Y_jyS5/lib/python3.9/site-packages/django/db/models/sql/compiler.py", line 1397, in execute_sql
    cursor.execute(sql, params)
  File "/Users/rileymarsden/.local/share/virtualenvs/EasyConnect-40Y_jyS5/lib/python3.9/site-packages/django/db/backends/utils.py", line 98, in execute
    return super().execute(sql, params)
  File "/Users/rileymarsden/.local/share/virtualenvs/EasyConnect-40Y_jyS5/lib/python3.9/site-packages/django/db/backends/utils.py", line 66, in execute
    return self._execute_with_wrappers(sql, params, many=False, executor=self._execute)
  File "/Users/rileymarsden/.local/share/virtualenvs/EasyConnect-40Y_jyS5/lib/python3.9/site-packages/django/db/backends/utils.py", line 75, in _execute_with_wrappers
    return executor(sql, params, many, context)
  File "/Users/rileymarsden/.local/share/virtualenvs/EasyConnect-40Y_jyS5/lib/python3.9/site-packages/django/db/backends/utils.py", line 84, in _execute
    return self.cursor.execute(sql, params)
  File "/Users/rileymarsden/.local/share/virtualenvs/EasyConnect-40Y_jyS5/lib/python3.9/site-packages/django/db/utils.py", line 90, in __exit__
    raise dj_exc_value.with_traceback(traceback) from exc_value
  File "/Users/rileymarsden/.local/share/virtualenvs/EasyConnect-40Y_jyS5/lib/python3.9/site-packages/django/db/backends/utils.py", line 84, in _execute
    return self.cursor.execute(sql, params)
  File "/Users/rileymarsden/.local/share/virtualenvs/EasyConnect-40Y_jyS5/lib/python3.9/site-packages/django/db/backends/sqlite3/base.py", line 413, in execute
    return Database.Cursor.execute(self, query, params)
django.db.utils.IntegrityError: NOT NULL constraint failed: customuser_customuser.Organizatoin_user_type
>>>>>>> master

During handling of the above exception, another exception occurred:

Traceback (most recent call last):
<<<<<<< HEAD
  File "C:\Users\werkc\.virtualenvs\easyconnect-JWSqFyg0\lib\site-packages\django\core\handlers\exception.py", line 47, in inner
    response = get_response(request)
  File "C:\Users\werkc\.virtualenvs\easyconnect-JWSqFyg0\lib\site-packages\django\core\handlers\base.py", line 181, in _get_response
    response = wrapped_callback(request, *callback_args, **callback_kwargs)
  File "C:\Users\werkc\Desktop\EasyConnect\customuser\views.py", line 46, in SignUpAdminView
    return render(request, 'registration/adminsignup.html', context)
  File "C:\Users\werkc\.virtualenvs\easyconnect-JWSqFyg0\lib\site-packages\django\shortcuts.py", line 19, in render
    content = loader.render_to_string(template_name, context, request, using=using)
  File "C:\Users\werkc\.virtualenvs\easyconnect-JWSqFyg0\lib\site-packages\django\template\loader.py", line 61, in render_to_string
    template = get_template(template_name, using=using)
  File "C:\Users\werkc\.virtualenvs\easyconnect-JWSqFyg0\lib\site-packages\django\template\loader.py", line 15, in get_template
    return engine.get_template(template_name)
  File "C:\Users\werkc\.virtualenvs\easyconnect-JWSqFyg0\lib\site-packages\django\template\backends\django.py", line 34, in get_template
    return Template(self.engine.get_template(template_name), self)
  File "C:\Users\werkc\.virtualenvs\easyconnect-JWSqFyg0\lib\site-packages\django\template\engine.py", line 143, in get_template
    template, origin = self.find_template(template_name)
  File "C:\Users\werkc\.virtualenvs\easyconnect-JWSqFyg0\lib\site-packages\django\template\engine.py", line 125, in find_template
    template = loader.get_template(name, skip=skip)
  File "C:\Users\werkc\.virtualenvs\easyconnect-JWSqFyg0\lib\site-packages\django\template\loaders\base.py", line 29, in get_template
    return Template(
  File "C:\Users\werkc\.virtualenvs\easyconnect-JWSqFyg0\lib\site-packages\django\template\base.py", line 155, in __init__
    self.nodelist = self.compile_nodelist()
  File "C:\Users\werkc\.virtualenvs\easyconnect-JWSqFyg0\lib\site-packages\django\template\base.py", line 193, in compile_nodelist
    return parser.parse()
  File "C:\Users\werkc\.virtualenvs\easyconnect-JWSqFyg0\lib\site-packages\django\template\base.py", line 472, in parse
    self.invalid_block_tag(token, command, parse_until)
  File "C:\Users\werkc\.virtualenvs\easyconnect-JWSqFyg0\lib\site-packages\django\template\base.py", line 531, in invalid_block_tag
    raise self.error(
django.template.exceptions.TemplateSyntaxError: Invalid block tag on line 69: 'static'. Did you forget to register or load this tag?
[ERROR] 2021-11-17 21:59:54,821 django.request: Internal Server Error: /adminsignup/
Traceback (most recent call last):
  File "C:\Users\werkc\.virtualenvs\easyconnect-JWSqFyg0\lib\site-packages\django\template\base.py", line 470, in parse
    compile_func = self.tags[command]
KeyError: 'static'
=======
  File "/Users/rileymarsden/.local/share/virtualenvs/EasyConnect-40Y_jyS5/lib/python3.9/site-packages/django/core/handlers/exception.py", line 47, in inner
    response = get_response(request)
  File "/Users/rileymarsden/.local/share/virtualenvs/EasyConnect-40Y_jyS5/lib/python3.9/site-packages/django/core/handlers/base.py", line 181, in _get_response
    response = wrapped_callback(request, *callback_args, **callback_kwargs)
  File "/Users/rileymarsden/Desktop/EasyConnect/customuser/views.py", line 43, in SignUpAdminView
    FormSaveandAccountCreation(form, Org_name_CleanUP(form.cleaned_data.get('Organization_name')), sw, request, tk)
TypeError: FormSaveandAccountCreation() missing 1 required positional argument: 'is_admin'
[ERROR] 2021-11-17 20:26:46,185 django.request: Internal Server Error: /adminsignup/
Traceback (most recent call last):
  File "/Users/rileymarsden/.local/share/virtualenvs/EasyConnect-40Y_jyS5/lib/python3.9/site-packages/django/db/backends/utils.py", line 84, in _execute
    return self.cursor.execute(sql, params)
  File "/Users/rileymarsden/.local/share/virtualenvs/EasyConnect-40Y_jyS5/lib/python3.9/site-packages/django/db/backends/sqlite3/base.py", line 413, in execute
    return Database.Cursor.execute(self, query, params)
sqlite3.IntegrityError: NOT NULL constraint failed: customuser_customuser.Organizatoin_user_type

The above exception was the direct cause of the following exception:

Traceback (most recent call last):
  File "/Users/rileymarsden/Desktop/EasyConnect/customuser/views.py", line 40, in SignUpAdminView
    AddUserToGroup(groups, Org_name_CleanUP(form.cleaned_data.get('Organization_name')), form, True)
  File "/Users/rileymarsden/Desktop/EasyConnect/customuser/views.py", line 118, in AddUserToGroup
    user.save()
  File "/Users/rileymarsden/.local/share/virtualenvs/EasyConnect-40Y_jyS5/lib/python3.9/site-packages/django/contrib/auth/base_user.py", line 67, in save
    super().save(*args, **kwargs)
  File "/Users/rileymarsden/.local/share/virtualenvs/EasyConnect-40Y_jyS5/lib/python3.9/site-packages/django/db/models/base.py", line 753, in save
    self.save_base(using=using, force_insert=force_insert,
  File "/Users/rileymarsden/.local/share/virtualenvs/EasyConnect-40Y_jyS5/lib/python3.9/site-packages/django/db/models/base.py", line 790, in save_base
    updated = self._save_table(
  File "/Users/rileymarsden/.local/share/virtualenvs/EasyConnect-40Y_jyS5/lib/python3.9/site-packages/django/db/models/base.py", line 895, in _save_table
    results = self._do_insert(cls._base_manager, using, fields, returning_fields, raw)
  File "/Users/rileymarsden/.local/share/virtualenvs/EasyConnect-40Y_jyS5/lib/python3.9/site-packages/django/db/models/base.py", line 933, in _do_insert
    return manager._insert(
  File "/Users/rileymarsden/.local/share/virtualenvs/EasyConnect-40Y_jyS5/lib/python3.9/site-packages/django/db/models/manager.py", line 85, in manager_method
    return getattr(self.get_queryset(), name)(*args, **kwargs)
  File "/Users/rileymarsden/.local/share/virtualenvs/EasyConnect-40Y_jyS5/lib/python3.9/site-packages/django/db/models/query.py", line 1254, in _insert
    return query.get_compiler(using=using).execute_sql(returning_fields)
  File "/Users/rileymarsden/.local/share/virtualenvs/EasyConnect-40Y_jyS5/lib/python3.9/site-packages/django/db/models/sql/compiler.py", line 1397, in execute_sql
    cursor.execute(sql, params)
  File "/Users/rileymarsden/.local/share/virtualenvs/EasyConnect-40Y_jyS5/lib/python3.9/site-packages/django/db/backends/utils.py", line 98, in execute
    return super().execute(sql, params)
  File "/Users/rileymarsden/.local/share/virtualenvs/EasyConnect-40Y_jyS5/lib/python3.9/site-packages/django/db/backends/utils.py", line 66, in execute
    return self._execute_with_wrappers(sql, params, many=False, executor=self._execute)
  File "/Users/rileymarsden/.local/share/virtualenvs/EasyConnect-40Y_jyS5/lib/python3.9/site-packages/django/db/backends/utils.py", line 75, in _execute_with_wrappers
    return executor(sql, params, many, context)
  File "/Users/rileymarsden/.local/share/virtualenvs/EasyConnect-40Y_jyS5/lib/python3.9/site-packages/django/db/backends/utils.py", line 84, in _execute
    return self.cursor.execute(sql, params)
  File "/Users/rileymarsden/.local/share/virtualenvs/EasyConnect-40Y_jyS5/lib/python3.9/site-packages/django/db/utils.py", line 90, in __exit__
    raise dj_exc_value.with_traceback(traceback) from exc_value
  File "/Users/rileymarsden/.local/share/virtualenvs/EasyConnect-40Y_jyS5/lib/python3.9/site-packages/django/db/backends/utils.py", line 84, in _execute
    return self.cursor.execute(sql, params)
  File "/Users/rileymarsden/.local/share/virtualenvs/EasyConnect-40Y_jyS5/lib/python3.9/site-packages/django/db/backends/sqlite3/base.py", line 413, in execute
    return Database.Cursor.execute(self, query, params)
django.db.utils.IntegrityError: NOT NULL constraint failed: customuser_customuser.Organizatoin_user_type
>>>>>>> master

During handling of the above exception, another exception occurred:

Traceback (most recent call last):
<<<<<<< HEAD
  File "C:\Users\werkc\.virtualenvs\easyconnect-JWSqFyg0\lib\site-packages\django\core\handlers\exception.py", line 47, in inner
    response = get_response(request)
  File "C:\Users\werkc\.virtualenvs\easyconnect-JWSqFyg0\lib\site-packages\django\core\handlers\base.py", line 181, in _get_response
    response = wrapped_callback(request, *callback_args, **callback_kwargs)
  File "C:\Users\werkc\Desktop\EasyConnect\customuser\views.py", line 46, in SignUpAdminView
    return render(request, 'registration/adminsignup.html', context)
  File "C:\Users\werkc\.virtualenvs\easyconnect-JWSqFyg0\lib\site-packages\django\shortcuts.py", line 19, in render
    content = loader.render_to_string(template_name, context, request, using=using)
  File "C:\Users\werkc\.virtualenvs\easyconnect-JWSqFyg0\lib\site-packages\django\template\loader.py", line 61, in render_to_string
    template = get_template(template_name, using=using)
  File "C:\Users\werkc\.virtualenvs\easyconnect-JWSqFyg0\lib\site-packages\django\template\loader.py", line 15, in get_template
    return engine.get_template(template_name)
  File "C:\Users\werkc\.virtualenvs\easyconnect-JWSqFyg0\lib\site-packages\django\template\backends\django.py", line 34, in get_template
    return Template(self.engine.get_template(template_name), self)
  File "C:\Users\werkc\.virtualenvs\easyconnect-JWSqFyg0\lib\site-packages\django\template\engine.py", line 143, in get_template
    template, origin = self.find_template(template_name)
  File "C:\Users\werkc\.virtualenvs\easyconnect-JWSqFyg0\lib\site-packages\django\template\engine.py", line 125, in find_template
    template = loader.get_template(name, skip=skip)
  File "C:\Users\werkc\.virtualenvs\easyconnect-JWSqFyg0\lib\site-packages\django\template\loaders\base.py", line 29, in get_template
    return Template(
  File "C:\Users\werkc\.virtualenvs\easyconnect-JWSqFyg0\lib\site-packages\django\template\base.py", line 155, in __init__
    self.nodelist = self.compile_nodelist()
  File "C:\Users\werkc\.virtualenvs\easyconnect-JWSqFyg0\lib\site-packages\django\template\base.py", line 193, in compile_nodelist
    return parser.parse()
  File "C:\Users\werkc\.virtualenvs\easyconnect-JWSqFyg0\lib\site-packages\django\template\base.py", line 472, in parse
    self.invalid_block_tag(token, command, parse_until)
  File "C:\Users\werkc\.virtualenvs\easyconnect-JWSqFyg0\lib\site-packages\django\template\base.py", line 531, in invalid_block_tag
    raise self.error(
django.template.exceptions.TemplateSyntaxError: Invalid block tag on line 71: 'static'. Did you forget to register or load this tag?
[ERROR] 2021-11-19 14:00:15,657 django.request: Internal Server Error: /clienteusignup/
Traceback (most recent call last):
  File "C:\Users\werkc\.virtualenvs\easyconnect-JWSqFyg0\lib\site-packages\django\template\base.py", line 470, in parse
    compile_func = self.tags[command]
KeyError: 'static'
=======
  File "/Users/rileymarsden/.local/share/virtualenvs/EasyConnect-40Y_jyS5/lib/python3.9/site-packages/django/db/backends/utils.py", line 84, in _execute
    return self.cursor.execute(sql, params)
  File "/Users/rileymarsden/.local/share/virtualenvs/EasyConnect-40Y_jyS5/lib/python3.9/site-packages/django/db/backends/sqlite3/base.py", line 413, in execute
    return Database.Cursor.execute(self, query, params)
sqlite3.IntegrityError: NOT NULL constraint failed: customuser_customuser.Organizatoin_user_type

The above exception was the direct cause of the following exception:

Traceback (most recent call last):
  File "/Users/rileymarsden/.local/share/virtualenvs/EasyConnect-40Y_jyS5/lib/python3.9/site-packages/django/core/handlers/exception.py", line 47, in inner
    response = get_response(request)
  File "/Users/rileymarsden/.local/share/virtualenvs/EasyConnect-40Y_jyS5/lib/python3.9/site-packages/django/core/handlers/base.py", line 181, in _get_response
    response = wrapped_callback(request, *callback_args, **callback_kwargs)
  File "/Users/rileymarsden/Desktop/EasyConnect/customuser/views.py", line 43, in SignUpAdminView
    FormSaveandAccountCreation(form, Org_name_CleanUP(form.cleaned_data.get('Organization_name')), sw, request, tk, True)
  File "/Users/rileymarsden/Desktop/EasyConnect/customuser/views.py", line 105, in FormSaveandAccountCreation
    formsdata.save()
  File "/Users/rileymarsden/.local/share/virtualenvs/EasyConnect-40Y_jyS5/lib/python3.9/site-packages/django/contrib/auth/forms.py", line 138, in save
    user.save()
  File "/Users/rileymarsden/.local/share/virtualenvs/EasyConnect-40Y_jyS5/lib/python3.9/site-packages/django/contrib/auth/base_user.py", line 67, in save
    super().save(*args, **kwargs)
  File "/Users/rileymarsden/.local/share/virtualenvs/EasyConnect-40Y_jyS5/lib/python3.9/site-packages/django/db/models/base.py", line 753, in save
    self.save_base(using=using, force_insert=force_insert,
  File "/Users/rileymarsden/.local/share/virtualenvs/EasyConnect-40Y_jyS5/lib/python3.9/site-packages/django/db/models/base.py", line 790, in save_base
    updated = self._save_table(
  File "/Users/rileymarsden/.local/share/virtualenvs/EasyConnect-40Y_jyS5/lib/python3.9/site-packages/django/db/models/base.py", line 895, in _save_table
    results = self._do_insert(cls._base_manager, using, fields, returning_fields, raw)
  File "/Users/rileymarsden/.local/share/virtualenvs/EasyConnect-40Y_jyS5/lib/python3.9/site-packages/django/db/models/base.py", line 933, in _do_insert
    return manager._insert(
  File "/Users/rileymarsden/.local/share/virtualenvs/EasyConnect-40Y_jyS5/lib/python3.9/site-packages/django/db/models/manager.py", line 85, in manager_method
    return getattr(self.get_queryset(), name)(*args, **kwargs)
  File "/Users/rileymarsden/.local/share/virtualenvs/EasyConnect-40Y_jyS5/lib/python3.9/site-packages/django/db/models/query.py", line 1254, in _insert
    return query.get_compiler(using=using).execute_sql(returning_fields)
  File "/Users/rileymarsden/.local/share/virtualenvs/EasyConnect-40Y_jyS5/lib/python3.9/site-packages/django/db/models/sql/compiler.py", line 1397, in execute_sql
    cursor.execute(sql, params)
  File "/Users/rileymarsden/.local/share/virtualenvs/EasyConnect-40Y_jyS5/lib/python3.9/site-packages/django/db/backends/utils.py", line 98, in execute
    return super().execute(sql, params)
  File "/Users/rileymarsden/.local/share/virtualenvs/EasyConnect-40Y_jyS5/lib/python3.9/site-packages/django/db/backends/utils.py", line 66, in execute
    return self._execute_with_wrappers(sql, params, many=False, executor=self._execute)
  File "/Users/rileymarsden/.local/share/virtualenvs/EasyConnect-40Y_jyS5/lib/python3.9/site-packages/django/db/backends/utils.py", line 75, in _execute_with_wrappers
    return executor(sql, params, many, context)
  File "/Users/rileymarsden/.local/share/virtualenvs/EasyConnect-40Y_jyS5/lib/python3.9/site-packages/django/db/backends/utils.py", line 84, in _execute
    return self.cursor.execute(sql, params)
  File "/Users/rileymarsden/.local/share/virtualenvs/EasyConnect-40Y_jyS5/lib/python3.9/site-packages/django/db/utils.py", line 90, in __exit__
    raise dj_exc_value.with_traceback(traceback) from exc_value
  File "/Users/rileymarsden/.local/share/virtualenvs/EasyConnect-40Y_jyS5/lib/python3.9/site-packages/django/db/backends/utils.py", line 84, in _execute
    return self.cursor.execute(sql, params)
  File "/Users/rileymarsden/.local/share/virtualenvs/EasyConnect-40Y_jyS5/lib/python3.9/site-packages/django/db/backends/sqlite3/base.py", line 413, in execute
    return Database.Cursor.execute(self, query, params)
django.db.utils.IntegrityError: NOT NULL constraint failed: customuser_customuser.Organizatoin_user_type
[ERROR] 2021-11-17 20:29:25,578 django.request: Internal Server Error: /adminsignup/
Traceback (most recent call last):
  File "/Users/rileymarsden/.local/share/virtualenvs/EasyConnect-40Y_jyS5/lib/python3.9/site-packages/django/db/backends/utils.py", line 84, in _execute
    return self.cursor.execute(sql, params)
  File "/Users/rileymarsden/.local/share/virtualenvs/EasyConnect-40Y_jyS5/lib/python3.9/site-packages/django/db/backends/sqlite3/base.py", line 413, in execute
    return Database.Cursor.execute(self, query, params)
sqlite3.IntegrityError: NOT NULL constraint failed: customuser_customuser.Organizatoin_user_type

The above exception was the direct cause of the following exception:

Traceback (most recent call last):
  File "/Users/rileymarsden/.local/share/virtualenvs/EasyConnect-40Y_jyS5/lib/python3.9/site-packages/django/core/handlers/exception.py", line 47, in inner
    response = get_response(request)
  File "/Users/rileymarsden/.local/share/virtualenvs/EasyConnect-40Y_jyS5/lib/python3.9/site-packages/django/core/handlers/base.py", line 181, in _get_response
    response = wrapped_callback(request, *callback_args, **callback_kwargs)
  File "/Users/rileymarsden/Desktop/EasyConnect/customuser/views.py", line 43, in SignUpAdminView
    FormSaveandAccountCreation(form, Org_name_CleanUP(form.cleaned_data.get('Organization_name')), sw, request, tk, True)
  File "/Users/rileymarsden/Desktop/EasyConnect/customuser/views.py", line 105, in FormSaveandAccountCreation
    formsdata.save()
  File "/Users/rileymarsden/.local/share/virtualenvs/EasyConnect-40Y_jyS5/lib/python3.9/site-packages/django/contrib/auth/forms.py", line 138, in save
    user.save()
  File "/Users/rileymarsden/.local/share/virtualenvs/EasyConnect-40Y_jyS5/lib/python3.9/site-packages/django/contrib/auth/base_user.py", line 67, in save
    super().save(*args, **kwargs)
  File "/Users/rileymarsden/.local/share/virtualenvs/EasyConnect-40Y_jyS5/lib/python3.9/site-packages/django/db/models/base.py", line 753, in save
    self.save_base(using=using, force_insert=force_insert,
  File "/Users/rileymarsden/.local/share/virtualenvs/EasyConnect-40Y_jyS5/lib/python3.9/site-packages/django/db/models/base.py", line 790, in save_base
    updated = self._save_table(
  File "/Users/rileymarsden/.local/share/virtualenvs/EasyConnect-40Y_jyS5/lib/python3.9/site-packages/django/db/models/base.py", line 895, in _save_table
    results = self._do_insert(cls._base_manager, using, fields, returning_fields, raw)
  File "/Users/rileymarsden/.local/share/virtualenvs/EasyConnect-40Y_jyS5/lib/python3.9/site-packages/django/db/models/base.py", line 933, in _do_insert
    return manager._insert(
  File "/Users/rileymarsden/.local/share/virtualenvs/EasyConnect-40Y_jyS5/lib/python3.9/site-packages/django/db/models/manager.py", line 85, in manager_method
    return getattr(self.get_queryset(), name)(*args, **kwargs)
  File "/Users/rileymarsden/.local/share/virtualenvs/EasyConnect-40Y_jyS5/lib/python3.9/site-packages/django/db/models/query.py", line 1254, in _insert
    return query.get_compiler(using=using).execute_sql(returning_fields)
  File "/Users/rileymarsden/.local/share/virtualenvs/EasyConnect-40Y_jyS5/lib/python3.9/site-packages/django/db/models/sql/compiler.py", line 1397, in execute_sql
    cursor.execute(sql, params)
  File "/Users/rileymarsden/.local/share/virtualenvs/EasyConnect-40Y_jyS5/lib/python3.9/site-packages/django/db/backends/utils.py", line 98, in execute
    return super().execute(sql, params)
  File "/Users/rileymarsden/.local/share/virtualenvs/EasyConnect-40Y_jyS5/lib/python3.9/site-packages/django/db/backends/utils.py", line 66, in execute
    return self._execute_with_wrappers(sql, params, many=False, executor=self._execute)
  File "/Users/rileymarsden/.local/share/virtualenvs/EasyConnect-40Y_jyS5/lib/python3.9/site-packages/django/db/backends/utils.py", line 75, in _execute_with_wrappers
    return executor(sql, params, many, context)
  File "/Users/rileymarsden/.local/share/virtualenvs/EasyConnect-40Y_jyS5/lib/python3.9/site-packages/django/db/backends/utils.py", line 84, in _execute
    return self.cursor.execute(sql, params)
  File "/Users/rileymarsden/.local/share/virtualenvs/EasyConnect-40Y_jyS5/lib/python3.9/site-packages/django/db/utils.py", line 90, in __exit__
    raise dj_exc_value.with_traceback(traceback) from exc_value
  File "/Users/rileymarsden/.local/share/virtualenvs/EasyConnect-40Y_jyS5/lib/python3.9/site-packages/django/db/backends/utils.py", line 84, in _execute
    return self.cursor.execute(sql, params)
  File "/Users/rileymarsden/.local/share/virtualenvs/EasyConnect-40Y_jyS5/lib/python3.9/site-packages/django/db/backends/sqlite3/base.py", line 413, in execute
    return Database.Cursor.execute(self, query, params)
django.db.utils.IntegrityError: NOT NULL constraint failed: customuser_customuser.Organizatoin_user_type
[ERROR] 2021-11-17 20:35:06,850 django.request: Internal Server Error: /adminsignup/
Traceback (most recent call last):
  File "/Users/rileymarsden/.local/share/virtualenvs/EasyConnect-40Y_jyS5/lib/python3.9/site-packages/django/db/backends/utils.py", line 84, in _execute
    return self.cursor.execute(sql, params)
  File "/Users/rileymarsden/.local/share/virtualenvs/EasyConnect-40Y_jyS5/lib/python3.9/site-packages/django/db/backends/sqlite3/base.py", line 413, in execute
    return Database.Cursor.execute(self, query, params)
sqlite3.IntegrityError: NOT NULL constraint failed: customuser_customuser.Organizatoin_user_type

The above exception was the direct cause of the following exception:

Traceback (most recent call last):
  File "/Users/rileymarsden/Desktop/EasyConnect/customuser/views.py", line 41, in SignUpAdminView
    AddUserToGroup(groups, Org_name_CleanUP(org_name), form, True)
  File "/Users/rileymarsden/Desktop/EasyConnect/customuser/views.py", line 119, in AddUserToGroup
    user.save()
  File "/Users/rileymarsden/.local/share/virtualenvs/EasyConnect-40Y_jyS5/lib/python3.9/site-packages/django/contrib/auth/base_user.py", line 67, in save
    super().save(*args, **kwargs)
  File "/Users/rileymarsden/.local/share/virtualenvs/EasyConnect-40Y_jyS5/lib/python3.9/site-packages/django/db/models/base.py", line 753, in save
    self.save_base(using=using, force_insert=force_insert,
  File "/Users/rileymarsden/.local/share/virtualenvs/EasyConnect-40Y_jyS5/lib/python3.9/site-packages/django/db/models/base.py", line 790, in save_base
    updated = self._save_table(
  File "/Users/rileymarsden/.local/share/virtualenvs/EasyConnect-40Y_jyS5/lib/python3.9/site-packages/django/db/models/base.py", line 895, in _save_table
    results = self._do_insert(cls._base_manager, using, fields, returning_fields, raw)
  File "/Users/rileymarsden/.local/share/virtualenvs/EasyConnect-40Y_jyS5/lib/python3.9/site-packages/django/db/models/base.py", line 933, in _do_insert
    return manager._insert(
  File "/Users/rileymarsden/.local/share/virtualenvs/EasyConnect-40Y_jyS5/lib/python3.9/site-packages/django/db/models/manager.py", line 85, in manager_method
    return getattr(self.get_queryset(), name)(*args, **kwargs)
  File "/Users/rileymarsden/.local/share/virtualenvs/EasyConnect-40Y_jyS5/lib/python3.9/site-packages/django/db/models/query.py", line 1254, in _insert
    return query.get_compiler(using=using).execute_sql(returning_fields)
  File "/Users/rileymarsden/.local/share/virtualenvs/EasyConnect-40Y_jyS5/lib/python3.9/site-packages/django/db/models/sql/compiler.py", line 1397, in execute_sql
    cursor.execute(sql, params)
  File "/Users/rileymarsden/.local/share/virtualenvs/EasyConnect-40Y_jyS5/lib/python3.9/site-packages/django/db/backends/utils.py", line 98, in execute
    return super().execute(sql, params)
  File "/Users/rileymarsden/.local/share/virtualenvs/EasyConnect-40Y_jyS5/lib/python3.9/site-packages/django/db/backends/utils.py", line 66, in execute
    return self._execute_with_wrappers(sql, params, many=False, executor=self._execute)
  File "/Users/rileymarsden/.local/share/virtualenvs/EasyConnect-40Y_jyS5/lib/python3.9/site-packages/django/db/backends/utils.py", line 75, in _execute_with_wrappers
    return executor(sql, params, many, context)
  File "/Users/rileymarsden/.local/share/virtualenvs/EasyConnect-40Y_jyS5/lib/python3.9/site-packages/django/db/backends/utils.py", line 84, in _execute
    return self.cursor.execute(sql, params)
  File "/Users/rileymarsden/.local/share/virtualenvs/EasyConnect-40Y_jyS5/lib/python3.9/site-packages/django/db/utils.py", line 90, in __exit__
    raise dj_exc_value.with_traceback(traceback) from exc_value
  File "/Users/rileymarsden/.local/share/virtualenvs/EasyConnect-40Y_jyS5/lib/python3.9/site-packages/django/db/backends/utils.py", line 84, in _execute
    return self.cursor.execute(sql, params)
  File "/Users/rileymarsden/.local/share/virtualenvs/EasyConnect-40Y_jyS5/lib/python3.9/site-packages/django/db/backends/sqlite3/base.py", line 413, in execute
    return Database.Cursor.execute(self, query, params)
django.db.utils.IntegrityError: NOT NULL constraint failed: customuser_customuser.Organizatoin_user_type
>>>>>>> master

During handling of the above exception, another exception occurred:

Traceback (most recent call last):
<<<<<<< HEAD
  File "C:\Users\werkc\.virtualenvs\easyconnect-JWSqFyg0\lib\site-packages\django\core\handlers\exception.py", line 47, in inner
    response = get_response(request)
  File "C:\Users\werkc\.virtualenvs\easyconnect-JWSqFyg0\lib\site-packages\django\core\handlers\base.py", line 181, in _get_response
    response = wrapped_callback(request, *callback_args, **callback_kwargs)
  File "C:\Users\werkc\Desktop\EasyConnect\customuser\views.py", line 70, in SignUpEUView
    return render(request, 'registration/client_EU_signup.html', context)
  File "C:\Users\werkc\.virtualenvs\easyconnect-JWSqFyg0\lib\site-packages\django\shortcuts.py", line 19, in render
    content = loader.render_to_string(template_name, context, request, using=using)
  File "C:\Users\werkc\.virtualenvs\easyconnect-JWSqFyg0\lib\site-packages\django\template\loader.py", line 61, in render_to_string
    template = get_template(template_name, using=using)
  File "C:\Users\werkc\.virtualenvs\easyconnect-JWSqFyg0\lib\site-packages\django\template\loader.py", line 15, in get_template
    return engine.get_template(template_name)
  File "C:\Users\werkc\.virtualenvs\easyconnect-JWSqFyg0\lib\site-packages\django\template\backends\django.py", line 34, in get_template
    return Template(self.engine.get_template(template_name), self)
  File "C:\Users\werkc\.virtualenvs\easyconnect-JWSqFyg0\lib\site-packages\django\template\engine.py", line 143, in get_template
    template, origin = self.find_template(template_name)
  File "C:\Users\werkc\.virtualenvs\easyconnect-JWSqFyg0\lib\site-packages\django\template\engine.py", line 125, in find_template
    template = loader.get_template(name, skip=skip)
  File "C:\Users\werkc\.virtualenvs\easyconnect-JWSqFyg0\lib\site-packages\django\template\loaders\base.py", line 29, in get_template
    return Template(
  File "C:\Users\werkc\.virtualenvs\easyconnect-JWSqFyg0\lib\site-packages\django\template\base.py", line 155, in __init__
    self.nodelist = self.compile_nodelist()
  File "C:\Users\werkc\.virtualenvs\easyconnect-JWSqFyg0\lib\site-packages\django\template\base.py", line 193, in compile_nodelist
    return parser.parse()
  File "C:\Users\werkc\.virtualenvs\easyconnect-JWSqFyg0\lib\site-packages\django\template\base.py", line 472, in parse
    self.invalid_block_tag(token, command, parse_until)
  File "C:\Users\werkc\.virtualenvs\easyconnect-JWSqFyg0\lib\site-packages\django\template\base.py", line 531, in invalid_block_tag
    raise self.error(
django.template.exceptions.TemplateSyntaxError: Invalid block tag on line 73: 'static'. Did you forget to register or load this tag?
=======
  File "/Users/rileymarsden/.local/share/virtualenvs/EasyConnect-40Y_jyS5/lib/python3.9/site-packages/django/db/backends/utils.py", line 84, in _execute
    return self.cursor.execute(sql, params)
  File "/Users/rileymarsden/.local/share/virtualenvs/EasyConnect-40Y_jyS5/lib/python3.9/site-packages/django/db/backends/sqlite3/base.py", line 413, in execute
    return Database.Cursor.execute(self, query, params)
sqlite3.IntegrityError: NOT NULL constraint failed: customuser_customuser.Organizatoin_user_type

The above exception was the direct cause of the following exception:

Traceback (most recent call last):
  File "/Users/rileymarsden/.local/share/virtualenvs/EasyConnect-40Y_jyS5/lib/python3.9/site-packages/django/core/handlers/exception.py", line 47, in inner
    response = get_response(request)
  File "/Users/rileymarsden/.local/share/virtualenvs/EasyConnect-40Y_jyS5/lib/python3.9/site-packages/django/core/handlers/base.py", line 181, in _get_response
    response = wrapped_callback(request, *callback_args, **callback_kwargs)
  File "/Users/rileymarsden/Desktop/EasyConnect/customuser/views.py", line 44, in SignUpAdminView
    FormSaveandAccountCreation(form, Org_name_CleanUP(org_name), sw, request, tk, True)
  File "/Users/rileymarsden/Desktop/EasyConnect/customuser/views.py", line 106, in FormSaveandAccountCreation
    formsdata.save()
  File "/Users/rileymarsden/.local/share/virtualenvs/EasyConnect-40Y_jyS5/lib/python3.9/site-packages/django/contrib/auth/forms.py", line 138, in save
    user.save()
  File "/Users/rileymarsden/.local/share/virtualenvs/EasyConnect-40Y_jyS5/lib/python3.9/site-packages/django/contrib/auth/base_user.py", line 67, in save
    super().save(*args, **kwargs)
  File "/Users/rileymarsden/.local/share/virtualenvs/EasyConnect-40Y_jyS5/lib/python3.9/site-packages/django/db/models/base.py", line 753, in save
    self.save_base(using=using, force_insert=force_insert,
  File "/Users/rileymarsden/.local/share/virtualenvs/EasyConnect-40Y_jyS5/lib/python3.9/site-packages/django/db/models/base.py", line 790, in save_base
    updated = self._save_table(
  File "/Users/rileymarsden/.local/share/virtualenvs/EasyConnect-40Y_jyS5/lib/python3.9/site-packages/django/db/models/base.py", line 895, in _save_table
    results = self._do_insert(cls._base_manager, using, fields, returning_fields, raw)
  File "/Users/rileymarsden/.local/share/virtualenvs/EasyConnect-40Y_jyS5/lib/python3.9/site-packages/django/db/models/base.py", line 933, in _do_insert
    return manager._insert(
  File "/Users/rileymarsden/.local/share/virtualenvs/EasyConnect-40Y_jyS5/lib/python3.9/site-packages/django/db/models/manager.py", line 85, in manager_method
    return getattr(self.get_queryset(), name)(*args, **kwargs)
  File "/Users/rileymarsden/.local/share/virtualenvs/EasyConnect-40Y_jyS5/lib/python3.9/site-packages/django/db/models/query.py", line 1254, in _insert
    return query.get_compiler(using=using).execute_sql(returning_fields)
  File "/Users/rileymarsden/.local/share/virtualenvs/EasyConnect-40Y_jyS5/lib/python3.9/site-packages/django/db/models/sql/compiler.py", line 1397, in execute_sql
    cursor.execute(sql, params)
  File "/Users/rileymarsden/.local/share/virtualenvs/EasyConnect-40Y_jyS5/lib/python3.9/site-packages/django/db/backends/utils.py", line 98, in execute
    return super().execute(sql, params)
  File "/Users/rileymarsden/.local/share/virtualenvs/EasyConnect-40Y_jyS5/lib/python3.9/site-packages/django/db/backends/utils.py", line 66, in execute
    return self._execute_with_wrappers(sql, params, many=False, executor=self._execute)
  File "/Users/rileymarsden/.local/share/virtualenvs/EasyConnect-40Y_jyS5/lib/python3.9/site-packages/django/db/backends/utils.py", line 75, in _execute_with_wrappers
    return executor(sql, params, many, context)
  File "/Users/rileymarsden/.local/share/virtualenvs/EasyConnect-40Y_jyS5/lib/python3.9/site-packages/django/db/backends/utils.py", line 84, in _execute
    return self.cursor.execute(sql, params)
  File "/Users/rileymarsden/.local/share/virtualenvs/EasyConnect-40Y_jyS5/lib/python3.9/site-packages/django/db/utils.py", line 90, in __exit__
    raise dj_exc_value.with_traceback(traceback) from exc_value
  File "/Users/rileymarsden/.local/share/virtualenvs/EasyConnect-40Y_jyS5/lib/python3.9/site-packages/django/db/backends/utils.py", line 84, in _execute
    return self.cursor.execute(sql, params)
  File "/Users/rileymarsden/.local/share/virtualenvs/EasyConnect-40Y_jyS5/lib/python3.9/site-packages/django/db/backends/sqlite3/base.py", line 413, in execute
    return Database.Cursor.execute(self, query, params)
django.db.utils.IntegrityError: NOT NULL constraint failed: customuser_customuser.Organizatoin_user_type
>>>>>>> master
[ERROR] 2021-11-29 21:38:23,466 django.request: Internal Server Error: /password_change/
Traceback (most recent call last):
  File "/Users/rileymarsden/.local/share/virtualenvs/EasyConnect-40Y_jyS5/lib/python3.9/site-packages/django/core/handlers/exception.py", line 47, in inner
    response = get_response(request)
  File "/Users/rileymarsden/.local/share/virtualenvs/EasyConnect-40Y_jyS5/lib/python3.9/site-packages/django/core/handlers/base.py", line 204, in _get_response
    response = response.render()
  File "/Users/rileymarsden/.local/share/virtualenvs/EasyConnect-40Y_jyS5/lib/python3.9/site-packages/django/template/response.py", line 105, in render
    self.content = self.rendered_content
  File "/Users/rileymarsden/.local/share/virtualenvs/EasyConnect-40Y_jyS5/lib/python3.9/site-packages/django/template/response.py", line 81, in rendered_content
    template = self.resolve_template(self.template_name)
  File "/Users/rileymarsden/.local/share/virtualenvs/EasyConnect-40Y_jyS5/lib/python3.9/site-packages/django/template/response.py", line 63, in resolve_template
    return select_template(template, using=self.using)
  File "/Users/rileymarsden/.local/share/virtualenvs/EasyConnect-40Y_jyS5/lib/python3.9/site-packages/django/template/loader.py", line 47, in select_template
    raise TemplateDoesNotExist(', '.join(template_name_list), chain=chain)
django.template.exceptions.TemplateDoesNotExist: password_reset/password_change.html
[ERROR] 2021-11-29 21:47:48,189 django.request: Internal Server Error: /password_reset/
Traceback (most recent call last):
  File "/Users/rileymarsden/.local/share/virtualenvs/EasyConnect-40Y_jyS5/lib/python3.9/site-packages/django/core/handlers/exception.py", line 47, in inner
    response = get_response(request)
  File "/Users/rileymarsden/.local/share/virtualenvs/EasyConnect-40Y_jyS5/lib/python3.9/site-packages/django/core/handlers/base.py", line 181, in _get_response
    response = wrapped_callback(request, *callback_args, **callback_kwargs)
  File "/Users/rileymarsden/.local/share/virtualenvs/EasyConnect-40Y_jyS5/lib/python3.9/site-packages/django/views/generic/base.py", line 70, in view
    return self.dispatch(request, *args, **kwargs)
  File "/Users/rileymarsden/.local/share/virtualenvs/EasyConnect-40Y_jyS5/lib/python3.9/site-packages/django/utils/decorators.py", line 43, in _wrapper
    return bound_method(*args, **kwargs)
  File "/Users/rileymarsden/.local/share/virtualenvs/EasyConnect-40Y_jyS5/lib/python3.9/site-packages/django/utils/decorators.py", line 130, in _wrapped_view
    response = view_func(request, *args, **kwargs)
  File "/Users/rileymarsden/Desktop/EasyConnect/customuser/views.py", line 234, in dispatch
    return super().dispatch(*args, **kwargs)
  File "/Users/rileymarsden/.local/share/virtualenvs/EasyConnect-40Y_jyS5/lib/python3.9/site-packages/django/views/generic/base.py", line 98, in dispatch
    return handler(request, *args, **kwargs)
  File "/Users/rileymarsden/.local/share/virtualenvs/EasyConnect-40Y_jyS5/lib/python3.9/site-packages/django/views/generic/edit.py", line 142, in post
    return self.form_valid(form)
  File "/Users/rileymarsden/Desktop/EasyConnect/customuser/views.py", line 247, in form_valid
    form.save(**opts)
  File "/Users/rileymarsden/.local/share/virtualenvs/EasyConnect-40Y_jyS5/lib/python3.9/site-packages/django/contrib/auth/forms.py", line 323, in save
    self.send_mail(
  File "/Users/rileymarsden/.local/share/virtualenvs/EasyConnect-40Y_jyS5/lib/python3.9/site-packages/django/contrib/auth/forms.py", line 273, in send_mail
    email_message.send()
  File "/Users/rileymarsden/.local/share/virtualenvs/EasyConnect-40Y_jyS5/lib/python3.9/site-packages/django/core/mail/message.py", line 284, in send
    return self.get_connection(fail_silently).send_messages([self])
  File "/Users/rileymarsden/.local/share/virtualenvs/EasyConnect-40Y_jyS5/lib/python3.9/site-packages/django/core/mail/backends/smtp.py", line 102, in send_messages
    new_conn_created = self.open()
  File "/Users/rileymarsden/.local/share/virtualenvs/EasyConnect-40Y_jyS5/lib/python3.9/site-packages/django/core/mail/backends/smtp.py", line 62, in open
    self.connection = self.connection_class(self.host, self.port, **connection_params)
  File "/Library/Frameworks/Python.framework/Versions/3.9/lib/python3.9/smtplib.py", line 253, in __init__
    (code, msg) = self.connect(host, port)
  File "/Library/Frameworks/Python.framework/Versions/3.9/lib/python3.9/smtplib.py", line 339, in connect
    self.sock = self._get_socket(host, port, self.timeout)
  File "/Library/Frameworks/Python.framework/Versions/3.9/lib/python3.9/smtplib.py", line 310, in _get_socket
    return socket.create_connection((host, port), timeout,
  File "/Library/Frameworks/Python.framework/Versions/3.9/lib/python3.9/socket.py", line 843, in create_connection
    raise err
  File "/Library/Frameworks/Python.framework/Versions/3.9/lib/python3.9/socket.py", line 831, in create_connection
    sock.connect(sa)
ConnectionRefusedError: [Errno 61] Connection refused
[ERROR] 2021-11-29 21:48:36,466 django.request: Internal Server Error: /password_reset/
Traceback (most recent call last):
  File "/Users/rileymarsden/.local/share/virtualenvs/EasyConnect-40Y_jyS5/lib/python3.9/site-packages/django/core/handlers/exception.py", line 47, in inner
    response = get_response(request)
  File "/Users/rileymarsden/.local/share/virtualenvs/EasyConnect-40Y_jyS5/lib/python3.9/site-packages/django/core/handlers/base.py", line 181, in _get_response
    response = wrapped_callback(request, *callback_args, **callback_kwargs)
  File "/Users/rileymarsden/.local/share/virtualenvs/EasyConnect-40Y_jyS5/lib/python3.9/site-packages/django/views/generic/base.py", line 70, in view
    return self.dispatch(request, *args, **kwargs)
  File "/Users/rileymarsden/.local/share/virtualenvs/EasyConnect-40Y_jyS5/lib/python3.9/site-packages/django/utils/decorators.py", line 43, in _wrapper
    return bound_method(*args, **kwargs)
  File "/Users/rileymarsden/.local/share/virtualenvs/EasyConnect-40Y_jyS5/lib/python3.9/site-packages/django/utils/decorators.py", line 130, in _wrapped_view
    response = view_func(request, *args, **kwargs)
  File "/Users/rileymarsden/Desktop/EasyConnect/customuser/views.py", line 234, in dispatch
    return super().dispatch(*args, **kwargs)
  File "/Users/rileymarsden/.local/share/virtualenvs/EasyConnect-40Y_jyS5/lib/python3.9/site-packages/django/views/generic/base.py", line 98, in dispatch
    return handler(request, *args, **kwargs)
  File "/Users/rileymarsden/.local/share/virtualenvs/EasyConnect-40Y_jyS5/lib/python3.9/site-packages/django/views/generic/edit.py", line 142, in post
    return self.form_valid(form)
  File "/Users/rileymarsden/Desktop/EasyConnect/customuser/views.py", line 247, in form_valid
    form.save(**opts)
  File "/Users/rileymarsden/.local/share/virtualenvs/EasyConnect-40Y_jyS5/lib/python3.9/site-packages/django/contrib/auth/forms.py", line 323, in save
    self.send_mail(
  File "/Users/rileymarsden/.local/share/virtualenvs/EasyConnect-40Y_jyS5/lib/python3.9/site-packages/django/contrib/auth/forms.py", line 273, in send_mail
    email_message.send()
  File "/Users/rileymarsden/.local/share/virtualenvs/EasyConnect-40Y_jyS5/lib/python3.9/site-packages/django/core/mail/message.py", line 284, in send
    return self.get_connection(fail_silently).send_messages([self])
  File "/Users/rileymarsden/.local/share/virtualenvs/EasyConnect-40Y_jyS5/lib/python3.9/site-packages/django/core/mail/backends/smtp.py", line 102, in send_messages
    new_conn_created = self.open()
  File "/Users/rileymarsden/.local/share/virtualenvs/EasyConnect-40Y_jyS5/lib/python3.9/site-packages/django/core/mail/backends/smtp.py", line 62, in open
    self.connection = self.connection_class(self.host, self.port, **connection_params)
  File "/Library/Frameworks/Python.framework/Versions/3.9/lib/python3.9/smtplib.py", line 253, in __init__
    (code, msg) = self.connect(host, port)
  File "/Library/Frameworks/Python.framework/Versions/3.9/lib/python3.9/smtplib.py", line 339, in connect
    self.sock = self._get_socket(host, port, self.timeout)
  File "/Library/Frameworks/Python.framework/Versions/3.9/lib/python3.9/smtplib.py", line 310, in _get_socket
    return socket.create_connection((host, port), timeout,
  File "/Library/Frameworks/Python.framework/Versions/3.9/lib/python3.9/socket.py", line 843, in create_connection
    raise err
  File "/Library/Frameworks/Python.framework/Versions/3.9/lib/python3.9/socket.py", line 831, in create_connection
    sock.connect(sa)
ConnectionRefusedError: [Errno 61] Connection refused
[ERROR] 2021-12-03 20:21:20,393 django.request: Internal Server Error: /Home
Traceback (most recent call last):
  File "C:\Users\werkc\.virtualenvs\easyconnect-JWSqFyg0\lib\site-packages\django\core\handlers\exception.py", line 47, in inner
    response = get_response(request)
  File "C:\Users\werkc\.virtualenvs\easyconnect-JWSqFyg0\lib\site-packages\django\core\handlers\base.py", line 181, in _get_response
    response = wrapped_callback(request, *callback_args, **callback_kwargs)
  File "C:\Users\werkc\Desktop\EasyConnect\EasyConnect\views.py", line 6, in HomePageView
    return render(request, 'home.html', context)
  File "C:\Users\werkc\.virtualenvs\easyconnect-JWSqFyg0\lib\site-packages\django\shortcuts.py", line 19, in render
    content = loader.render_to_string(template_name, context, request, using=using)
  File "C:\Users\werkc\.virtualenvs\easyconnect-JWSqFyg0\lib\site-packages\django\template\loader.py", line 61, in render_to_string
    template = get_template(template_name, using=using)
  File "C:\Users\werkc\.virtualenvs\easyconnect-JWSqFyg0\lib\site-packages\django\template\loader.py", line 15, in get_template
    return engine.get_template(template_name)
  File "C:\Users\werkc\.virtualenvs\easyconnect-JWSqFyg0\lib\site-packages\django\template\backends\django.py", line 34, in get_template
    return Template(self.engine.get_template(template_name), self)
  File "C:\Users\werkc\.virtualenvs\easyconnect-JWSqFyg0\lib\site-packages\django\template\engine.py", line 143, in get_template
    template, origin = self.find_template(template_name)
  File "C:\Users\werkc\.virtualenvs\easyconnect-JWSqFyg0\lib\site-packages\django\template\engine.py", line 125, in find_template
    template = loader.get_template(name, skip=skip)
  File "C:\Users\werkc\.virtualenvs\easyconnect-JWSqFyg0\lib\site-packages\django\template\loaders\base.py", line 29, in get_template
    return Template(
  File "C:\Users\werkc\.virtualenvs\easyconnect-JWSqFyg0\lib\site-packages\django\template\base.py", line 155, in __init__
    self.nodelist = self.compile_nodelist()
  File "C:\Users\werkc\.virtualenvs\easyconnect-JWSqFyg0\lib\site-packages\django\template\base.py", line 193, in compile_nodelist
    return parser.parse()
  File "C:\Users\werkc\.virtualenvs\easyconnect-JWSqFyg0\lib\site-packages\django\template\base.py", line 478, in parse
    raise self.error(token, e)
  File "C:\Users\werkc\.virtualenvs\easyconnect-JWSqFyg0\lib\site-packages\django\template\base.py", line 476, in parse
    compiled_result = compile_func(self, token)
  File "C:\Users\werkc\.virtualenvs\easyconnect-JWSqFyg0\lib\site-packages\django\template\loader_tags.py", line 270, in do_extends
    nodelist = parser.parse()
  File "C:\Users\werkc\.virtualenvs\easyconnect-JWSqFyg0\lib\site-packages\django\template\base.py", line 478, in parse
    raise self.error(token, e)
  File "C:\Users\werkc\.virtualenvs\easyconnect-JWSqFyg0\lib\site-packages\django\template\base.py", line 476, in parse
    compiled_result = compile_func(self, token)
  File "C:\Users\werkc\.virtualenvs\easyconnect-JWSqFyg0\lib\site-packages\django\template\loader_tags.py", line 213, in do_block
    nodelist = parser.parse(('endblock',))
  File "C:\Users\werkc\.virtualenvs\easyconnect-JWSqFyg0\lib\site-packages\django\template\base.py", line 478, in parse
    raise self.error(token, e)
  File "C:\Users\werkc\.virtualenvs\easyconnect-JWSqFyg0\lib\site-packages\django\template\base.py", line 476, in parse
    compiled_result = compile_func(self, token)
  File "C:\Users\werkc\.virtualenvs\easyconnect-JWSqFyg0\lib\site-packages\django\template\defaulttags.py", line 1372, in url
    viewname = parser.compile_filter(bits[1])
  File "C:\Users\werkc\.virtualenvs\easyconnect-JWSqFyg0\lib\site-packages\django\template\base.py", line 563, in compile_filter
    return FilterExpression(token, self)
  File "C:\Users\werkc\.virtualenvs\easyconnect-JWSqFyg0\lib\site-packages\django\template\base.py", line 662, in __init__
    raise TemplateSyntaxError("Could not parse the remainder: '%s' "
django.template.exceptions.TemplateSyntaxError: Could not parse the remainder: ''adminsignup' from ''adminsignup'
[ERROR] 2021-12-05 00:13:49,951 django.request: Internal Server Error: /announcements
Traceback (most recent call last):
  File "/Users/rileymarsden/.local/share/virtualenvs/EasyConnect-40Y_jyS5/lib/python3.9/site-packages/django/template/base.py", line 470, in parse
    compile_func = self.tags[command]
KeyError: 'cache'

During handling of the above exception, another exception occurred:

Traceback (most recent call last):
  File "/Users/rileymarsden/.local/share/virtualenvs/EasyConnect-40Y_jyS5/lib/python3.9/site-packages/django/core/handlers/exception.py", line 47, in inner
    response = get_response(request)
  File "/Users/rileymarsden/.local/share/virtualenvs/EasyConnect-40Y_jyS5/lib/python3.9/site-packages/django/core/handlers/base.py", line 181, in _get_response
    response = wrapped_callback(request, *callback_args, **callback_kwargs)
  File "/Users/rileymarsden/Desktop/EasyConnect/EasyConnect/views.py", line 18, in AnnouncementsView
    return render(request, 'announcements.html', context)
  File "/Users/rileymarsden/.local/share/virtualenvs/EasyConnect-40Y_jyS5/lib/python3.9/site-packages/django/shortcuts.py", line 19, in render
    content = loader.render_to_string(template_name, context, request, using=using)
  File "/Users/rileymarsden/.local/share/virtualenvs/EasyConnect-40Y_jyS5/lib/python3.9/site-packages/django/template/loader.py", line 61, in render_to_string
    template = get_template(template_name, using=using)
  File "/Users/rileymarsden/.local/share/virtualenvs/EasyConnect-40Y_jyS5/lib/python3.9/site-packages/django/template/loader.py", line 15, in get_template
    return engine.get_template(template_name)
  File "/Users/rileymarsden/.local/share/virtualenvs/EasyConnect-40Y_jyS5/lib/python3.9/site-packages/django/template/backends/django.py", line 34, in get_template
    return Template(self.engine.get_template(template_name), self)
  File "/Users/rileymarsden/.local/share/virtualenvs/EasyConnect-40Y_jyS5/lib/python3.9/site-packages/django/template/engine.py", line 143, in get_template
    template, origin = self.find_template(template_name)
  File "/Users/rileymarsden/.local/share/virtualenvs/EasyConnect-40Y_jyS5/lib/python3.9/site-packages/django/template/engine.py", line 125, in find_template
    template = loader.get_template(name, skip=skip)
  File "/Users/rileymarsden/.local/share/virtualenvs/EasyConnect-40Y_jyS5/lib/python3.9/site-packages/django/template/loaders/base.py", line 29, in get_template
    return Template(
  File "/Users/rileymarsden/.local/share/virtualenvs/EasyConnect-40Y_jyS5/lib/python3.9/site-packages/django/template/base.py", line 155, in __init__
    self.nodelist = self.compile_nodelist()
  File "/Users/rileymarsden/.local/share/virtualenvs/EasyConnect-40Y_jyS5/lib/python3.9/site-packages/django/template/base.py", line 193, in compile_nodelist
    return parser.parse()
  File "/Users/rileymarsden/.local/share/virtualenvs/EasyConnect-40Y_jyS5/lib/python3.9/site-packages/django/template/base.py", line 478, in parse
    raise self.error(token, e)
  File "/Users/rileymarsden/.local/share/virtualenvs/EasyConnect-40Y_jyS5/lib/python3.9/site-packages/django/template/base.py", line 476, in parse
    compiled_result = compile_func(self, token)
  File "/Users/rileymarsden/.local/share/virtualenvs/EasyConnect-40Y_jyS5/lib/python3.9/site-packages/django/template/loader_tags.py", line 270, in do_extends
    nodelist = parser.parse()
  File "/Users/rileymarsden/.local/share/virtualenvs/EasyConnect-40Y_jyS5/lib/python3.9/site-packages/django/template/base.py", line 478, in parse
    raise self.error(token, e)
  File "/Users/rileymarsden/.local/share/virtualenvs/EasyConnect-40Y_jyS5/lib/python3.9/site-packages/django/template/base.py", line 476, in parse
    compiled_result = compile_func(self, token)
  File "/Users/rileymarsden/.local/share/virtualenvs/EasyConnect-40Y_jyS5/lib/python3.9/site-packages/django/template/loader_tags.py", line 213, in do_block
    nodelist = parser.parse(('endblock',))
  File "/Users/rileymarsden/.local/share/virtualenvs/EasyConnect-40Y_jyS5/lib/python3.9/site-packages/django/template/base.py", line 472, in parse
    self.invalid_block_tag(token, command, parse_until)
  File "/Users/rileymarsden/.local/share/virtualenvs/EasyConnect-40Y_jyS5/lib/python3.9/site-packages/django/template/base.py", line 522, in invalid_block_tag
    raise self.error(
django.template.exceptions.TemplateSyntaxError: Invalid block tag on line 37: 'cache', expected 'endblock'. Did you forget to register or load this tag?
[ERROR] 2021-12-05 00:27:41,846 django.request: Internal Server Error: /announcements
Traceback (most recent call last):
  File "/Users/rileymarsden/.local/share/virtualenvs/EasyConnect-40Y_jyS5/lib/python3.9/site-packages/django/utils/module_loading.py", line 20, in import_string
    return getattr(module, class_name)
AttributeError: module 'announcements.context_processors' has no attribute 'announcements'

The above exception was the direct cause of the following exception:

Traceback (most recent call last):
  File "/Users/rileymarsden/.local/share/virtualenvs/EasyConnect-40Y_jyS5/lib/python3.9/site-packages/django/core/handlers/exception.py", line 47, in inner
    response = get_response(request)
  File "/Users/rileymarsden/.local/share/virtualenvs/EasyConnect-40Y_jyS5/lib/python3.9/site-packages/django/core/handlers/base.py", line 181, in _get_response
    response = wrapped_callback(request, *callback_args, **callback_kwargs)
  File "/Users/rileymarsden/Desktop/EasyConnect/EasyConnect/views.py", line 18, in AnnouncementsView
    return render(request, 'announcements.html', context)
  File "/Users/rileymarsden/.local/share/virtualenvs/EasyConnect-40Y_jyS5/lib/python3.9/site-packages/django/shortcuts.py", line 19, in render
    content = loader.render_to_string(template_name, context, request, using=using)
  File "/Users/rileymarsden/.local/share/virtualenvs/EasyConnect-40Y_jyS5/lib/python3.9/site-packages/django/template/loader.py", line 62, in render_to_string
    return template.render(context, request)
  File "/Users/rileymarsden/.local/share/virtualenvs/EasyConnect-40Y_jyS5/lib/python3.9/site-packages/django/template/backends/django.py", line 61, in render
    return self.template.render(context)
  File "/Users/rileymarsden/.local/share/virtualenvs/EasyConnect-40Y_jyS5/lib/python3.9/site-packages/django/template/base.py", line 168, in render
    with context.bind_template(self):
  File "/Library/Frameworks/Python.framework/Versions/3.9/lib/python3.9/contextlib.py", line 117, in __enter__
    return next(self.gen)
  File "/Users/rileymarsden/.local/share/virtualenvs/EasyConnect-40Y_jyS5/lib/python3.9/site-packages/django/template/context.py", line 240, in bind_template
    processors = (template.engine.template_context_processors +
  File "/Users/rileymarsden/.local/share/virtualenvs/EasyConnect-40Y_jyS5/lib/python3.9/site-packages/django/utils/functional.py", line 48, in __get__
    res = instance.__dict__[self.name] = self.func(instance)
  File "/Users/rileymarsden/.local/share/virtualenvs/EasyConnect-40Y_jyS5/lib/python3.9/site-packages/django/template/engine.py", line 85, in template_context_processors
    return tuple(import_string(path) for path in context_processors)
  File "/Users/rileymarsden/.local/share/virtualenvs/EasyConnect-40Y_jyS5/lib/python3.9/site-packages/django/template/engine.py", line 85, in <genexpr>
    return tuple(import_string(path) for path in context_processors)
  File "/Users/rileymarsden/.local/share/virtualenvs/EasyConnect-40Y_jyS5/lib/python3.9/site-packages/django/utils/module_loading.py", line 22, in import_string
    raise ImportError('Module "%s" does not define a "%s" attribute/class' % (
ImportError: Module "announcements.context_processors" does not define a "announcements" attribute/class
[ERROR] 2021-12-05 07:03:28,136 django.request: Internal Server Error: /adminsignup/
Traceback (most recent call last):
  File "/Users/rileymarsden/.local/share/virtualenvs/EasyConnect-40Y_jyS5/lib/python3.9/site-packages/django/core/handlers/exception.py", line 47, in inner
    response = get_response(request)
  File "/Users/rileymarsden/.local/share/virtualenvs/EasyConnect-40Y_jyS5/lib/python3.9/site-packages/django/core/handlers/base.py", line 181, in _get_response
    response = wrapped_callback(request, *callback_args, **callback_kwargs)
  File "/Users/rileymarsden/Desktop/EasyConnect/customuser/views.py", line 66, in SignUpAdminView
    AddUserToGroup(groups, Org_name_CleanUP(request.POST.get('Organization_name')), form, True)
TypeError: AddUserToGroup() missing 1 required positional argument: 'org_user_type'
[ERROR] 2021-12-06 00:17:07,346 django.request: Internal Server Error: /chat/example/
Traceback (most recent call last):
  File "/Users/rileymarsden/.local/share/virtualenvs/EasyConnect-40Y_jyS5/lib/python3.9/site-packages/django/template/base.py", line 470, in parse
    compile_func = self.tags[command]
KeyError: "'url"

During handling of the above exception, another exception occurred:

Traceback (most recent call last):
  File "/Users/rileymarsden/.local/share/virtualenvs/EasyConnect-40Y_jyS5/lib/python3.9/site-packages/asgiref/sync.py", line 482, in thread_handler
    raise exc_info[1]
  File "/Users/rileymarsden/.local/share/virtualenvs/EasyConnect-40Y_jyS5/lib/python3.9/site-packages/django/core/handlers/exception.py", line 38, in inner
    response = await get_response(request)
  File "/Users/rileymarsden/.local/share/virtualenvs/EasyConnect-40Y_jyS5/lib/python3.9/site-packages/django/core/handlers/base.py", line 233, in _get_response_async
    response = await wrapped_callback(request, *callback_args, **callback_kwargs)
  File "/Users/rileymarsden/.local/share/virtualenvs/EasyConnect-40Y_jyS5/lib/python3.9/site-packages/asgiref/sync.py", line 444, in __call__
    ret = await asyncio.wait_for(future, timeout=None)
  File "/Library/Frameworks/Python.framework/Versions/3.9/lib/python3.9/asyncio/tasks.py", line 442, in wait_for
    return await fut
  File "/Users/rileymarsden/.local/share/virtualenvs/EasyConnect-40Y_jyS5/lib/python3.9/site-packages/asgiref/current_thread_executor.py", line 22, in run
    result = self.fn(*self.args, **self.kwargs)
  File "/Users/rileymarsden/.local/share/virtualenvs/EasyConnect-40Y_jyS5/lib/python3.9/site-packages/asgiref/sync.py", line 486, in thread_handler
    return func(*args, **kwargs)
  File "/Users/rileymarsden/.local/share/virtualenvs/EasyConnect-40Y_jyS5/lib/python3.9/site-packages/django/contrib/auth/decorators.py", line 21, in _wrapped_view
    return view_func(request, *args, **kwargs)
  File "/Users/rileymarsden/Desktop/EasyConnect/chat/views.py", line 11, in room
    return render(request, 'chat/room.html', {
  File "/Users/rileymarsden/.local/share/virtualenvs/EasyConnect-40Y_jyS5/lib/python3.9/site-packages/django/shortcuts.py", line 19, in render
    content = loader.render_to_string(template_name, context, request, using=using)
  File "/Users/rileymarsden/.local/share/virtualenvs/EasyConnect-40Y_jyS5/lib/python3.9/site-packages/django/template/loader.py", line 61, in render_to_string
    template = get_template(template_name, using=using)
  File "/Users/rileymarsden/.local/share/virtualenvs/EasyConnect-40Y_jyS5/lib/python3.9/site-packages/django/template/loader.py", line 15, in get_template
    return engine.get_template(template_name)
  File "/Users/rileymarsden/.local/share/virtualenvs/EasyConnect-40Y_jyS5/lib/python3.9/site-packages/django/template/backends/django.py", line 34, in get_template
    return Template(self.engine.get_template(template_name), self)
  File "/Users/rileymarsden/.local/share/virtualenvs/EasyConnect-40Y_jyS5/lib/python3.9/site-packages/django/template/engine.py", line 143, in get_template
    template, origin = self.find_template(template_name)
  File "/Users/rileymarsden/.local/share/virtualenvs/EasyConnect-40Y_jyS5/lib/python3.9/site-packages/django/template/engine.py", line 125, in find_template
    template = loader.get_template(name, skip=skip)
  File "/Users/rileymarsden/.local/share/virtualenvs/EasyConnect-40Y_jyS5/lib/python3.9/site-packages/django/template/loaders/base.py", line 29, in get_template
    return Template(
  File "/Users/rileymarsden/.local/share/virtualenvs/EasyConnect-40Y_jyS5/lib/python3.9/site-packages/django/template/base.py", line 155, in __init__
    self.nodelist = self.compile_nodelist()
  File "/Users/rileymarsden/.local/share/virtualenvs/EasyConnect-40Y_jyS5/lib/python3.9/site-packages/django/template/base.py", line 193, in compile_nodelist
    return parser.parse()
  File "/Users/rileymarsden/.local/share/virtualenvs/EasyConnect-40Y_jyS5/lib/python3.9/site-packages/django/template/base.py", line 472, in parse
    self.invalid_block_tag(token, command, parse_until)
  File "/Users/rileymarsden/.local/share/virtualenvs/EasyConnect-40Y_jyS5/lib/python3.9/site-packages/django/template/base.py", line 531, in invalid_block_tag
    raise self.error(
django.template.exceptions.TemplateSyntaxError: Invalid block tag on line 74: ''url'. Did you forget to register or load this tag?
[ERROR] 2021-12-06 00:19:51,355 django.request: Internal Server Error: /chat/example/
Traceback (most recent call last):
  File "/Users/rileymarsden/.local/share/virtualenvs/EasyConnect-40Y_jyS5/lib/python3.9/site-packages/asgiref/sync.py", line 482, in thread_handler
    raise exc_info[1]
  File "/Users/rileymarsden/.local/share/virtualenvs/EasyConnect-40Y_jyS5/lib/python3.9/site-packages/django/core/handlers/exception.py", line 38, in inner
    response = await get_response(request)
  File "/Users/rileymarsden/.local/share/virtualenvs/EasyConnect-40Y_jyS5/lib/python3.9/site-packages/django/core/handlers/base.py", line 233, in _get_response_async
    response = await wrapped_callback(request, *callback_args, **callback_kwargs)
  File "/Users/rileymarsden/.local/share/virtualenvs/EasyConnect-40Y_jyS5/lib/python3.9/site-packages/asgiref/sync.py", line 444, in __call__
    ret = await asyncio.wait_for(future, timeout=None)
  File "/Library/Frameworks/Python.framework/Versions/3.9/lib/python3.9/asyncio/tasks.py", line 442, in wait_for
    return await fut
  File "/Users/rileymarsden/.local/share/virtualenvs/EasyConnect-40Y_jyS5/lib/python3.9/site-packages/asgiref/current_thread_executor.py", line 22, in run
    result = self.fn(*self.args, **self.kwargs)
  File "/Users/rileymarsden/.local/share/virtualenvs/EasyConnect-40Y_jyS5/lib/python3.9/site-packages/asgiref/sync.py", line 486, in thread_handler
    return func(*args, **kwargs)
  File "/Users/rileymarsden/.local/share/virtualenvs/EasyConnect-40Y_jyS5/lib/python3.9/site-packages/django/contrib/auth/decorators.py", line 21, in _wrapped_view
    return view_func(request, *args, **kwargs)
  File "/Users/rileymarsden/Desktop/EasyConnect/chat/views.py", line 11, in room
    return render(request, 'chat/room.html', {
  File "/Users/rileymarsden/.local/share/virtualenvs/EasyConnect-40Y_jyS5/lib/python3.9/site-packages/django/shortcuts.py", line 19, in render
    content = loader.render_to_string(template_name, context, request, using=using)
  File "/Users/rileymarsden/.local/share/virtualenvs/EasyConnect-40Y_jyS5/lib/python3.9/site-packages/django/template/loader.py", line 62, in render_to_string
    return template.render(context, request)
  File "/Users/rileymarsden/.local/share/virtualenvs/EasyConnect-40Y_jyS5/lib/python3.9/site-packages/django/template/backends/django.py", line 61, in render
    return self.template.render(context)
  File "/Users/rileymarsden/.local/share/virtualenvs/EasyConnect-40Y_jyS5/lib/python3.9/site-packages/django/template/base.py", line 170, in render
    return self._render(context)
  File "/Users/rileymarsden/.local/share/virtualenvs/EasyConnect-40Y_jyS5/lib/python3.9/site-packages/django/template/base.py", line 162, in _render
    return self.nodelist.render(context)
  File "/Users/rileymarsden/.local/share/virtualenvs/EasyConnect-40Y_jyS5/lib/python3.9/site-packages/django/template/base.py", line 938, in render
    bit = node.render_annotated(context)
  File "/Users/rileymarsden/.local/share/virtualenvs/EasyConnect-40Y_jyS5/lib/python3.9/site-packages/django/template/base.py", line 905, in render_annotated
    return self.render(context)
  File "/Users/rileymarsden/.local/share/virtualenvs/EasyConnect-40Y_jyS5/lib/python3.9/site-packages/django/template/defaulttags.py", line 446, in render
    url = reverse(view_name, args=args, kwargs=kwargs, current_app=current_app)
  File "/Users/rileymarsden/.local/share/virtualenvs/EasyConnect-40Y_jyS5/lib/python3.9/site-packages/django/urls/base.py", line 87, in reverse
    return iri_to_uri(resolver._reverse_with_prefix(view, prefix, *args, **kwargs))
  File "/Users/rileymarsden/.local/share/virtualenvs/EasyConnect-40Y_jyS5/lib/python3.9/site-packages/django/urls/resolvers.py", line 685, in _reverse_with_prefix
    raise NoReverseMatch(msg)
django.urls.exceptions.NoReverseMatch: Reverse for 'chat' not found. 'chat' is not a valid view function or pattern name.
[ERROR] 2021-12-06 00:20:26,919 django.request: Internal Server Error: /chat/example/
Traceback (most recent call last):
  File "/Users/rileymarsden/.local/share/virtualenvs/EasyConnect-40Y_jyS5/lib/python3.9/site-packages/asgiref/sync.py", line 482, in thread_handler
    raise exc_info[1]
  File "/Users/rileymarsden/.local/share/virtualenvs/EasyConnect-40Y_jyS5/lib/python3.9/site-packages/django/core/handlers/exception.py", line 38, in inner
    response = await get_response(request)
  File "/Users/rileymarsden/.local/share/virtualenvs/EasyConnect-40Y_jyS5/lib/python3.9/site-packages/django/core/handlers/base.py", line 233, in _get_response_async
    response = await wrapped_callback(request, *callback_args, **callback_kwargs)
  File "/Users/rileymarsden/.local/share/virtualenvs/EasyConnect-40Y_jyS5/lib/python3.9/site-packages/asgiref/sync.py", line 444, in __call__
    ret = await asyncio.wait_for(future, timeout=None)
  File "/Library/Frameworks/Python.framework/Versions/3.9/lib/python3.9/asyncio/tasks.py", line 442, in wait_for
    return await fut
  File "/Users/rileymarsden/.local/share/virtualenvs/EasyConnect-40Y_jyS5/lib/python3.9/site-packages/asgiref/current_thread_executor.py", line 22, in run
    result = self.fn(*self.args, **self.kwargs)
  File "/Users/rileymarsden/.local/share/virtualenvs/EasyConnect-40Y_jyS5/lib/python3.9/site-packages/asgiref/sync.py", line 486, in thread_handler
    return func(*args, **kwargs)
  File "/Users/rileymarsden/.local/share/virtualenvs/EasyConnect-40Y_jyS5/lib/python3.9/site-packages/django/contrib/auth/decorators.py", line 21, in _wrapped_view
    return view_func(request, *args, **kwargs)
  File "/Users/rileymarsden/Desktop/EasyConnect/chat/views.py", line 11, in room
    return render(request, 'chat/room.html', {
  File "/Users/rileymarsden/.local/share/virtualenvs/EasyConnect-40Y_jyS5/lib/python3.9/site-packages/django/shortcuts.py", line 19, in render
    content = loader.render_to_string(template_name, context, request, using=using)
  File "/Users/rileymarsden/.local/share/virtualenvs/EasyConnect-40Y_jyS5/lib/python3.9/site-packages/django/template/loader.py", line 62, in render_to_string
    return template.render(context, request)
  File "/Users/rileymarsden/.local/share/virtualenvs/EasyConnect-40Y_jyS5/lib/python3.9/site-packages/django/template/backends/django.py", line 61, in render
    return self.template.render(context)
  File "/Users/rileymarsden/.local/share/virtualenvs/EasyConnect-40Y_jyS5/lib/python3.9/site-packages/django/template/base.py", line 170, in render
    return self._render(context)
  File "/Users/rileymarsden/.local/share/virtualenvs/EasyConnect-40Y_jyS5/lib/python3.9/site-packages/django/template/base.py", line 162, in _render
    return self.nodelist.render(context)
  File "/Users/rileymarsden/.local/share/virtualenvs/EasyConnect-40Y_jyS5/lib/python3.9/site-packages/django/template/base.py", line 938, in render
    bit = node.render_annotated(context)
  File "/Users/rileymarsden/.local/share/virtualenvs/EasyConnect-40Y_jyS5/lib/python3.9/site-packages/django/template/base.py", line 905, in render_annotated
    return self.render(context)
  File "/Users/rileymarsden/.local/share/virtualenvs/EasyConnect-40Y_jyS5/lib/python3.9/site-packages/django/template/defaulttags.py", line 446, in render
    url = reverse(view_name, args=args, kwargs=kwargs, current_app=current_app)
  File "/Users/rileymarsden/.local/share/virtualenvs/EasyConnect-40Y_jyS5/lib/python3.9/site-packages/django/urls/base.py", line 87, in reverse
    return iri_to_uri(resolver._reverse_with_prefix(view, prefix, *args, **kwargs))
  File "/Users/rileymarsden/.local/share/virtualenvs/EasyConnect-40Y_jyS5/lib/python3.9/site-packages/django/urls/resolvers.py", line 685, in _reverse_with_prefix
    raise NoReverseMatch(msg)
django.urls.exceptions.NoReverseMatch: Reverse for 'index' not found. 'index' is not a valid view function or pattern name.
[ERROR] 2021-12-06 00:23:00,682 django.request: Internal Server Error: /chat/example/
Traceback (most recent call last):
  File "/Users/rileymarsden/.local/share/virtualenvs/EasyConnect-40Y_jyS5/lib/python3.9/site-packages/asgiref/sync.py", line 482, in thread_handler
    raise exc_info[1]
  File "/Users/rileymarsden/.local/share/virtualenvs/EasyConnect-40Y_jyS5/lib/python3.9/site-packages/django/core/handlers/exception.py", line 38, in inner
    response = await get_response(request)
  File "/Users/rileymarsden/.local/share/virtualenvs/EasyConnect-40Y_jyS5/lib/python3.9/site-packages/django/core/handlers/base.py", line 233, in _get_response_async
    response = await wrapped_callback(request, *callback_args, **callback_kwargs)
  File "/Users/rileymarsden/.local/share/virtualenvs/EasyConnect-40Y_jyS5/lib/python3.9/site-packages/asgiref/sync.py", line 444, in __call__
    ret = await asyncio.wait_for(future, timeout=None)
  File "/Library/Frameworks/Python.framework/Versions/3.9/lib/python3.9/asyncio/tasks.py", line 442, in wait_for
    return await fut
  File "/Users/rileymarsden/.local/share/virtualenvs/EasyConnect-40Y_jyS5/lib/python3.9/site-packages/asgiref/current_thread_executor.py", line 22, in run
    result = self.fn(*self.args, **self.kwargs)
  File "/Users/rileymarsden/.local/share/virtualenvs/EasyConnect-40Y_jyS5/lib/python3.9/site-packages/asgiref/sync.py", line 486, in thread_handler
    return func(*args, **kwargs)
  File "/Users/rileymarsden/.local/share/virtualenvs/EasyConnect-40Y_jyS5/lib/python3.9/site-packages/django/contrib/auth/decorators.py", line 21, in _wrapped_view
    return view_func(request, *args, **kwargs)
  File "/Users/rileymarsden/Desktop/EasyConnect/chat/views.py", line 11, in room
    return render(request, 'chat/room.html', {
  File "/Users/rileymarsden/.local/share/virtualenvs/EasyConnect-40Y_jyS5/lib/python3.9/site-packages/django/shortcuts.py", line 19, in render
    content = loader.render_to_string(template_name, context, request, using=using)
  File "/Users/rileymarsden/.local/share/virtualenvs/EasyConnect-40Y_jyS5/lib/python3.9/site-packages/django/template/loader.py", line 62, in render_to_string
    return template.render(context, request)
  File "/Users/rileymarsden/.local/share/virtualenvs/EasyConnect-40Y_jyS5/lib/python3.9/site-packages/django/template/backends/django.py", line 61, in render
    return self.template.render(context)
  File "/Users/rileymarsden/.local/share/virtualenvs/EasyConnect-40Y_jyS5/lib/python3.9/site-packages/django/template/base.py", line 170, in render
    return self._render(context)
  File "/Users/rileymarsden/.local/share/virtualenvs/EasyConnect-40Y_jyS5/lib/python3.9/site-packages/django/template/base.py", line 162, in _render
    return self.nodelist.render(context)
  File "/Users/rileymarsden/.local/share/virtualenvs/EasyConnect-40Y_jyS5/lib/python3.9/site-packages/django/template/base.py", line 938, in render
    bit = node.render_annotated(context)
  File "/Users/rileymarsden/.local/share/virtualenvs/EasyConnect-40Y_jyS5/lib/python3.9/site-packages/django/template/base.py", line 905, in render_annotated
    return self.render(context)
  File "/Users/rileymarsden/.local/share/virtualenvs/EasyConnect-40Y_jyS5/lib/python3.9/site-packages/django/template/defaulttags.py", line 446, in render
    url = reverse(view_name, args=args, kwargs=kwargs, current_app=current_app)
  File "/Users/rileymarsden/.local/share/virtualenvs/EasyConnect-40Y_jyS5/lib/python3.9/site-packages/django/urls/base.py", line 87, in reverse
    return iri_to_uri(resolver._reverse_with_prefix(view, prefix, *args, **kwargs))
  File "/Users/rileymarsden/.local/share/virtualenvs/EasyConnect-40Y_jyS5/lib/python3.9/site-packages/django/urls/resolvers.py", line 685, in _reverse_with_prefix
    raise NoReverseMatch(msg)
django.urls.exceptions.NoReverseMatch: Reverse for 'chat/' not found. 'chat/' is not a valid view function or pattern name.
[ERROR] 2021-12-06 00:23:55,225 django.request: Internal Server Error: /chat/example/
Traceback (most recent call last):
  File "/Users/rileymarsden/.local/share/virtualenvs/EasyConnect-40Y_jyS5/lib/python3.9/site-packages/asgiref/sync.py", line 482, in thread_handler
    raise exc_info[1]
  File "/Users/rileymarsden/.local/share/virtualenvs/EasyConnect-40Y_jyS5/lib/python3.9/site-packages/django/core/handlers/exception.py", line 38, in inner
    response = await get_response(request)
  File "/Users/rileymarsden/.local/share/virtualenvs/EasyConnect-40Y_jyS5/lib/python3.9/site-packages/django/core/handlers/base.py", line 233, in _get_response_async
    response = await wrapped_callback(request, *callback_args, **callback_kwargs)
  File "/Users/rileymarsden/.local/share/virtualenvs/EasyConnect-40Y_jyS5/lib/python3.9/site-packages/asgiref/sync.py", line 444, in __call__
    ret = await asyncio.wait_for(future, timeout=None)
  File "/Library/Frameworks/Python.framework/Versions/3.9/lib/python3.9/asyncio/tasks.py", line 442, in wait_for
    return await fut
  File "/Users/rileymarsden/.local/share/virtualenvs/EasyConnect-40Y_jyS5/lib/python3.9/site-packages/asgiref/current_thread_executor.py", line 22, in run
    result = self.fn(*self.args, **self.kwargs)
  File "/Users/rileymarsden/.local/share/virtualenvs/EasyConnect-40Y_jyS5/lib/python3.9/site-packages/asgiref/sync.py", line 486, in thread_handler
    return func(*args, **kwargs)
  File "/Users/rileymarsden/.local/share/virtualenvs/EasyConnect-40Y_jyS5/lib/python3.9/site-packages/django/contrib/auth/decorators.py", line 21, in _wrapped_view
    return view_func(request, *args, **kwargs)
  File "/Users/rileymarsden/Desktop/EasyConnect/chat/views.py", line 11, in room
    return render(request, 'chat/room.html', {
  File "/Users/rileymarsden/.local/share/virtualenvs/EasyConnect-40Y_jyS5/lib/python3.9/site-packages/django/shortcuts.py", line 19, in render
    content = loader.render_to_string(template_name, context, request, using=using)
  File "/Users/rileymarsden/.local/share/virtualenvs/EasyConnect-40Y_jyS5/lib/python3.9/site-packages/django/template/loader.py", line 62, in render_to_string
    return template.render(context, request)
  File "/Users/rileymarsden/.local/share/virtualenvs/EasyConnect-40Y_jyS5/lib/python3.9/site-packages/django/template/backends/django.py", line 61, in render
    return self.template.render(context)
  File "/Users/rileymarsden/.local/share/virtualenvs/EasyConnect-40Y_jyS5/lib/python3.9/site-packages/django/template/base.py", line 170, in render
    return self._render(context)
  File "/Users/rileymarsden/.local/share/virtualenvs/EasyConnect-40Y_jyS5/lib/python3.9/site-packages/django/template/base.py", line 162, in _render
    return self.nodelist.render(context)
  File "/Users/rileymarsden/.local/share/virtualenvs/EasyConnect-40Y_jyS5/lib/python3.9/site-packages/django/template/base.py", line 938, in render
    bit = node.render_annotated(context)
  File "/Users/rileymarsden/.local/share/virtualenvs/EasyConnect-40Y_jyS5/lib/python3.9/site-packages/django/template/base.py", line 905, in render_annotated
    return self.render(context)
  File "/Users/rileymarsden/.local/share/virtualenvs/EasyConnect-40Y_jyS5/lib/python3.9/site-packages/django/template/defaulttags.py", line 446, in render
    url = reverse(view_name, args=args, kwargs=kwargs, current_app=current_app)
  File "/Users/rileymarsden/.local/share/virtualenvs/EasyConnect-40Y_jyS5/lib/python3.9/site-packages/django/urls/base.py", line 87, in reverse
    return iri_to_uri(resolver._reverse_with_prefix(view, prefix, *args, **kwargs))
  File "/Users/rileymarsden/.local/share/virtualenvs/EasyConnect-40Y_jyS5/lib/python3.9/site-packages/django/urls/resolvers.py", line 685, in _reverse_with_prefix
    raise NoReverseMatch(msg)
django.urls.exceptions.NoReverseMatch: Reverse for 'chat' not found. 'chat' is not a valid view function or pattern name.
[ERROR] 2021-12-06 00:24:04,111 django.request: Internal Server Error: /chat/example/
Traceback (most recent call last):
  File "/Users/rileymarsden/.local/share/virtualenvs/EasyConnect-40Y_jyS5/lib/python3.9/site-packages/asgiref/sync.py", line 482, in thread_handler
    raise exc_info[1]
  File "/Users/rileymarsden/.local/share/virtualenvs/EasyConnect-40Y_jyS5/lib/python3.9/site-packages/django/core/handlers/exception.py", line 38, in inner
    response = await get_response(request)
  File "/Users/rileymarsden/.local/share/virtualenvs/EasyConnect-40Y_jyS5/lib/python3.9/site-packages/django/core/handlers/base.py", line 233, in _get_response_async
    response = await wrapped_callback(request, *callback_args, **callback_kwargs)
  File "/Users/rileymarsden/.local/share/virtualenvs/EasyConnect-40Y_jyS5/lib/python3.9/site-packages/asgiref/sync.py", line 444, in __call__
    ret = await asyncio.wait_for(future, timeout=None)
  File "/Library/Frameworks/Python.framework/Versions/3.9/lib/python3.9/asyncio/tasks.py", line 442, in wait_for
    return await fut
  File "/Users/rileymarsden/.local/share/virtualenvs/EasyConnect-40Y_jyS5/lib/python3.9/site-packages/asgiref/current_thread_executor.py", line 22, in run
    result = self.fn(*self.args, **self.kwargs)
  File "/Users/rileymarsden/.local/share/virtualenvs/EasyConnect-40Y_jyS5/lib/python3.9/site-packages/asgiref/sync.py", line 486, in thread_handler
    return func(*args, **kwargs)
  File "/Users/rileymarsden/.local/share/virtualenvs/EasyConnect-40Y_jyS5/lib/python3.9/site-packages/django/contrib/auth/decorators.py", line 21, in _wrapped_view
    return view_func(request, *args, **kwargs)
  File "/Users/rileymarsden/Desktop/EasyConnect/chat/views.py", line 11, in room
    return render(request, 'chat/room.html', {
  File "/Users/rileymarsden/.local/share/virtualenvs/EasyConnect-40Y_jyS5/lib/python3.9/site-packages/django/shortcuts.py", line 19, in render
    content = loader.render_to_string(template_name, context, request, using=using)
  File "/Users/rileymarsden/.local/share/virtualenvs/EasyConnect-40Y_jyS5/lib/python3.9/site-packages/django/template/loader.py", line 62, in render_to_string
    return template.render(context, request)
  File "/Users/rileymarsden/.local/share/virtualenvs/EasyConnect-40Y_jyS5/lib/python3.9/site-packages/django/template/backends/django.py", line 61, in render
    return self.template.render(context)
  File "/Users/rileymarsden/.local/share/virtualenvs/EasyConnect-40Y_jyS5/lib/python3.9/site-packages/django/template/base.py", line 170, in render
    return self._render(context)
  File "/Users/rileymarsden/.local/share/virtualenvs/EasyConnect-40Y_jyS5/lib/python3.9/site-packages/django/template/base.py", line 162, in _render
    return self.nodelist.render(context)
  File "/Users/rileymarsden/.local/share/virtualenvs/EasyConnect-40Y_jyS5/lib/python3.9/site-packages/django/template/base.py", line 938, in render
    bit = node.render_annotated(context)
  File "/Users/rileymarsden/.local/share/virtualenvs/EasyConnect-40Y_jyS5/lib/python3.9/site-packages/django/template/base.py", line 905, in render_annotated
    return self.render(context)
  File "/Users/rileymarsden/.local/share/virtualenvs/EasyConnect-40Y_jyS5/lib/python3.9/site-packages/django/template/defaulttags.py", line 446, in render
    url = reverse(view_name, args=args, kwargs=kwargs, current_app=current_app)
  File "/Users/rileymarsden/.local/share/virtualenvs/EasyConnect-40Y_jyS5/lib/python3.9/site-packages/django/urls/base.py", line 87, in reverse
    return iri_to_uri(resolver._reverse_with_prefix(view, prefix, *args, **kwargs))
  File "/Users/rileymarsden/.local/share/virtualenvs/EasyConnect-40Y_jyS5/lib/python3.9/site-packages/django/urls/resolvers.py", line 685, in _reverse_with_prefix
    raise NoReverseMatch(msg)
django.urls.exceptions.NoReverseMatch: Reverse for 'room' with no arguments not found. 1 pattern(s) tried: ['chat/(?P<room_name>[^/]+)/$']
[ERROR] 2021-12-06 00:24:47,357 django.request: Internal Server Error: /chat/easyy/
Traceback (most recent call last):
  File "/Users/rileymarsden/.local/share/virtualenvs/EasyConnect-40Y_jyS5/lib/python3.9/site-packages/asgiref/sync.py", line 482, in thread_handler
    raise exc_info[1]
  File "/Users/rileymarsden/.local/share/virtualenvs/EasyConnect-40Y_jyS5/lib/python3.9/site-packages/django/core/handlers/exception.py", line 38, in inner
    response = await get_response(request)
  File "/Users/rileymarsden/.local/share/virtualenvs/EasyConnect-40Y_jyS5/lib/python3.9/site-packages/django/core/handlers/base.py", line 233, in _get_response_async
    response = await wrapped_callback(request, *callback_args, **callback_kwargs)
  File "/Users/rileymarsden/.local/share/virtualenvs/EasyConnect-40Y_jyS5/lib/python3.9/site-packages/asgiref/sync.py", line 444, in __call__
    ret = await asyncio.wait_for(future, timeout=None)
  File "/Library/Frameworks/Python.framework/Versions/3.9/lib/python3.9/asyncio/tasks.py", line 442, in wait_for
    return await fut
  File "/Users/rileymarsden/.local/share/virtualenvs/EasyConnect-40Y_jyS5/lib/python3.9/site-packages/asgiref/current_thread_executor.py", line 22, in run
    result = self.fn(*self.args, **self.kwargs)
  File "/Users/rileymarsden/.local/share/virtualenvs/EasyConnect-40Y_jyS5/lib/python3.9/site-packages/asgiref/sync.py", line 486, in thread_handler
    return func(*args, **kwargs)
  File "/Users/rileymarsden/.local/share/virtualenvs/EasyConnect-40Y_jyS5/lib/python3.9/site-packages/django/contrib/auth/decorators.py", line 21, in _wrapped_view
    return view_func(request, *args, **kwargs)
  File "/Users/rileymarsden/Desktop/EasyConnect/chat/views.py", line 11, in room
    return render(request, 'chat/room.html', {
  File "/Users/rileymarsden/.local/share/virtualenvs/EasyConnect-40Y_jyS5/lib/python3.9/site-packages/django/shortcuts.py", line 19, in render
    content = loader.render_to_string(template_name, context, request, using=using)
  File "/Users/rileymarsden/.local/share/virtualenvs/EasyConnect-40Y_jyS5/lib/python3.9/site-packages/django/template/loader.py", line 62, in render_to_string
    return template.render(context, request)
  File "/Users/rileymarsden/.local/share/virtualenvs/EasyConnect-40Y_jyS5/lib/python3.9/site-packages/django/template/backends/django.py", line 61, in render
    return self.template.render(context)
  File "/Users/rileymarsden/.local/share/virtualenvs/EasyConnect-40Y_jyS5/lib/python3.9/site-packages/django/template/base.py", line 170, in render
    return self._render(context)
  File "/Users/rileymarsden/.local/share/virtualenvs/EasyConnect-40Y_jyS5/lib/python3.9/site-packages/django/template/base.py", line 162, in _render
    return self.nodelist.render(context)
  File "/Users/rileymarsden/.local/share/virtualenvs/EasyConnect-40Y_jyS5/lib/python3.9/site-packages/django/template/base.py", line 938, in render
    bit = node.render_annotated(context)
  File "/Users/rileymarsden/.local/share/virtualenvs/EasyConnect-40Y_jyS5/lib/python3.9/site-packages/django/template/base.py", line 905, in render_annotated
    return self.render(context)
  File "/Users/rileymarsden/.local/share/virtualenvs/EasyConnect-40Y_jyS5/lib/python3.9/site-packages/django/template/defaulttags.py", line 446, in render
    url = reverse(view_name, args=args, kwargs=kwargs, current_app=current_app)
  File "/Users/rileymarsden/.local/share/virtualenvs/EasyConnect-40Y_jyS5/lib/python3.9/site-packages/django/urls/base.py", line 87, in reverse
    return iri_to_uri(resolver._reverse_with_prefix(view, prefix, *args, **kwargs))
  File "/Users/rileymarsden/.local/share/virtualenvs/EasyConnect-40Y_jyS5/lib/python3.9/site-packages/django/urls/resolvers.py", line 685, in _reverse_with_prefix
    raise NoReverseMatch(msg)
django.urls.exceptions.NoReverseMatch: Reverse for 'chat' not found. 'chat' is not a valid view function or pattern name.
[ERROR] 2021-12-06 00:42:41,450 django.request: Internal Server Error: /chat/admintest/
Traceback (most recent call last):
  File "/Users/rileymarsden/.local/share/virtualenvs/EasyConnect-40Y_jyS5/lib/python3.9/site-packages/asgiref/sync.py", line 482, in thread_handler
    raise exc_info[1]
  File "/Users/rileymarsden/.local/share/virtualenvs/EasyConnect-40Y_jyS5/lib/python3.9/site-packages/django/core/handlers/exception.py", line 38, in inner
    response = await get_response(request)
  File "/Users/rileymarsden/.local/share/virtualenvs/EasyConnect-40Y_jyS5/lib/python3.9/site-packages/django/core/handlers/base.py", line 233, in _get_response_async
    response = await wrapped_callback(request, *callback_args, **callback_kwargs)
  File "/Users/rileymarsden/.local/share/virtualenvs/EasyConnect-40Y_jyS5/lib/python3.9/site-packages/asgiref/sync.py", line 444, in __call__
    ret = await asyncio.wait_for(future, timeout=None)
  File "/Library/Frameworks/Python.framework/Versions/3.9/lib/python3.9/asyncio/tasks.py", line 442, in wait_for
    return await fut
  File "/Users/rileymarsden/.local/share/virtualenvs/EasyConnect-40Y_jyS5/lib/python3.9/site-packages/asgiref/current_thread_executor.py", line 22, in run
    result = self.fn(*self.args, **self.kwargs)
  File "/Users/rileymarsden/.local/share/virtualenvs/EasyConnect-40Y_jyS5/lib/python3.9/site-packages/asgiref/sync.py", line 486, in thread_handler
    return func(*args, **kwargs)
  File "/Users/rileymarsden/.local/share/virtualenvs/EasyConnect-40Y_jyS5/lib/python3.9/site-packages/django/contrib/auth/decorators.py", line 21, in _wrapped_view
    return view_func(request, *args, **kwargs)
  File "/Users/rileymarsden/Desktop/EasyConnect/chat/views.py", line 11, in room
    return render(request, 'chat/room.html', {
  File "/Users/rileymarsden/.local/share/virtualenvs/EasyConnect-40Y_jyS5/lib/python3.9/site-packages/django/shortcuts.py", line 19, in render
    content = loader.render_to_string(template_name, context, request, using=using)
  File "/Users/rileymarsden/.local/share/virtualenvs/EasyConnect-40Y_jyS5/lib/python3.9/site-packages/django/template/loader.py", line 62, in render_to_string
    return template.render(context, request)
  File "/Users/rileymarsden/.local/share/virtualenvs/EasyConnect-40Y_jyS5/lib/python3.9/site-packages/django/template/backends/django.py", line 61, in render
    return self.template.render(context)
  File "/Users/rileymarsden/.local/share/virtualenvs/EasyConnect-40Y_jyS5/lib/python3.9/site-packages/django/template/base.py", line 170, in render
    return self._render(context)
  File "/Users/rileymarsden/.local/share/virtualenvs/EasyConnect-40Y_jyS5/lib/python3.9/site-packages/django/template/base.py", line 162, in _render
    return self.nodelist.render(context)
  File "/Users/rileymarsden/.local/share/virtualenvs/EasyConnect-40Y_jyS5/lib/python3.9/site-packages/django/template/base.py", line 938, in render
    bit = node.render_annotated(context)
  File "/Users/rileymarsden/.local/share/virtualenvs/EasyConnect-40Y_jyS5/lib/python3.9/site-packages/django/template/base.py", line 905, in render_annotated
    return self.render(context)
  File "/Users/rileymarsden/.local/share/virtualenvs/EasyConnect-40Y_jyS5/lib/python3.9/site-packages/django/template/defaulttags.py", line 446, in render
    url = reverse(view_name, args=args, kwargs=kwargs, current_app=current_app)
  File "/Users/rileymarsden/.local/share/virtualenvs/EasyConnect-40Y_jyS5/lib/python3.9/site-packages/django/urls/base.py", line 87, in reverse
    return iri_to_uri(resolver._reverse_with_prefix(view, prefix, *args, **kwargs))
  File "/Users/rileymarsden/.local/share/virtualenvs/EasyConnect-40Y_jyS5/lib/python3.9/site-packages/django/urls/resolvers.py", line 685, in _reverse_with_prefix
    raise NoReverseMatch(msg)
django.urls.exceptions.NoReverseMatch: Reverse for 'chat' not found. 'chat' is not a valid view function or pattern name.
[ERROR] 2021-12-06 00:50:05,627 django.request: Internal Server Error: /chat/easy/
Traceback (most recent call last):
  File "/Users/rileymarsden/.local/share/virtualenvs/EasyConnect-40Y_jyS5/lib/python3.9/site-packages/asgiref/sync.py", line 482, in thread_handler
    raise exc_info[1]
  File "/Users/rileymarsden/.local/share/virtualenvs/EasyConnect-40Y_jyS5/lib/python3.9/site-packages/django/core/handlers/exception.py", line 38, in inner
    response = await get_response(request)
  File "/Users/rileymarsden/.local/share/virtualenvs/EasyConnect-40Y_jyS5/lib/python3.9/site-packages/django/core/handlers/base.py", line 233, in _get_response_async
    response = await wrapped_callback(request, *callback_args, **callback_kwargs)
  File "/Users/rileymarsden/.local/share/virtualenvs/EasyConnect-40Y_jyS5/lib/python3.9/site-packages/asgiref/sync.py", line 444, in __call__
    ret = await asyncio.wait_for(future, timeout=None)
  File "/Library/Frameworks/Python.framework/Versions/3.9/lib/python3.9/asyncio/tasks.py", line 442, in wait_for
    return await fut
  File "/Users/rileymarsden/.local/share/virtualenvs/EasyConnect-40Y_jyS5/lib/python3.9/site-packages/asgiref/current_thread_executor.py", line 22, in run
    result = self.fn(*self.args, **self.kwargs)
  File "/Users/rileymarsden/.local/share/virtualenvs/EasyConnect-40Y_jyS5/lib/python3.9/site-packages/asgiref/sync.py", line 486, in thread_handler
    return func(*args, **kwargs)
  File "/Users/rileymarsden/.local/share/virtualenvs/EasyConnect-40Y_jyS5/lib/python3.9/site-packages/django/contrib/auth/decorators.py", line 21, in _wrapped_view
    return view_func(request, *args, **kwargs)
  File "/Users/rileymarsden/Desktop/EasyConnect/chat/views.py", line 11, in room
    return render(request, 'chat/room.html', {
  File "/Users/rileymarsden/.local/share/virtualenvs/EasyConnect-40Y_jyS5/lib/python3.9/site-packages/django/shortcuts.py", line 19, in render
    content = loader.render_to_string(template_name, context, request, using=using)
  File "/Users/rileymarsden/.local/share/virtualenvs/EasyConnect-40Y_jyS5/lib/python3.9/site-packages/django/template/loader.py", line 62, in render_to_string
    return template.render(context, request)
  File "/Users/rileymarsden/.local/share/virtualenvs/EasyConnect-40Y_jyS5/lib/python3.9/site-packages/django/template/backends/django.py", line 61, in render
    return self.template.render(context)
  File "/Users/rileymarsden/.local/share/virtualenvs/EasyConnect-40Y_jyS5/lib/python3.9/site-packages/django/template/base.py", line 170, in render
    return self._render(context)
  File "/Users/rileymarsden/.local/share/virtualenvs/EasyConnect-40Y_jyS5/lib/python3.9/site-packages/django/template/base.py", line 162, in _render
    return self.nodelist.render(context)
  File "/Users/rileymarsden/.local/share/virtualenvs/EasyConnect-40Y_jyS5/lib/python3.9/site-packages/django/template/base.py", line 938, in render
    bit = node.render_annotated(context)
  File "/Users/rileymarsden/.local/share/virtualenvs/EasyConnect-40Y_jyS5/lib/python3.9/site-packages/django/template/base.py", line 905, in render_annotated
    return self.render(context)
  File "/Users/rileymarsden/.local/share/virtualenvs/EasyConnect-40Y_jyS5/lib/python3.9/site-packages/django/template/defaulttags.py", line 446, in render
    url = reverse(view_name, args=args, kwargs=kwargs, current_app=current_app)
  File "/Users/rileymarsden/.local/share/virtualenvs/EasyConnect-40Y_jyS5/lib/python3.9/site-packages/django/urls/base.py", line 87, in reverse
    return iri_to_uri(resolver._reverse_with_prefix(view, prefix, *args, **kwargs))
  File "/Users/rileymarsden/.local/share/virtualenvs/EasyConnect-40Y_jyS5/lib/python3.9/site-packages/django/urls/resolvers.py", line 685, in _reverse_with_prefix
    raise NoReverseMatch(msg)
django.urls.exceptions.NoReverseMatch: Reverse for 'index' not found. 'index' is not a valid view function or pattern name.
[ERROR] 2021-12-06 00:58:40,240 django.request: Internal Server Error: /chat/group/
Traceback (most recent call last):
  File "/Users/rileymarsden/.local/share/virtualenvs/EasyConnect-40Y_jyS5/lib/python3.9/site-packages/django/template/base.py", line 470, in parse
    compile_func = self.tags[command]
KeyError: 'default.png'

During handling of the above exception, another exception occurred:

Traceback (most recent call last):
  File "/Users/rileymarsden/.local/share/virtualenvs/EasyConnect-40Y_jyS5/lib/python3.9/site-packages/asgiref/sync.py", line 482, in thread_handler
    raise exc_info[1]
  File "/Users/rileymarsden/.local/share/virtualenvs/EasyConnect-40Y_jyS5/lib/python3.9/site-packages/django/core/handlers/exception.py", line 38, in inner
    response = await get_response(request)
  File "/Users/rileymarsden/.local/share/virtualenvs/EasyConnect-40Y_jyS5/lib/python3.9/site-packages/django/core/handlers/base.py", line 233, in _get_response_async
    response = await wrapped_callback(request, *callback_args, **callback_kwargs)
  File "/Users/rileymarsden/.local/share/virtualenvs/EasyConnect-40Y_jyS5/lib/python3.9/site-packages/asgiref/sync.py", line 444, in __call__
    ret = await asyncio.wait_for(future, timeout=None)
  File "/Library/Frameworks/Python.framework/Versions/3.9/lib/python3.9/asyncio/tasks.py", line 442, in wait_for
    return await fut
  File "/Users/rileymarsden/.local/share/virtualenvs/EasyConnect-40Y_jyS5/lib/python3.9/site-packages/asgiref/current_thread_executor.py", line 22, in run
    result = self.fn(*self.args, **self.kwargs)
  File "/Users/rileymarsden/.local/share/virtualenvs/EasyConnect-40Y_jyS5/lib/python3.9/site-packages/asgiref/sync.py", line 486, in thread_handler
    return func(*args, **kwargs)
  File "/Users/rileymarsden/.local/share/virtualenvs/EasyConnect-40Y_jyS5/lib/python3.9/site-packages/django/contrib/auth/decorators.py", line 21, in _wrapped_view
    return view_func(request, *args, **kwargs)
  File "/Users/rileymarsden/Desktop/EasyConnect/chat/views.py", line 11, in room
    return render(request, 'chat/room.html', {
  File "/Users/rileymarsden/.local/share/virtualenvs/EasyConnect-40Y_jyS5/lib/python3.9/site-packages/django/shortcuts.py", line 19, in render
    content = loader.render_to_string(template_name, context, request, using=using)
  File "/Users/rileymarsden/.local/share/virtualenvs/EasyConnect-40Y_jyS5/lib/python3.9/site-packages/django/template/loader.py", line 61, in render_to_string
    template = get_template(template_name, using=using)
  File "/Users/rileymarsden/.local/share/virtualenvs/EasyConnect-40Y_jyS5/lib/python3.9/site-packages/django/template/loader.py", line 15, in get_template
    return engine.get_template(template_name)
  File "/Users/rileymarsden/.local/share/virtualenvs/EasyConnect-40Y_jyS5/lib/python3.9/site-packages/django/template/backends/django.py", line 34, in get_template
    return Template(self.engine.get_template(template_name), self)
  File "/Users/rileymarsden/.local/share/virtualenvs/EasyConnect-40Y_jyS5/lib/python3.9/site-packages/django/template/engine.py", line 143, in get_template
    template, origin = self.find_template(template_name)
  File "/Users/rileymarsden/.local/share/virtualenvs/EasyConnect-40Y_jyS5/lib/python3.9/site-packages/django/template/engine.py", line 125, in find_template
    template = loader.get_template(name, skip=skip)
  File "/Users/rileymarsden/.local/share/virtualenvs/EasyConnect-40Y_jyS5/lib/python3.9/site-packages/django/template/loaders/base.py", line 29, in get_template
    return Template(
  File "/Users/rileymarsden/.local/share/virtualenvs/EasyConnect-40Y_jyS5/lib/python3.9/site-packages/django/template/base.py", line 155, in __init__
    self.nodelist = self.compile_nodelist()
  File "/Users/rileymarsden/.local/share/virtualenvs/EasyConnect-40Y_jyS5/lib/python3.9/site-packages/django/template/base.py", line 193, in compile_nodelist
    return parser.parse()
  File "/Users/rileymarsden/.local/share/virtualenvs/EasyConnect-40Y_jyS5/lib/python3.9/site-packages/django/template/base.py", line 472, in parse
    self.invalid_block_tag(token, command, parse_until)
  File "/Users/rileymarsden/.local/share/virtualenvs/EasyConnect-40Y_jyS5/lib/python3.9/site-packages/django/template/base.py", line 531, in invalid_block_tag
    raise self.error(
django.template.exceptions.TemplateSyntaxError: Invalid block tag on line 66: 'default.png'. Did you forget to register or load this tag?
[ERROR] 2021-12-06 00:59:10,903 django.request: Internal Server Error: /chat/group/
Traceback (most recent call last):
  File "/Users/rileymarsden/.local/share/virtualenvs/EasyConnect-40Y_jyS5/lib/python3.9/site-packages/django/template/defaulttags.py", line 1034, in find_library
    return parser.libraries[name]
KeyError: 'media'

During handling of the above exception, another exception occurred:

Traceback (most recent call last):
  File "/Users/rileymarsden/.local/share/virtualenvs/EasyConnect-40Y_jyS5/lib/python3.9/site-packages/asgiref/sync.py", line 482, in thread_handler
    raise exc_info[1]
  File "/Users/rileymarsden/.local/share/virtualenvs/EasyConnect-40Y_jyS5/lib/python3.9/site-packages/django/core/handlers/exception.py", line 38, in inner
    response = await get_response(request)
  File "/Users/rileymarsden/.local/share/virtualenvs/EasyConnect-40Y_jyS5/lib/python3.9/site-packages/django/core/handlers/base.py", line 233, in _get_response_async
    response = await wrapped_callback(request, *callback_args, **callback_kwargs)
  File "/Users/rileymarsden/.local/share/virtualenvs/EasyConnect-40Y_jyS5/lib/python3.9/site-packages/asgiref/sync.py", line 444, in __call__
    ret = await asyncio.wait_for(future, timeout=None)
  File "/Library/Frameworks/Python.framework/Versions/3.9/lib/python3.9/asyncio/tasks.py", line 442, in wait_for
    return await fut
  File "/Users/rileymarsden/.local/share/virtualenvs/EasyConnect-40Y_jyS5/lib/python3.9/site-packages/asgiref/current_thread_executor.py", line 22, in run
    result = self.fn(*self.args, **self.kwargs)
  File "/Users/rileymarsden/.local/share/virtualenvs/EasyConnect-40Y_jyS5/lib/python3.9/site-packages/asgiref/sync.py", line 486, in thread_handler
    return func(*args, **kwargs)
  File "/Users/rileymarsden/.local/share/virtualenvs/EasyConnect-40Y_jyS5/lib/python3.9/site-packages/django/contrib/auth/decorators.py", line 21, in _wrapped_view
    return view_func(request, *args, **kwargs)
  File "/Users/rileymarsden/Desktop/EasyConnect/chat/views.py", line 11, in room
    return render(request, 'chat/room.html', {
  File "/Users/rileymarsden/.local/share/virtualenvs/EasyConnect-40Y_jyS5/lib/python3.9/site-packages/django/shortcuts.py", line 19, in render
    content = loader.render_to_string(template_name, context, request, using=using)
  File "/Users/rileymarsden/.local/share/virtualenvs/EasyConnect-40Y_jyS5/lib/python3.9/site-packages/django/template/loader.py", line 61, in render_to_string
    template = get_template(template_name, using=using)
  File "/Users/rileymarsden/.local/share/virtualenvs/EasyConnect-40Y_jyS5/lib/python3.9/site-packages/django/template/loader.py", line 15, in get_template
    return engine.get_template(template_name)
  File "/Users/rileymarsden/.local/share/virtualenvs/EasyConnect-40Y_jyS5/lib/python3.9/site-packages/django/template/backends/django.py", line 34, in get_template
    return Template(self.engine.get_template(template_name), self)
  File "/Users/rileymarsden/.local/share/virtualenvs/EasyConnect-40Y_jyS5/lib/python3.9/site-packages/django/template/engine.py", line 143, in get_template
    template, origin = self.find_template(template_name)
  File "/Users/rileymarsden/.local/share/virtualenvs/EasyConnect-40Y_jyS5/lib/python3.9/site-packages/django/template/engine.py", line 125, in find_template
    template = loader.get_template(name, skip=skip)
  File "/Users/rileymarsden/.local/share/virtualenvs/EasyConnect-40Y_jyS5/lib/python3.9/site-packages/django/template/loaders/base.py", line 29, in get_template
    return Template(
  File "/Users/rileymarsden/.local/share/virtualenvs/EasyConnect-40Y_jyS5/lib/python3.9/site-packages/django/template/base.py", line 155, in __init__
    self.nodelist = self.compile_nodelist()
  File "/Users/rileymarsden/.local/share/virtualenvs/EasyConnect-40Y_jyS5/lib/python3.9/site-packages/django/template/base.py", line 193, in compile_nodelist
    return parser.parse()
  File "/Users/rileymarsden/.local/share/virtualenvs/EasyConnect-40Y_jyS5/lib/python3.9/site-packages/django/template/base.py", line 478, in parse
    raise self.error(token, e)
  File "/Users/rileymarsden/.local/share/virtualenvs/EasyConnect-40Y_jyS5/lib/python3.9/site-packages/django/template/base.py", line 476, in parse
    compiled_result = compile_func(self, token)
  File "/Users/rileymarsden/.local/share/virtualenvs/EasyConnect-40Y_jyS5/lib/python3.9/site-packages/django/template/defaulttags.py", line 1091, in load
    lib = find_library(parser, name)
  File "/Users/rileymarsden/.local/share/virtualenvs/EasyConnect-40Y_jyS5/lib/python3.9/site-packages/django/template/defaulttags.py", line 1036, in find_library
    raise TemplateSyntaxError(
django.template.exceptions.TemplateSyntaxError: 'media' is not a registered tag library. Must be one of:
admin_list
admin_modify
admin_urls
cache
i18n
l10n
log
static
tz
[ERROR] 2021-12-06 01:06:24,848 django.request: Internal Server Error: /chat/group/
Traceback (most recent call last):
  File "/Users/rileymarsden/.local/share/virtualenvs/EasyConnect-40Y_jyS5/lib/python3.9/site-packages/asgiref/sync.py", line 482, in thread_handler
    raise exc_info[1]
  File "/Users/rileymarsden/.local/share/virtualenvs/EasyConnect-40Y_jyS5/lib/python3.9/site-packages/django/core/handlers/exception.py", line 38, in inner
    response = await get_response(request)
  File "/Users/rileymarsden/.local/share/virtualenvs/EasyConnect-40Y_jyS5/lib/python3.9/site-packages/django/core/handlers/base.py", line 233, in _get_response_async
    response = await wrapped_callback(request, *callback_args, **callback_kwargs)
  File "/Users/rileymarsden/.local/share/virtualenvs/EasyConnect-40Y_jyS5/lib/python3.9/site-packages/asgiref/sync.py", line 444, in __call__
    ret = await asyncio.wait_for(future, timeout=None)
  File "/Library/Frameworks/Python.framework/Versions/3.9/lib/python3.9/asyncio/tasks.py", line 442, in wait_for
    return await fut
  File "/Users/rileymarsden/.local/share/virtualenvs/EasyConnect-40Y_jyS5/lib/python3.9/site-packages/asgiref/current_thread_executor.py", line 22, in run
    result = self.fn(*self.args, **self.kwargs)
  File "/Users/rileymarsden/.local/share/virtualenvs/EasyConnect-40Y_jyS5/lib/python3.9/site-packages/asgiref/sync.py", line 486, in thread_handler
    return func(*args, **kwargs)
  File "/Users/rileymarsden/.local/share/virtualenvs/EasyConnect-40Y_jyS5/lib/python3.9/site-packages/django/contrib/auth/decorators.py", line 21, in _wrapped_view
    return view_func(request, *args, **kwargs)
  File "/Users/rileymarsden/Desktop/EasyConnect/chat/views.py", line 11, in room
    return render(request, 'chat/room.html', {
  File "/Users/rileymarsden/.local/share/virtualenvs/EasyConnect-40Y_jyS5/lib/python3.9/site-packages/django/shortcuts.py", line 19, in render
    content = loader.render_to_string(template_name, context, request, using=using)
  File "/Users/rileymarsden/.local/share/virtualenvs/EasyConnect-40Y_jyS5/lib/python3.9/site-packages/django/template/loader.py", line 61, in render_to_string
    template = get_template(template_name, using=using)
  File "/Users/rileymarsden/.local/share/virtualenvs/EasyConnect-40Y_jyS5/lib/python3.9/site-packages/django/template/loader.py", line 15, in get_template
    return engine.get_template(template_name)
  File "/Users/rileymarsden/.local/share/virtualenvs/EasyConnect-40Y_jyS5/lib/python3.9/site-packages/django/template/backends/django.py", line 34, in get_template
    return Template(self.engine.get_template(template_name), self)
  File "/Users/rileymarsden/.local/share/virtualenvs/EasyConnect-40Y_jyS5/lib/python3.9/site-packages/django/template/engine.py", line 143, in get_template
    template, origin = self.find_template(template_name)
  File "/Users/rileymarsden/.local/share/virtualenvs/EasyConnect-40Y_jyS5/lib/python3.9/site-packages/django/template/engine.py", line 125, in find_template
    template = loader.get_template(name, skip=skip)
  File "/Users/rileymarsden/.local/share/virtualenvs/EasyConnect-40Y_jyS5/lib/python3.9/site-packages/django/template/loaders/base.py", line 29, in get_template
    return Template(
  File "/Users/rileymarsden/.local/share/virtualenvs/EasyConnect-40Y_jyS5/lib/python3.9/site-packages/django/template/base.py", line 155, in __init__
    self.nodelist = self.compile_nodelist()
  File "/Users/rileymarsden/.local/share/virtualenvs/EasyConnect-40Y_jyS5/lib/python3.9/site-packages/django/template/base.py", line 193, in compile_nodelist
    return parser.parse()
  File "/Users/rileymarsden/.local/share/virtualenvs/EasyConnect-40Y_jyS5/lib/python3.9/site-packages/django/template/base.py", line 449, in parse
    raise self.error(token, e)
  File "/Users/rileymarsden/.local/share/virtualenvs/EasyConnect-40Y_jyS5/lib/python3.9/site-packages/django/template/base.py", line 447, in parse
    filter_expression = self.compile_filter(token.contents)
  File "/Users/rileymarsden/.local/share/virtualenvs/EasyConnect-40Y_jyS5/lib/python3.9/site-packages/django/template/base.py", line 563, in compile_filter
    return FilterExpression(token, self)
  File "/Users/rileymarsden/.local/share/virtualenvs/EasyConnect-40Y_jyS5/lib/python3.9/site-packages/django/template/base.py", line 662, in __init__
    raise TemplateSyntaxError("Could not parse the remainder: '%s' "
django.template.exceptions.TemplateSyntaxError: Could not parse the remainder: '-name-submit' from 'room-name-submit'
[ERROR] 2021-12-06 01:06:42,779 django.request: Internal Server Error: /chat/group/
Traceback (most recent call last):
  File "/Users/rileymarsden/.local/share/virtualenvs/EasyConnect-40Y_jyS5/lib/python3.9/site-packages/asgiref/sync.py", line 482, in thread_handler
    raise exc_info[1]
  File "/Users/rileymarsden/.local/share/virtualenvs/EasyConnect-40Y_jyS5/lib/python3.9/site-packages/django/core/handlers/exception.py", line 38, in inner
    response = await get_response(request)
  File "/Users/rileymarsden/.local/share/virtualenvs/EasyConnect-40Y_jyS5/lib/python3.9/site-packages/django/core/handlers/base.py", line 233, in _get_response_async
    response = await wrapped_callback(request, *callback_args, **callback_kwargs)
  File "/Users/rileymarsden/.local/share/virtualenvs/EasyConnect-40Y_jyS5/lib/python3.9/site-packages/asgiref/sync.py", line 444, in __call__
    ret = await asyncio.wait_for(future, timeout=None)
  File "/Library/Frameworks/Python.framework/Versions/3.9/lib/python3.9/asyncio/tasks.py", line 442, in wait_for
    return await fut
  File "/Users/rileymarsden/.local/share/virtualenvs/EasyConnect-40Y_jyS5/lib/python3.9/site-packages/asgiref/current_thread_executor.py", line 22, in run
    result = self.fn(*self.args, **self.kwargs)
  File "/Users/rileymarsden/.local/share/virtualenvs/EasyConnect-40Y_jyS5/lib/python3.9/site-packages/asgiref/sync.py", line 486, in thread_handler
    return func(*args, **kwargs)
  File "/Users/rileymarsden/.local/share/virtualenvs/EasyConnect-40Y_jyS5/lib/python3.9/site-packages/django/contrib/auth/decorators.py", line 21, in _wrapped_view
    return view_func(request, *args, **kwargs)
  File "/Users/rileymarsden/Desktop/EasyConnect/chat/views.py", line 11, in room
    return render(request, 'chat/room.html', {
  File "/Users/rileymarsden/.local/share/virtualenvs/EasyConnect-40Y_jyS5/lib/python3.9/site-packages/django/shortcuts.py", line 19, in render
    content = loader.render_to_string(template_name, context, request, using=using)
  File "/Users/rileymarsden/.local/share/virtualenvs/EasyConnect-40Y_jyS5/lib/python3.9/site-packages/django/template/loader.py", line 61, in render_to_string
    template = get_template(template_name, using=using)
  File "/Users/rileymarsden/.local/share/virtualenvs/EasyConnect-40Y_jyS5/lib/python3.9/site-packages/django/template/loader.py", line 15, in get_template
    return engine.get_template(template_name)
  File "/Users/rileymarsden/.local/share/virtualenvs/EasyConnect-40Y_jyS5/lib/python3.9/site-packages/django/template/backends/django.py", line 34, in get_template
    return Template(self.engine.get_template(template_name), self)
  File "/Users/rileymarsden/.local/share/virtualenvs/EasyConnect-40Y_jyS5/lib/python3.9/site-packages/django/template/engine.py", line 143, in get_template
    template, origin = self.find_template(template_name)
  File "/Users/rileymarsden/.local/share/virtualenvs/EasyConnect-40Y_jyS5/lib/python3.9/site-packages/django/template/engine.py", line 125, in find_template
    template = loader.get_template(name, skip=skip)
  File "/Users/rileymarsden/.local/share/virtualenvs/EasyConnect-40Y_jyS5/lib/python3.9/site-packages/django/template/loaders/base.py", line 29, in get_template
    return Template(
  File "/Users/rileymarsden/.local/share/virtualenvs/EasyConnect-40Y_jyS5/lib/python3.9/site-packages/django/template/base.py", line 155, in __init__
    self.nodelist = self.compile_nodelist()
  File "/Users/rileymarsden/.local/share/virtualenvs/EasyConnect-40Y_jyS5/lib/python3.9/site-packages/django/template/base.py", line 193, in compile_nodelist
    return parser.parse()
  File "/Users/rileymarsden/.local/share/virtualenvs/EasyConnect-40Y_jyS5/lib/python3.9/site-packages/django/template/base.py", line 449, in parse
    raise self.error(token, e)
  File "/Users/rileymarsden/.local/share/virtualenvs/EasyConnect-40Y_jyS5/lib/python3.9/site-packages/django/template/base.py", line 447, in parse
    filter_expression = self.compile_filter(token.contents)
  File "/Users/rileymarsden/.local/share/virtualenvs/EasyConnect-40Y_jyS5/lib/python3.9/site-packages/django/template/base.py", line 563, in compile_filter
    return FilterExpression(token, self)
  File "/Users/rileymarsden/.local/share/virtualenvs/EasyConnect-40Y_jyS5/lib/python3.9/site-packages/django/template/base.py", line 662, in __init__
    raise TemplateSyntaxError("Could not parse the remainder: '%s' "
django.template.exceptions.TemplateSyntaxError: Could not parse the remainder: '-name-input' from 'room-name-input'
